Workbook

Sheet NOMINA
B2: CURSO 2A | D2: GESTION: 2026
D3: ,
A4: Nº | B4: APELLIDOS Y NOMBRES | C4: GENERO | D4: FECHA DE | F4: C.I.
D5: NACIMIENTO
A6: 1 | B6: ABREU MARRERO LIZ DANIELA
A7: 2 | B7: ALIAGA SAAVEDRA MARCU MAURICIO
A8: 3 | B8: ANTEZANA CACHI JOSE MAXWEL
A9: 4 | B9: ARIZACA SALGUERO SANTIAGO
A10: 5 | B10: BAUTISTA GARCIA ALISON LUCIANA
A11: 6 | B11: BOLIVAR REVOLLO NIVARDO ADOLFO
A12: 7 | B12: CADIMA SOLIZ NICOLAS
A13: 8 | B13: CALLE PEREZ ANDREA BELEN
A14: 9 | B14: CHAVEZ AMURRIO SEBASTIAN FABIAN
A15: 10 | B15: CHOQUE ARISPE YURIANA LUCIA
A16: 11 | B16: CHOQUE PERALTA JHOEL ELIAZAR
A17: 12 | B17: COPA RIVERO MARCIA MARCELA
... A40: 35 | B40: ZAMBRANA MENDEZ MIRCO ALEXANDER
A41: 36
A42: 37
A43: 38
A44: 39
A45: 40
A46: 41
A47: 42
A48: 43
A49: 44
A50: 45

Sheet LEN
B2: =NOMINA!$B$2 -> CURSO 2A | D2: LENGUAJE
A4: Nº | B4: APELLIDOS Y NOMBRES | C4: 1er. TRIM. | D4: 2do. TRIM. | E4: 3er. TRIM. | F4: PRO. ANUAL
C5: CUANT. | D5: CUANT. | E5: CUANT. | F5: P.TOTAL | G5: OBSERV.
A6: =NOMINA!A6 -> 1 | B6: =NOMINA!B6 -> ABREU MARRERO LIZ DANIELA | C6: 54 | F6: =IF(ROUND((C6+D6+E6)/3,0)>0,ROUND((C6+D6+E6)/3,0)," ") -> 18
A7: =NOMINA!A7 -> 2 | B7: =NOMINA!B7 -> ALIAGA SAAVEDRA MARCU MAURICIO | C7: 53 | F7: =IF(ROUND((C7+D7+E7)/3,0)>0,ROUND((C7+D7+E7)/3,0)," ") -> 18
A8: =NOMINA!A8 -> 3 | B8: =NOMINA!B8 -> ANTEZANA CACHI JOSE MAXWEL | C8: 65 | F8: =IF(ROUND((C8+D8+E8)/3,0)>0,ROUND((C8+D8+E8)/3,0)," ") -> 22
A9: =NOMINA!A9 -> 4 | B9: =NOMINA!B9 -> ARIZACA SALGUERO SANTIAGO | C9: 46 | F9: =IF(ROUND((C9+D9+E9)/3,0)>0,ROUND((C9+D9+E9)/3,0)," ") -> 15
A10: =NOMINA!A10 -> 5 | B10: =NOMINA!B10 -> BAUTISTA GARCIA ALISON LUCIANA | C10: 52 | F10: =IF(ROUND((C10+D10+E10)/3,0)>0,ROUND((C10+D10+E10)/3,0)," ") -> 17
A11: =NOMINA!A11 -> 6 | B11: =NOMINA!B11 -> BOLIVAR REVOLLO NIVARDO ADOLFO | C11: 51 | F11: =IF(ROUND((C11+D11+E11)/3,0)>0,ROUND((C11+D11+E11)/3,0)," ") -> 17
A12: =NOMINA!A12 -> 7 | B12: =NOMINA!B12 -> CADIMA SOLIZ NICOLAS | C12: 46 | F12: =IF(ROUND((C12+D12+E12)/3,0)>0,ROUND((C12+D12+E12)/3,0)," ") -> 15
A13: =NOMINA!A13 -> 8 | B13: =NOMINA!B13 -> CALLE PEREZ ANDREA BELEN | C13: 78 | F13: =IF(ROUND((C13+D13+E13)/3,0)>0,ROUND((C13+D13+E13)/3,0)," ") -> 26
A14: =NOMINA!A14 -> 9 | B14: =NOMINA!B14 -> CHAVEZ AMURRIO SEBASTIAN FABIAN | C14: 44 | F14: =IF(ROUND((C14+D14+E14)/3,0)>0,ROUND((C14+D14+E14)/3,0)," ") -> 15
A15: =NOMINA!A15 -> 10 | B15: =NOMINA!B15 -> CHOQUE ARISPE YURIANA LUCIA | C15: 51 | F15: =IF(ROUND((C15+D15+E15)/3,0)>0,ROUND((C15+D15+E15)/3,0)," ") -> 17
A16: =NOMINA!A16 -> 11 | B16: =NOMINA!B16 -> CHOQUE PERALTA JHOEL ELIAZAR | C16: 85 | F16: =IF(ROUND((C16+D16+E16)/3,0)>0,ROUND((C16+D16+E16)/3,0)," ") -> 28
A17: =NOMINA!A17 -> 12 | B17: =NOMINA!B17 -> COPA RIVERO MARCIA MARCELA | C17: 43 | F17: =IF(ROUND((C17+D17+E17)/3,0)>0,ROUND((C17+D17+E17)/3,0)," ") -> 14
... A40: =NOMINA!A40 -> 35 | B40: =NOMINA!B40 -> ZAMBRANA MENDEZ MIRCO ALEXANDER | C40: 45 | F40: =IF(ROUND((C40+D40+E40)/3,0)>0,ROUND((C40+D40+E40)/3,0)," ") -> 15
A41: =NOMINA!A41 -> 36 | B41: =NOMINA!B41 -> 0 | F41: =IF(ROUND((C41+D41+E41)/3,0)>0,ROUND((C41+D41+E41)/3,0)," ")
A42: =NOMINA!A42 -> 37 | B42: =NOMINA!B42 -> 0 | F42: =IF(ROUND((C42+D42+E42)/3,0)>0,ROUND((C42+D42+E42)/3,0)," ")
A43: =NOMINA!A43 -> 38 | B43: =NOMINA!B43 -> 0 | F43: =IF(ROUND((C43+D43+E43)/3,0)>0,ROUND((C43+D43+E43)/3,0)," ")
A44: =NOMINA!A44 -> 39 | B44: =NOMINA!B44 -> 0 | F44: =IF(ROUND((C44+D44+E44)/3,0)>0,ROUND((C44+D44+E44)/3,0)," ")
A45: =NOMINA!A45 -> 40 | B45: =NOMINA!B45 -> 0 | F45: =IF(ROUND((C45+D45+E45)/3,0)>0,ROUND((C45+D45+E45)/3,0)," ")
A46: =NOMINA!A46 -> 41 | B46: =NOMINA!B46 -> 0 | F46: =IF(ROUND((C46+D46+E46)/3,0)>0,ROUND((C46+D46+E46)/3,0)," ")
A47: =NOMINA!A47 -> 42 | B47: =NOMINA!B47 -> 0 | F47: =IF(ROUND((C47+D47+E47)/3,0)>0,ROUND((C47+D47+E47)/3,0)," ")
A48: =NOMINA!A48 -> 43 | B48: =NOMINA!B48 -> 0 | F48: =IF(ROUND((C48+D48+E48)/3,0)>0,ROUND((C48+D48+E48)/3,0)," ")
A49: =NOMINA!A49 -> 44 | B49: =NOMINA!B49 -> 0 | F49: =IF(ROUND((C49+D49+E49)/3,0)>0,ROUND((C49+D49+E49)/3,0)," ")
A50: =NOMINA!A50 -> 45 | B50: =NOMINA!B50 -> 0 | F50: =IF(ROUND((C50+D50+E50)/3,0)>0,ROUND((C50+D50+E50)/3,0)," ")

Sheet ING
B2: =NOMINA!$B$2 -> CURSO 2A | D2: INGLES
A4: Nº | B4: APELLIDOS Y NOMBRES | C4: 1er. TRIM. | D4: 2do. TRIM. | E4: 3er. TRIM. | F4: PRO. ANUAL
C5: CUANT. | D5: CUANT. | E5: CUANT. | F5: P.TOTAL | G5: OBSERV.
A6: =NOMINA!A6 -> 1 | B6: =NOMINA!B6 -> ABREU MARRERO LIZ DANIELA | C6: 60 | F6: =IF(ROUND((C6+D6+E6)/3,0)>0,ROUND((C6+D6+E6)/3,0)," ") -> 20
A7: =NOMINA!A7 -> 2 | B7: =NOMINA!B7 -> ALIAGA SAAVEDRA MARCU MAURICIO | C7: 66 | F7: =IF(ROUND((C7+D7+E7)/3,0)>0,ROUND((C7+D7+E7)/3,0)," ") -> 22
A8: =NOMINA!A8 -> 3 | B8: =NOMINA!B8 -> ANTEZANA CACHI JOSE MAXWEL | C8: 81 | F8: =IF(ROUND((C8+D8+E8)/3,0)>0,ROUND((C8+D8+E8)/3,0)," ") -> 27
A9: =NOMINA!A9 -> 4 | B9: =NOMINA!B9 -> ARIZACA SALGUERO SANTIAGO | C9: 48 | F9: =IF(ROUND((C9+D9+E9)/3,0)>0,ROUND((C9+D9+E9)/3,0)," ") -> 16
A10: =NOMINA!A10 -> 5 | B10: =NOMINA!B10 -> BAUTISTA GARCIA ALISON LUCIANA | C10: 57 | F10: =IF(ROUND((C10+D10+E10)/3,0)>0,ROUND((C10+D10+E10)/3,0)," ") -> 19
A11: =NOMINA!A11 -> 6 | B11: =NOMINA!B11 -> BOLIVAR REVOLLO NIVARDO ADOLFO | C11: 63 | F11: =IF(ROUND((C11+D11+E11)/3,0)>0,ROUND((C11+D11+E11)/3,0)," ") -> 21
A12: =NOMINA!A12 -> 7 | B12: =NOMINA!B12 -> CADIMA SOLIZ NICOLAS | C12: 47 | F12: =IF(ROUND((C12+D12+E12)/3,0)>0,ROUND((C12+D12+E12)/3,0)," ") -> 16
A13: =NOMINA!A13 -> 8 | B13: =NOMINA!B13 -> CALLE PEREZ ANDREA BELEN | C13: 80 | F13: =IF(ROUND((C13+D13+E13)/3,0)>0,ROUND((C13+D13+E13)/3,0)," ") -> 27
A14: =NOMINA!A14 -> 9 | B14: =NOMINA!B14 -> CHAVEZ AMURRIO SEBASTIAN FABIAN | C14: 45 | F14: =IF(ROUND((C14+D14+E14)/3,0)>0,ROUND((C14+D14+E14)/3,0)," ") -> 15
A15: =NOMINA!A15 -> 10 | B15: =NOMINA!B15 -> CHOQUE ARISPE YURIANA LUCIA | C15: 58 | F15: =IF(ROUND((C15+D15+E15)/3,0)>0,ROUND((C15+D15+E15)/3,0)," ") -> 19
A16: =NOMINA!A16 -> 11 | B16: =NOMINA!B16 -> CHOQUE PERALTA JHOEL ELIAZAR | C16: 90 | F16: =IF(ROUND((C16+D16+E16)/3,0)>0,ROUND((C16+D16+E16)/3,0)," ") -> 30
A17: =NOMINA!A17 -> 12 | B17: =NOMINA!B17 -> COPA RIVERO MARCIA MARCELA | C17: 67 | F17: =IF(ROUND((C17+D17+E17)/3,0)>0,ROUND((C17+D17+E17)/3,0)," ") -> 22
... A40: =NOMINA!A40 -> 35 | B40: =NOMINA!B40 -> ZAMBRANA MENDEZ MIRCO ALEXANDER | C40: 41 | F40: =IF(ROUND((C40+D40+E40)/3,0)>0,ROUND((C40+D40+E40)/3,0)," ") -> 14
A41: =NOMINA!A41 -> 36 | B41: =NOMINA!B41 -> 0 | F41: =IF(ROUND((C41+D41+E41)/3,0)>0,ROUND((C41+D41+E41)/3,0)," ")
A42: =NOMINA!A42 -> 37 | B42: =NOMINA!B42 -> 0 | F42: =IF(ROUND((C42+D42+E42)/3,0)>0,ROUND((C42+D42+E42)/3,0)," ")
A43: =NOMINA!A43 -> 38 | B43: =NOMINA!B43 -> 0 | F43: =IF(ROUND((C43+D43+E43)/3,0)>0,ROUND((C43+D43+E43)/3,0)," ")
A44: =NOMINA!A44 -> 39 | B44: =NOMINA!B44 -> 0 | F44: =IF(ROUND((C44+D44+E44)/3,0)>0,ROUND((C44+D44+E44)/3,0)," ")
A45: =NOMINA!A45 -> 40 | B45: =NOMINA!B45 -> 0 | F45: =IF(ROUND((C45+D45+E45)/3,0)>0,ROUND((C45+D45+E45)/3,0)," ")
A46: =NOMINA!A46 -> 41 | B46: =NOMINA!B46 -> 0 | F46: =IF(ROUND((C46+D46+E46)/3,0)>0,ROUND((C46+D46+E46)/3,0)," ")
A47: =NOMINA!A47 -> 42 | B47: =NOMINA!B47 -> 0 | F47: =IF(ROUND((C47+D47+E47)/3,0)>0,ROUND((C47+D47+E47)/3,0)," ")
A48: =NOMINA!A48 -> 43 | B48: =NOMINA!B48 -> 0 | F48: =IF(ROUND((C48+D48+E48)/3,0)>0,ROUND((C48+D48+E48)/3,0)," ")
A49: =NOMINA!A49 -> 44 | B49: =NOMINA!B49 -> 0 | F49: =IF(ROUND((C49+D49+E49)/3,0)>0,ROUND((C49+D49+E49)/3,0)," ")
A50: =NOMINA!A50 -> 45 | B50: =NOMINA!B50 -> 0 | F50: =IF(ROUND((C50+D50+E50)/3,0)>0,ROUND((C50+D50+E50)/3,0)," ")

Sheet C.SOC
B2: =NOMINA!$B$2 -> CURSO 2A | D2: CIENCIAS SOCIALES
A4: Nº | B4: APELLIDOS Y NOMBRES | C4: 1er. TRIM. | D4: 2do. TRIM. | E4: 3er. TRIM. | F4: PRO. ANUAL
C5: CUANT. | D5: CUANT. | E5: CUANT. | F5: P.TOTAL | G5: OBSERV.
A6: =NOMINA!A6 -> 1 | B6: =NOMINA!B6 -> ABREU MARRERO LIZ DANIELA | C6: 73 | F6: =IF(ROUND((C6+D6+E6)/3,0)>0,ROUND((C6+D6+E6)/3,0)," ") -> 24
A7: =NOMINA!A7 -> 2 | B7: =NOMINA!B7 -> ALIAGA SAAVEDRA MARCU MAURICIO | C7: 58 | F7: =IF(ROUND((C7+D7+E7)/3,0)>0,ROUND((C7+D7+E7)/3,0)," ") -> 19
A8: =NOMINA!A8 -> 3 | B8: =NOMINA!B8 -> ANTEZANA CACHI JOSE MAXWEL | C8: 74 | F8: =IF(ROUND((C8+D8+E8)/3,0)>0,ROUND((C8+D8+E8)/3,0)," ") -> 25
A9: =NOMINA!A9 -> 4 | B9: =NOMINA!B9 -> ARIZACA SALGUERO SANTIAGO | C9: 63 | F9: =IF(ROUND((C9+D9+E9)/3,0)>0,ROUND((C9+D9+E9)/3,0)," ") -> 21
A10: =NOMINA!A10 -> 5 | B10: =NOMINA!B10 -> BAUTISTA GARCIA ALISON LUCIANA | C10: 51 | F10: =IF(ROUND((C10+D10+E10)/3,0)>0,ROUND((C10+D10+E10)/3,0)," ") -> 17
A11: =NOMINA!A11 -> 6 | B11: =NOMINA!B11 -> BOLIVAR REVOLLO NIVARDO ADOLFO | C11: 43 | F11: =IF(ROUND((C11+D11+E11)/3,0)>0,ROUND((C11+D11+E11)/3,0)," ") -> 14
A12: =NOMINA!A12 -> 7 | B12: =NOMINA!B12 -> CADIMA SOLIZ NICOLAS | C12: 40 | F12: =IF(ROUND((C12+D12+E12)/3,0)>0,ROUND((C12+D12+E12)/3,0)," ") -> 13
A13: =NOMINA!A13 -> 8 | B13: =NOMINA!B13 -> CALLE PEREZ ANDREA BELEN | C13: 75 | F13: =IF(ROUND((C13+D13+E13)/3,0)>0,ROUND((C13+D13+E13)/3,0)," ") -> 25
A14: =NOMINA!A14 -> 9 | B14: =NOMINA!B14 -> CHAVEZ AMURRIO SEBASTIAN FABIAN | C14: 56 | F14: =IF(ROUND((C14+D14+E14)/3,0)>0,ROUND((C14+D14+E14)/3,0)," ") -> 19
A15: =NOMINA!A15 -> 10 | B15: =NOMINA!B15 -> CHOQUE ARISPE YURIANA LUCIA | C15: 44 | F15: =IF(ROUND((C15+D15+E15)/3,0)>0,ROUND((C15+D15+E15)/3,0)," ") -> 15
A16: =NOMINA!A16 -> 11 | B16: =NOMINA!B16 -> CHOQUE PERALTA JHOEL ELIAZAR | C16: 82 | F16: =IF(ROUND((C16+D16+E16)/3,0)>0,ROUND((C16+D16+E16)/3,0)," ") -> 27
A17: =NOMINA!A17 -> 12 | B17: =NOMINA!B17 -> COPA RIVERO MARCIA MARCELA | C17: 51 | F17: =IF(ROUND((C17+D17+E17)/3,0)>0,ROUND((C17+D17+E17)/3,0)," ") -> 17
... A40: =NOMINA!A40 -> 35 | B40: =NOMINA!B40 -> ZAMBRANA MENDEZ MIRCO ALEXANDER | C40: 53 | F40: =IF(ROUND((C40+D40+E40)/3,0)>0,ROUND((C40+D40+E40)/3,0)," ") -> 18
A41: =NOMINA!A41 -> 36 | B41: =NOMINA!B41 -> 0 | F41: =IF(ROUND((C41+D41+E41)/3,0)>0,ROUND((C41+D41+E41)/3,0)," ")
A42: =NOMINA!A42 -> 37 | B42: =NOMINA!B42 -> 0 | F42: =IF(ROUND((C42+D42+E42)/3,0)>0,ROUND((C42+D42+E42)/3,0)," ")
A43: =NOMINA!A43 -> 38 | B43: =NOMINA!B43 -> 0 | F43: =IF(ROUND((C43+D43+E43)/3,0)>0,ROUND((C43+D43+E43)/3,0)," ")
A44: =NOMINA!A44 -> 39 | B44: =NOMINA!B44 -> 0 | F44: =IF(ROUND((C44+D44+E44)/3,0)>0,ROUND((C44+D44+E44)/3,0)," ")
A45: =NOMINA!A45 -> 40 | B45: =NOMINA!B45 -> 0 | F45: =IF(ROUND((C45+D45+E45)/3,0)>0,ROUND((C45+D45+E45)/3,0)," ")
A46: =NOMINA!A46 -> 41 | B46: =NOMINA!B46 -> 0 | F46: =IF(ROUND((C46+D46+E46)/3,0)>0,ROUND((C46+D46+E46)/3,0)," ")
A47: =NOMINA!A47 -> 42 | B47: =NOMINA!B47 -> 0 | F47: =IF(ROUND((C47+D47+E47)/3,0)>0,ROUND((C47+D47+E47)/3,0)," ")
A48: =NOMINA!A48 -> 43 | B48: =NOMINA!B48 -> 0 | F48: =IF(ROUND((C48+D48+E48)/3,0)>0,ROUND((C48+D48+E48)/3,0)," ")
A49: =NOMINA!A49 -> 44 | B49: =NOMINA!B49 -> 0 | F49: =IF(ROUND((C49+D49+E49)/3,0)>0,ROUND((C49+D49+E49)/3,0)," ")
A50: =NOMINA!A50 -> 45 | B50: =NOMINA!B50 -> 0 | F50: =IF(ROUND((C50+D50+E50)/3,0)>0,ROUND((C50+D50+E50)/3,0)," ")

Sheet E. FIS.
B2: =NOMINA!$B$2 -> CURSO 2A | D2: ED. FÍSICA
A4: Nº | B4: APELLIDOS Y NOMBRES | C4: 1er. TRIM. | D4: 2do. TRIM. | E4: 3er. TRIM. | F4: PRO. ANUAL
C5: CUANT. | D5: CUANT. | E5: CUANT. | F5: P.TOTAL | G5: OBSERV.
A6: =NOMINA!A6 -> 1 | B6: =NOMINA!B6 -> ABREU MARRERO LIZ DANIELA | C6: 70 | F6: =IF(ROUND((C6+D6+E6)/3,0)>0,ROUND((C6+D6+E6)/3,0)," ") -> 23
A7: =NOMINA!A7 -> 2 | B7: =NOMINA!B7 -> ALIAGA SAAVEDRA MARCU MAURICIO | C7: 54 | F7: =IF(ROUND((C7+D7+E7)/3,0)>0,ROUND((C7+D7+E7)/3,0)," ") -> 18
A8: =NOMINA!A8 -> 3 | B8: =NOMINA!B8 -> ANTEZANA CACHI JOSE MAXWEL | C8: 63 | F8: =IF(ROUND((C8+D8+E8)/3,0)>0,ROUND((C8+D8+E8)/3,0)," ") -> 21
A9: =NOMINA!A9 -> 4 | B9: =NOMINA!B9 -> ARIZACA SALGUERO SANTIAGO | C9: 76 | F9: =IF(ROUND((C9+D9+E9)/3,0)>0,ROUND((C9+D9+E9)/3,0)," ") -> 25
A10: =NOMINA!A10 -> 5 | B10: =NOMINA!B10 -> BAUTISTA GARCIA ALISON LUCIANA | C10: 67 | F10: =IF(ROUND((C10+D10+E10)/3,0)>0,ROUND((C10+D10+E10)/3,0)," ") -> 22
A11: =NOMINA!A11 -> 6 | B11: =NOMINA!B11 -> BOLIVAR REVOLLO NIVARDO ADOLFO | C11: 59 | F11: =IF(ROUND((C11+D11+E11)/3,0)>0,ROUND((C11+D11+E11)/3,0)," ") -> 20
A12: =NOMINA!A12 -> 7 | B12: =NOMINA!B12 -> CADIMA SOLIZ NICOLAS | C12: 69 | F12: =IF(ROUND((C12+D12+E12)/3,0)>0,ROUND((C12+D12+E12)/3,0)," ") -> 23
A13: =NOMINA!A13 -> 8 | B13: =NOMINA!B13 -> CALLE PEREZ ANDREA BELEN | C13: 67 | F13: =IF(ROUND((C13+D13+E13)/3,0)>0,ROUND((C13+D13+E13)/3,0)," ") -> 22
A14: =NOMINA!A14 -> 9 | B14: =NOMINA!B14 -> CHAVEZ AMURRIO SEBASTIAN FABIAN | C14: 45 | F14: =IF(ROUND((C14+D14+E14)/3,0)>0,ROUND((C14+D14+E14)/3,0)," ") -> 15
A15: =NOMINA!A15 -> 10 | B15: =NOMINA!B15 -> CHOQUE ARISPE YURIANA LUCIA | C15: 55 | F15: =IF(ROUND((C15+D15+E15)/3,0)>0,ROUND((C15+D15+E15)/3,0)," ") -> 18
A16: =NOMINA!A16 -> 11 | B16: =NOMINA!B16 -> CHOQUE PERALTA JHOEL ELIAZAR | C16: 74 | F16: =IF(ROUND((C16+D16+E16)/3,0)>0,ROUND((C16+D16+E16)/3,0)," ") -> 25
A17: =NOMINA!A17 -> 12 | B17: =NOMINA!B17 -> COPA RIVERO MARCIA MARCELA | C17: 80 | F17: =IF(ROUND((C17+D17+E17)/3,0)>0,ROUND((C17+D17+E17)/3,0)," ") -> 27
... A40: =NOMINA!A40 -> 35 | B40: =NOMINA!B40 -> ZAMBRANA MENDEZ MIRCO ALEXANDER | C40: 51 | F40: =IF(ROUND((C40+D40+E40)/3,0)>0,ROUND((C40+D40+E40)/3,0)," ") -> 17
A41: =NOMINA!A41 -> 36 | B41: =NOMINA!B41 -> 0 | F41: =IF(ROUND((C41+D41+E41)/3,0)>0,ROUND((C41+D41+E41)/3,0)," ")
A42: =NOMINA!A42 -> 37 | B42: =NOMINA!B42 -> 0 | F42: =IF(ROUND((C42+D42+E42)/3,0)>0,ROUND((C42+D42+E42)/3,0)," ")
A43: =NOMINA!A43 -> 38 | B43: =NOMINA!B43 -> 0 | F43: =IF(ROUND((C43+D43+E43)/3,0)>0,ROUND((C43+D43+E43)/3,0)," ")
A44: =NOMINA!A44 -> 39 | B44: =NOMINA!B44 -> 0 | F44: =IF(ROUND((C44+D44+E44)/3,0)>0,ROUND((C44+D44+E44)/3,0)," ")
A45: =NOMINA!A45 -> 40 | B45: =NOMINA!B45 -> 0 | F45: =IF(ROUND((C45+D45+E45)/3,0)>0,ROUND((C45+D45+E45)/3,0)," ")
A46: =NOMINA!A46 -> 41 | B46: =NOMINA!B46 -> 0 | F46: =IF(ROUND((C46+D46+E46)/3,0)>0,ROUND((C46+D46+E46)/3,0)," ")
A47: =NOMINA!A47 -> 42 | B47: =NOMINA!B47 -> 0 | F47: =IF(ROUND((C47+D47+E47)/3,0)>0,ROUND((C47+D47+E47)/3,0)," ")
A48: =NOMINA!A48 -> 43 | B48: =NOMINA!B48 -> 0 | F48: =IF(ROUND((C48+D48+E48)/3,0)>0,ROUND((C48+D48+E48)/3,0)," ")
A49: =NOMINA!A49 -> 44 | B49: =NOMINA!B49 -> 0 | F49: =IF(ROUND((C49+D49+E49)/3,0)>0,ROUND((C49+D49+E49)/3,0)," ")
A50: =NOMINA!A50 -> 45 | B50: =NOMINA!B50 -> 0 | F50: =IF(ROUND((C50+D50+E50)/3,0)>0,ROUND((C50+D50+E50)/3,0)," ")

Sheet MUS.
B2: =NOMINA!$B$2 -> CURSO 2A | D2: ED. MÚSICAL
A4: Nº | B4: APELLIDOS Y NOMBRES | C4: 1er. TRIM. | D4: 2do. TRIM. | E4: 3er. TRIM. | F4: PRO. ANUAL
C5: CUANT. | D5: CUANT. | E5: CUANT. | F5: P.TOTAL | G5: OBSERV.
A6: =NOMINA!A6 -> 1 | B6: =NOMINA!B6 -> ABREU MARRERO LIZ DANIELA | C6: 94 | F6: =IF(ROUND((C6+D6+E6)/3,0)>0,ROUND((C6+D6+E6)/3,0)," ") -> 31
A7: =NOMINA!A7 -> 2 | B7: =NOMINA!B7 -> ALIAGA SAAVEDRA MARCU MAURICIO | C7: 87 | F7: =IF(ROUND((C7+D7+E7)/3,0)>0,ROUND((C7+D7+E7)/3,0)," ") -> 29
A8: =NOMINA!A8 -> 3 | B8: =NOMINA!B8 -> ANTEZANA CACHI JOSE MAXWEL | C8: 96 | F8: =IF(ROUND((C8+D8+E8)/3,0)>0,ROUND((C8+D8+E8)/3,0)," ") -> 32
A9: =NOMINA!A9 -> 4 | B9: =NOMINA!B9 -> ARIZACA SALGUERO SANTIAGO | C9: 70 | F9: =IF(ROUND((C9+D9+E9)/3,0)>0,ROUND((C9+D9+E9)/3,0)," ") -> 23
A10: =NOMINA!A10 -> 5 | B10: =NOMINA!B10 -> BAUTISTA GARCIA ALISON LUCIANA | C10: 76 | F10: =IF(ROUND((C10+D10+E10)/3,0)>0,ROUND((C10+D10+E10)/3,0)," ") -> 25
A11: =NOMINA!A11 -> 6 | B11: =NOMINA!B11 -> BOLIVAR REVOLLO NIVARDO ADOLFO | C11: 72 | F11: =IF(ROUND((C11+D11+E11)/3,0)>0,ROUND((C11+D11+E11)/3,0)," ") -> 24
A12: =NOMINA!A12 -> 7 | B12: =NOMINA!B12 -> CADIMA SOLIZ NICOLAS | C12: 66 | F12: =IF(ROUND((C12+D12+E12)/3,0)>0,ROUND((C12+D12+E12)/3,0)," ") -> 22
A13: =NOMINA!A13 -> 8 | B13: =NOMINA!B13 -> CALLE PEREZ ANDREA BELEN | C13: 97 | F13: =IF(ROUND((C13+D13+E13)/3,0)>0,ROUND((C13+D13+E13)/3,0)," ") -> 32
A14: =NOMINA!A14 -> 9 | B14: =NOMINA!B14 -> CHAVEZ AMURRIO SEBASTIAN FABIAN | C14: 54 | F14: =IF(ROUND((C14+D14+E14)/3,0)>0,ROUND((C14+D14+E14)/3,0)," ") -> 18
A15: =NOMINA!A15 -> 10 | B15: =NOMINA!B15 -> CHOQUE ARISPE YURIANA LUCIA | C15: 58 | F15: =IF(ROUND((C15+D15+E15)/3,0)>0,ROUND((C15+D15+E15)/3,0)," ") -> 19
A16: =NOMINA!A16 -> 11 | B16: =NOMINA!B16 -> CHOQUE PERALTA JHOEL ELIAZAR | C16: 94 | F16: =IF(ROUND((C16+D16+E16)/3,0)>0,ROUND((C16+D16+E16)/3,0)," ") -> 31
A17: =NOMINA!A17 -> 12 | B17: =NOMINA!B17 -> COPA RIVERO MARCIA MARCELA | C17: 70 | F17: =IF(ROUND((C17+D17+E17)/3,0)>0,ROUND((C17+D17+E17)/3,0)," ") -> 23
... A40: =NOMINA!A40 -> 35 | B40: =NOMINA!B40 -> ZAMBRANA MENDEZ MIRCO ALEXANDER | C40: 57 | F40: =IF(ROUND((C40+D40+E40)/3,0)>0,ROUND((C40+D40+E40)/3,0)," ") -> 19
A41: =NOMINA!A41 -> 36 | B41: =NOMINA!B41 -> 0 | F41: =IF(ROUND((C41+D41+E41)/3,0)>0,ROUND((C41+D41+E41)/3,0)," ")
A42: =NOMINA!A42 -> 37 | B42: =NOMINA!B42 -> 0 | F42: =IF(ROUND((C42+D42+E42)/3,0)>0,ROUND((C42+D42+E42)/3,0)," ")
A43: =NOMINA!A43 -> 38 | B43: =NOMINA!B43 -> 0 | F43: =IF(ROUND((C43+D43+E43)/3,0)>0,ROUND((C43+D43+E43)/3,0)," ")
A44: =NOMINA!A44 -> 39 | B44: =NOMINA!B44 -> 0 | F44: =IF(ROUND((C44+D44+E44)/3,0)>0,ROUND((C44+D44+E44)/3,0)," ")
A45: =NOMINA!A45 -> 40 | B45: =NOMINA!B45 -> 0 | F45: =IF(ROUND((C45+D45+E45)/3,0)>0,ROUND((C45+D45+E45)/3,0)," ")
A46: =NOMINA!A46 -> 41 | B46: =NOMINA!B46 -> 0 | F46: =IF(ROUND((C46+D46+E46)/3,0)>0,ROUND((C46+D46+E46)/3,0)," ")
A47: =NOMINA!A47 -> 42 | B47: =NOMINA!B47 -> 0 | F47: =IF(ROUND((C47+D47+E47)/3,0)>0,ROUND((C47+D47+E47)/3,0)," ")
A48: =NOMINA!A48 -> 43 | B48: =NOMINA!B48 -> 0 | F48: =IF(ROUND((C48+D48+E48)/3,0)>0,ROUND((C48+D48+E48)/3,0)," ")
A49: =NOMINA!A49 -> 44 | B49: =NOMINA!B49 -> 0 | F49: =IF(ROUND((C49+D49+E49)/3,0)>0,ROUND((C49+D49+E49)/3,0)," ")
A50: =NOMINA!A50 -> 45 | B50: =NOMINA!B50 -> 0 | F50: =IF(ROUND((C50+D50+E50)/3,0)>0,ROUND((C50+D50+E50)/3,0)," ")

Sheet A.PL. 
B2: =NOMINA!$B$2 -> CURSO 2A | D2: ART. PLÁSTICAS
A4: Nº | B4: APELLIDOS Y NOMBRES | C4: 1er. TRIM. | D4: 2do. TRIM. | E4: 3er. TRIM. | F4: PRO. ANUAL
C5: CUANT. | D5: CUANT. | E5: CUANT. | F5: P.TOTAL | G5: OBSERV.
A6: =NOMINA!A6 -> 1 | B6: =NOMINA!B6 -> ABREU MARRERO LIZ DANIELA | C6: 71 | F6: =IF(ROUND((C6+D6+E6)/3,0)>0,ROUND((C6+D6+E6)/3,0)," ") -> 24
A7: =NOMINA!A7 -> 2 | B7: =NOMINA!B7 -> ALIAGA SAAVEDRA MARCU MAURICIO | C7: 55 | F7: =IF(ROUND((C7+D7+E7)/3,0)>0,ROUND((C7+D7+E7)/3,0)," ") -> 18
A8: =NOMINA!A8 -> 3 | B8: =NOMINA!B8 -> ANTEZANA CACHI JOSE MAXWEL | C8: 59 | F8: =IF(ROUND((C8+D8+E8)/3,0)>0,ROUND((C8+D8+E8)/3,0)," ") -> 20
A9: =NOMINA!A9 -> 4 | B9: =NOMINA!B9 -> ARIZACA SALGUERO SANTIAGO | C9: 63 | F9: =IF(ROUND((C9+D9+E9)/3,0)>0,ROUND((C9+D9+E9)/3,0)," ") -> 21
A10: =NOMINA!A10 -> 5 | B10: =NOMINA!B10 -> BAUTISTA GARCIA ALISON LUCIANA | C10: 71 | F10: =IF(ROUND((C10+D10+E10)/3,0)>0,ROUND((C10+D10+E10)/3,0)," ") -> 24
A11: =NOMINA!A11 -> 6 | B11: =NOMINA!B11 -> BOLIVAR REVOLLO NIVARDO ADOLFO | C11: 53 | F11: =IF(ROUND((C11+D11+E11)/3,0)>0,ROUND((C11+D11+E11)/3,0)," ") -> 18
A12: =NOMINA!A12 -> 7 | B12: =NOMINA!B12 -> CADIMA SOLIZ NICOLAS | C12: 59 | F12: =IF(ROUND((C12+D12+E12)/3,0)>0,ROUND((C12+D12+E12)/3,0)," ") -> 20
A13: =NOMINA!A13 -> 8 | B13: =NOMINA!B13 -> CALLE PEREZ ANDREA BELEN | C13: 69 | F13: =IF(ROUND((C13+D13+E13)/3,0)>0,ROUND((C13+D13+E13)/3,0)," ") -> 23
A14: =NOMINA!A14 -> 9 | B14: =NOMINA!B14 -> CHAVEZ AMURRIO SEBASTIAN FABIAN | C14: 67 | F14: =IF(ROUND((C14+D14+E14)/3,0)>0,ROUND((C14+D14+E14)/3,0)," ") -> 22
A15: =NOMINA!A15 -> 10 | B15: =NOMINA!B15 -> CHOQUE ARISPE YURIANA LUCIA | C15: 66 | F15: =IF(ROUND((C15+D15+E15)/3,0)>0,ROUND((C15+D15+E15)/3,0)," ") -> 22
A16: =NOMINA!A16 -> 11 | B16: =NOMINA!B16 -> CHOQUE PERALTA JHOEL ELIAZAR | C16: 73 | F16: =IF(ROUND((C16+D16+E16)/3,0)>0,ROUND((C16+D16+E16)/3,0)," ") -> 24
A17: =NOMINA!A17 -> 12 | B17: =NOMINA!B17 -> COPA RIVERO MARCIA MARCELA | C17: 61 | F17: =IF(ROUND((C17+D17+E17)/3,0)>0,ROUND((C17+D17+E17)/3,0)," ") -> 20
... A40: =NOMINA!A40 -> 35 | B40: =NOMINA!B40 -> ZAMBRANA MENDEZ MIRCO ALEXANDER | C40: 70 | F40: =IF(ROUND((C40+D40+E40)/3,0)>0,ROUND((C40+D40+E40)/3,0)," ") -> 23
A41: =NOMINA!A41 -> 36 | B41: =NOMINA!B41 -> 0 | F41: =IF(ROUND((C41+D41+E41)/3,0)>0,ROUND((C41+D41+E41)/3,0)," ")
A42: =NOMINA!A42 -> 37 | B42: =NOMINA!B42 -> 0 | F42: =IF(ROUND((C42+D42+E42)/3,0)>0,ROUND((C42+D42+E42)/3,0)," ")
A43: =NOMINA!A43 -> 38 | B43: =NOMINA!B43 -> 0 | F43: =IF(ROUND((C43+D43+E43)/3,0)>0,ROUND((C43+D43+E43)/3,0)," ")
A44: =NOMINA!A44 -> 39 | B44: =NOMINA!B44 -> 0 | F44: =IF(ROUND((C44+D44+E44)/3,0)>0,ROUND((C44+D44+E44)/3,0)," ")
A45: =NOMINA!A45 -> 40 | B45: =NOMINA!B45 -> 0 | F45: =IF(ROUND((C45+D45+E45)/3,0)>0,ROUND((C45+D45+E45)/3,0)," ")
A46: =NOMINA!A46 -> 41 | B46: =NOMINA!B46 -> 0 | F46: =IF(ROUND((C46+D46+E46)/3,0)>0,ROUND((C46+D46+E46)/3,0)," ")
A47: =NOMINA!A47 -> 42 | B47: =NOMINA!B47 -> 0 | F47: =IF(ROUND((C47+D47+E47)/3,0)>0,ROUND((C47+D47+E47)/3,0)," ")
A48: =NOMINA!A48 -> 43 | B48: =NOMINA!B48 -> 0 | F48: =IF(ROUND((C48+D48+E48)/3,0)>0,ROUND((C48+D48+E48)/3,0)," ")
A49: =NOMINA!A49 -> 44 | B49: =NOMINA!B49 -> 0 | F49: =IF(ROUND((C49+D49+E49)/3,0)>0,ROUND((C49+D49+E49)/3,0)," ")
A50: =NOMINA!A50 -> 45 | B50: =NOMINA!B50 -> 0 | F50: =IF(ROUND((C50+D50+E50)/3,0)>0,ROUND((C50+D50+E50)/3,0)," ")

Sheet MAT
B2: =NOMINA!$B$2 -> CURSO 2A | D2: MATEMATICAS
A4: Nº | B4: APELLIDOS Y NOMBRES | C4: 1er. TRIM. | D4: 2do. TRIM. | E4: 3er. TRIM. | F4: PRO. ANUAL
C5: CUANT. | D5: CUANT. | E5: CUANT. | F5: P.TOTAL | G5: OBSERV.
A6: =NOMINA!A6 -> 1 | B6: =NOMINA!B6 -> ABREU MARRERO LIZ DANIELA | C6: 64 | F6: =IF(ROUND((C6+D6+E6)/3,0)>0,ROUND((C6+D6+E6)/3,0)," ") -> 21
A7: =NOMINA!A7 -> 2 | B7: =NOMINA!B7 -> ALIAGA SAAVEDRA MARCU MAURICIO | C7: 59 | F7: =IF(ROUND((C7+D7+E7)/3,0)>0,ROUND((C7+D7+E7)/3,0)," ") -> 20
A8: =NOMINA!A8 -> 3 | B8: =NOMINA!B8 -> ANTEZANA CACHI JOSE MAXWEL | C8: 91 | F8: =IF(ROUND((C8+D8+E8)/3,0)>0,ROUND((C8+D8+E8)/3,0)," ") -> 30
A9: =NOMINA!A9 -> 4 | B9: =NOMINA!B9 -> ARIZACA SALGUERO SANTIAGO | C9: 61 | F9: =IF(ROUND((C9+D9+E9)/3,0)>0,ROUND((C9+D9+E9)/3,0)," ") -> 20
A10: =NOMINA!A10 -> 5 | B10: =NOMINA!B10 -> BAUTISTA GARCIA ALISON LUCIANA | C10: 58 | F10: =IF(ROUND((C10+D10+E10)/3,0)>0,ROUND((C10+D10+E10)/3,0)," ") -> 19
A11: =NOMINA!A11 -> 6 | B11: =NOMINA!B11 -> BOLIVAR REVOLLO NIVARDO ADOLFO | C11: 46 | F11: =IF(ROUND((C11+D11+E11)/3,0)>0,ROUND((C11+D11+E11)/3,0)," ") -> 15
A12: =NOMINA!A12 -> 7 | B12: =NOMINA!B12 -> CADIMA SOLIZ NICOLAS | C12: 46 | F12: =IF(ROUND((C12+D12+E12)/3,0)>0,ROUND((C12+D12+E12)/3,0)," ") -> 15
A13: =NOMINA!A13 -> 8 | B13: =NOMINA!B13 -> CALLE PEREZ ANDREA BELEN | C13: 93 | F13: =IF(ROUND((C13+D13+E13)/3,0)>0,ROUND((C13+D13+E13)/3,0)," ") -> 31
A14: =NOMINA!A14 -> 9 | B14: =NOMINA!B14 -> CHAVEZ AMURRIO SEBASTIAN FABIAN | C14: 49 | F14: =IF(ROUND((C14+D14+E14)/3,0)>0,ROUND((C14+D14+E14)/3,0)," ") -> 16
A15: =NOMINA!A15 -> 10 | B15: =NOMINA!B15 -> CHOQUE ARISPE YURIANA LUCIA | C15: 52 | F15: =IF(ROUND((C15+D15+E15)/3,0)>0,ROUND((C15+D15+E15)/3,0)," ") -> 17
A16: =NOMINA!A16 -> 11 | B16: =NOMINA!B16 -> CHOQUE PERALTA JHOEL ELIAZAR | C16: 83 | F16: =IF(ROUND((C16+D16+E16)/3,0)>0,ROUND((C16+D16+E16)/3,0)," ") -> 28
A17: =NOMINA!A17 -> 12 | B17: =NOMINA!B17 -> COPA RIVERO MARCIA MARCELA | C17: 52 | F17: =IF(ROUND((C17+D17+E17)/3,0)>0,ROUND((C17+D17+E17)/3,0)," ") -> 17
... A40: =NOMINA!A40 -> 35 | B40: =NOMINA!B40 -> ZAMBRANA MENDEZ MIRCO ALEXANDER | C40: 47 | F40: =IF(ROUND((C40+D40+E40)/3,0)>0,ROUND((C40+D40+E40)/3,0)," ") -> 16
A41: =NOMINA!A41 -> 36 | B41: =NOMINA!B41 -> 0 | F41: =IF(ROUND((C41+D41+E41)/3,0)>0,ROUND((C41+D41+E41)/3,0)," ")
A42: =NOMINA!A42 -> 37 | B42: =NOMINA!B42 -> 0 | F42: =IF(ROUND((C42+D42+E42)/3,0)>0,ROUND((C42+D42+E42)/3,0)," ")
A43: =NOMINA!A43 -> 38 | B43: =NOMINA!B43 -> 0 | F43: =IF(ROUND((C43+D43+E43)/3,0)>0,ROUND((C43+D43+E43)/3,0)," ")
A44: =NOMINA!A44 -> 39 | B44: =NOMINA!B44 -> 0 | F44: =IF(ROUND((C44+D44+E44)/3,0)>0,ROUND((C44+D44+E44)/3,0)," ")
A45: =NOMINA!A45 -> 40 | B45: =NOMINA!B45 -> 0 | F45: =IF(ROUND((C45+D45+E45)/3,0)>0,ROUND((C45+D45+E45)/3,0)," ")
A46: =NOMINA!A46 -> 41 | B46: =NOMINA!B46 -> 0 | F46: =IF(ROUND((C46+D46+E46)/3,0)>0,ROUND((C46+D46+E46)/3,0)," ")
A47: =NOMINA!A47 -> 42 | B47: =NOMINA!B47 -> 0 | F47: =IF(ROUND((C47+D47+E47)/3,0)>0,ROUND((C47+D47+E47)/3,0)," ")
A48: =NOMINA!A48 -> 43 | B48: =NOMINA!B48 -> 0 | F48: =IF(ROUND((C48+D48+E48)/3,0)>0,ROUND((C48+D48+E48)/3,0)," ")
A49: =NOMINA!A49 -> 44 | B49: =NOMINA!B49 -> 0 | F49: =IF(ROUND((C49+D49+E49)/3,0)>0,ROUND((C49+D49+E49)/3,0)," ")
A50: =NOMINA!A50 -> 45 | B50: =NOMINA!B50 -> 0 | F50: =IF(ROUND((C50+D50+E50)/3,0)>0,ROUND((C50+D50+E50)/3,0)," ")

Sheet T. TEC. GRAL
B2: =NOMINA!$B$2 -> CURSO 2A | C2: TÉCNICA TECNOLÓGICA GENERAL
A4: Nº | B4: APELLIDOS Y NOMBRES | C4: 1er. TRIM. | D4: 2do. TRIM. | E4: 3er. TRIM. | F4: PRO. ANUAL
C5: CUANT. | D5: CUANT. | E5: CUANT. | F5: P.TOTAL | G5: OBSERV.
A6: =NOMINA!A6 -> 1 | B6: =NOMINA!B6 -> ABREU MARRERO LIZ DANIELA | C6: 66 | F6: =IF(ROUND((C6+D6+E6)/3,0)>0,ROUND((C6+D6+E6)/3,0)," ") -> 22
A7: =NOMINA!A7 -> 2 | B7: =NOMINA!B7 -> ALIAGA SAAVEDRA MARCU MAURICIO | C7: 63 | F7: =IF(ROUND((C7+D7+E7)/3,0)>0,ROUND((C7+D7+E7)/3,0)," ") -> 21
A8: =NOMINA!A8 -> 3 | B8: =NOMINA!B8 -> ANTEZANA CACHI JOSE MAXWEL | C8: 65 | F8: =IF(ROUND((C8+D8+E8)/3,0)>0,ROUND((C8+D8+E8)/3,0)," ") -> 22
A9: =NOMINA!A9 -> 4 | B9: =NOMINA!B9 -> ARIZACA SALGUERO SANTIAGO | C9: 68 | F9: =IF(ROUND((C9+D9+E9)/3,0)>0,ROUND((C9+D9+E9)/3,0)," ") -> 23
A10: =NOMINA!A10 -> 5 | B10: =NOMINA!B10 -> BAUTISTA GARCIA ALISON LUCIANA | C10: 71 | F10: =IF(ROUND((C10+D10+E10)/3,0)>0,ROUND((C10+D10+E10)/3,0)," ") -> 24
A11: =NOMINA!A11 -> 6 | B11: =NOMINA!B11 -> BOLIVAR REVOLLO NIVARDO ADOLFO | C11: 66 | F11: =IF(ROUND((C11+D11+E11)/3,0)>0,ROUND((C11+D11+E11)/3,0)," ") -> 22
A12: =NOMINA!A12 -> 7 | B12: =NOMINA!B12 -> CADIMA SOLIZ NICOLAS | C12: 57 | F12: =IF(ROUND((C12+D12+E12)/3,0)>0,ROUND((C12+D12+E12)/3,0)," ") -> 19
A13: =NOMINA!A13 -> 8 | B13: =NOMINA!B13 -> CALLE PEREZ ANDREA BELEN | C13: 79 | F13: =IF(ROUND((C13+D13+E13)/3,0)>0,ROUND((C13+D13+E13)/3,0)," ") -> 26
A14: =NOMINA!A14 -> 9 | B14: =NOMINA!B14 -> CHAVEZ AMURRIO SEBASTIAN FABIAN | C14: 44 | F14: =IF(ROUND((C14+D14+E14)/3,0)>0,ROUND((C14+D14+E14)/3,0)," ") -> 15
A15: =NOMINA!A15 -> 10 | B15: =NOMINA!B15 -> CHOQUE ARISPE YURIANA LUCIA | C15: 67 | F15: =IF(ROUND((C15+D15+E15)/3,0)>0,ROUND((C15+D15+E15)/3,0)," ") -> 22
A16: =NOMINA!A16 -> 11 | B16: =NOMINA!B16 -> CHOQUE PERALTA JHOEL ELIAZAR | C16: 65 | F16: =IF(ROUND((C16+D16+E16)/3,0)>0,ROUND((C16+D16+E16)/3,0)," ") -> 22
A17: =NOMINA!A17 -> 12 | B17: =NOMINA!B17 -> COPA RIVERO MARCIA MARCELA | C17: 56 | F17: =IF(ROUND((C17+D17+E17)/3,0)>0,ROUND((C17+D17+E17)/3,0)," ") -> 19
... A40: =NOMINA!A40 -> 35 | B40: =NOMINA!B40 -> ZAMBRANA MENDEZ MIRCO ALEXANDER | C40: 43 | F40: =IF(ROUND((C40+D40+E40)/3,0)>0,ROUND((C40+D40+E40)/3,0)," ") -> 14
A41: =NOMINA!A41 -> 36 | B41: =NOMINA!B41 -> 0 | F41: =IF(ROUND((C41+D41+E41)/3,0)>0,ROUND((C41+D41+E41)/3,0)," ")
A42: =NOMINA!A42 -> 37 | B42: =NOMINA!B42 -> 0 | F42: =IF(ROUND((C42+D42+E42)/3,0)>0,ROUND((C42+D42+E42)/3,0)," ")
A43: =NOMINA!A43 -> 38 | B43: =NOMINA!B43 -> 0 | F43: =IF(ROUND((C43+D43+E43)/3,0)>0,ROUND((C43+D43+E43)/3,0)," ")
A44: =NOMINA!A44 -> 39 | B44: =NOMINA!B44 -> 0 | F44: =IF(ROUND((C44+D44+E44)/3,0)>0,ROUND((C44+D44+E44)/3,0)," ")
A45: =NOMINA!A45 -> 40 | B45: =NOMINA!B45 -> 0 | F45: =IF(ROUND((C45+D45+E45)/3,0)>0,ROUND((C45+D45+E45)/3,0)," ")
A46: =NOMINA!A46 -> 41 | B46: =NOMINA!B46 -> 0 | F46: =IF(ROUND((C46+D46+E46)/3,0)>0,ROUND((C46+D46+E46)/3,0)," ")
A47: =NOMINA!A47 -> 42 | B47: =NOMINA!B47 -> 0 | F47: =IF(ROUND((C47+D47+E47)/3,0)>0,ROUND((C47+D47+E47)/3,0)," ")
A48: =NOMINA!A48 -> 43 | B48: =NOMINA!B48 -> 0 | F48: =IF(ROUND((C48+D48+E48)/3,0)>0,ROUND((C48+D48+E48)/3,0)," ")
A49: =NOMINA!A49 -> 44 | B49: =NOMINA!B49 -> 0 | F49: =IF(ROUND((C49+D49+E49)/3,0)>0,ROUND((C49+D49+E49)/3,0)," ")
A50: =NOMINA!A50 -> 45 | B50: =NOMINA!B50 -> 0 | F50: =IF(ROUND((C50+D50+E50)/3,0)>0,ROUND((C50+D50+E50)/3,0)," ")

Sheet BIO-GEO
B2: =NOMINA!$B$2 -> CURSO 2A | C2: BIOLOGÍA - GEOGRAFÍA
A4: Nº | B4: APELLIDOS Y NOMBRES | C4: 1er. TRIM. | D4: 2do. TRIM. | E4: 3er. TRIM. | F4: PRO. ANUAL
C5: CUANT. | D5: CUANT. | E5: CUANT. | F5: P.TOTAL | G5: OBSERV.
A6: =NOMINA!A6 -> 1 | B6: =NOMINA!B6 -> ABREU MARRERO LIZ DANIELA | C6: 77 | F6: =IF(ROUND((C6+D6+E6)/3,0)>0,ROUND((C6+D6+E6)/3,0)," ") -> 26
A7: =NOMINA!A7 -> 2 | B7: =NOMINA!B7 -> ALIAGA SAAVEDRA MARCU MAURICIO | C7: 74 | F7: =IF(ROUND((C7+D7+E7)/3,0)>0,ROUND((C7+D7+E7)/3,0)," ") -> 25
A8: =NOMINA!A8 -> 3 | B8: =NOMINA!B8 -> ANTEZANA CACHI JOSE MAXWEL | C8: 75 | F8: =IF(ROUND((C8+D8+E8)/3,0)>0,ROUND((C8+D8+E8)/3,0)," ") -> 25
A9: =NOMINA!A9 -> 4 | B9: =NOMINA!B9 -> ARIZACA SALGUERO SANTIAGO | C9: 77 | F9: =IF(ROUND((C9+D9+E9)/3,0)>0,ROUND((C9+D9+E9)/3,0)," ") -> 26
A10: =NOMINA!A10 -> 5 | B10: =NOMINA!B10 -> BAUTISTA GARCIA ALISON LUCIANA | C10: 70 | F10: =IF(ROUND((C10+D10+E10)/3,0)>0,ROUND((C10+D10+E10)/3,0)," ") -> 23
A11: =NOMINA!A11 -> 6 | B11: =NOMINA!B11 -> BOLIVAR REVOLLO NIVARDO ADOLFO | C11: 61 | F11: =IF(ROUND((C11+D11+E11)/3,0)>0,ROUND((C11+D11+E11)/3,0)," ") -> 20
A12: =NOMINA!A12 -> 7 | B12: =NOMINA!B12 -> CADIMA SOLIZ NICOLAS | C12: 67 | F12: =IF(ROUND((C12+D12+E12)/3,0)>0,ROUND((C12+D12+E12)/3,0)," ") -> 22
A13: =NOMINA!A13 -> 8 | B13: =NOMINA!B13 -> CALLE PEREZ ANDREA BELEN | C13: 83 | F13: =IF(ROUND((C13+D13+E13)/3,0)>0,ROUND((C13+D13+E13)/3,0)," ") -> 28
A14: =NOMINA!A14 -> 9 | B14: =NOMINA!B14 -> CHAVEZ AMURRIO SEBASTIAN FABIAN | C14: 35 | F14: =IF(ROUND((C14+D14+E14)/3,0)>0,ROUND((C14+D14+E14)/3,0)," ") -> 12
A15: =NOMINA!A15 -> 10 | B15: =NOMINA!B15 -> CHOQUE ARISPE YURIANA LUCIA | C15: 67 | F15: =IF(ROUND((C15+D15+E15)/3,0)>0,ROUND((C15+D15+E15)/3,0)," ") -> 22
A16: =NOMINA!A16 -> 11 | B16: =NOMINA!B16 -> CHOQUE PERALTA JHOEL ELIAZAR | C16: 82 | F16: =IF(ROUND((C16+D16+E16)/3,0)>0,ROUND((C16+D16+E16)/3,0)," ") -> 27
A17: =NOMINA!A17 -> 12 | B17: =NOMINA!B17 -> COPA RIVERO MARCIA MARCELA | C17: 59 | F17: =IF(ROUND((C17+D17+E17)/3,0)>0,ROUND((C17+D17+E17)/3,0)," ") -> 20
... A40: =NOMINA!A40 -> 35 | B40: =NOMINA!B40 -> ZAMBRANA MENDEZ MIRCO ALEXANDER | C40: 61 | F40: =IF(ROUND((C40+D40+E40)/3,0)>0,ROUND((C40+D40+E40)/3,0)," ") -> 20
A41: =NOMINA!A41 -> 36 | B41: =NOMINA!B41 -> 0 | F41: =IF(ROUND((C41+D41+E41)/3,0)>0,ROUND((C41+D41+E41)/3,0)," ")
A42: =NOMINA!A42 -> 37 | B42: =NOMINA!B42 -> 0 | F42: =IF(ROUND((C42+D42+E42)/3,0)>0,ROUND((C42+D42+E42)/3,0)," ")
A43: =NOMINA!A43 -> 38 | B43: =NOMINA!B43 -> 0 | F43: =IF(ROUND((C43+D43+E43)/3,0)>0,ROUND((C43+D43+E43)/3,0)," ")
A44: =NOMINA!A44 -> 39 | B44: =NOMINA!B44 -> 0 | F44: =IF(ROUND((C44+D44+E44)/3,0)>0,ROUND((C44+D44+E44)/3,0)," ")
A45: =NOMINA!A45 -> 40 | B45: =NOMINA!B45 -> 0 | F45: =IF(ROUND((C45+D45+E45)/3,0)>0,ROUND((C45+D45+E45)/3,0)," ")
A46: =NOMINA!A46 -> 41 | B46: =NOMINA!B46 -> 0 | F46: =IF(ROUND((C46+D46+E46)/3,0)>0,ROUND((C46+D46+E46)/3,0)," ")
A47: =NOMINA!A47 -> 42 | B47: =NOMINA!B47 -> 0 | F47: =IF(ROUND((C47+D47+E47)/3,0)>0,ROUND((C47+D47+E47)/3,0)," ")
A48: =NOMINA!A48 -> 43 | B48: =NOMINA!B48 -> 0 | F48: =IF(ROUND((C48+D48+E48)/3,0)>0,ROUND((C48+D48+E48)/3,0)," ")
A49: =NOMINA!A49 -> 44 | B49: =NOMINA!B49 -> 0 | F49: =IF(ROUND((C49+D49+E49)/3,0)>0,ROUND((C49+D49+E49)/3,0)," ")
A50: =NOMINA!A50 -> 45 | B50: =NOMINA!B50 -> 0 | F50: =IF(ROUND((C50+D50+E50)/3,0)>0,ROUND((C50+D50+E50)/3,0)," ")

Sheet PSI
B2: =NOMINA!$B$2 -> CURSO 2A | C2: PSICOLOGÍA -FILOSOFÍA
A4: Nº | B4: APELLIDOS Y NOMBRES | C4: 1er. TRIM. | D4: 2do. TRIM. | E4: 3er. TRIM. | F4: PRO. ANUAL
C5: CUANT. | D5: CUANT. | E5: CUANT. | F5: P.TOTAL | G5: OBSERV.
A6: =NOMINA!A6 -> 1 | B6: =NOMINA!B6 -> ABREU MARRERO LIZ DANIELA | C6: 74 | F6: =IF(ROUND((C6+D6+E6)/3,0)>0,ROUND((C6+D6+E6)/3,0)," ") -> 25
A7: =NOMINA!A7 -> 2 | B7: =NOMINA!B7 -> ALIAGA SAAVEDRA MARCU MAURICIO | C7: 80 | F7: =IF(ROUND((C7+D7+E7)/3,0)>0,ROUND((C7+D7+E7)/3,0)," ") -> 27
A8: =NOMINA!A8 -> 3 | B8: =NOMINA!B8 -> ANTEZANA CACHI JOSE MAXWEL | C8: 85 | F8: =IF(ROUND((C8+D8+E8)/3,0)>0,ROUND((C8+D8+E8)/3,0)," ") -> 28
A9: =NOMINA!A9 -> 4 | B9: =NOMINA!B9 -> ARIZACA SALGUERO SANTIAGO | C9: 51 | F9: =IF(ROUND((C9+D9+E9)/3,0)>0,ROUND((C9+D9+E9)/3,0)," ") -> 17
A10: =NOMINA!A10 -> 5 | B10: =NOMINA!B10 -> BAUTISTA GARCIA ALISON LUCIANA | C10: 66 | F10: =IF(ROUND((C10+D10+E10)/3,0)>0,ROUND((C10+D10+E10)/3,0)," ") -> 22
A11: =NOMINA!A11 -> 6 | B11: =NOMINA!B11 -> BOLIVAR REVOLLO NIVARDO ADOLFO | C11: 64 | F11: =IF(ROUND((C11+D11+E11)/3,0)>0,ROUND((C11+D11+E11)/3,0)," ") -> 21
A12: =NOMINA!A12 -> 7 | B12: =NOMINA!B12 -> CADIMA SOLIZ NICOLAS | C12: 67 | F12: =IF(ROUND((C12+D12+E12)/3,0)>0,ROUND((C12+D12+E12)/3,0)," ") -> 22
A13: =NOMINA!A13 -> 8 | B13: =NOMINA!B13 -> CALLE PEREZ ANDREA BELEN | C13: 81 | F13: =IF(ROUND((C13+D13+E13)/3,0)>0,ROUND((C13+D13+E13)/3,0)," ") -> 27
A14: =NOMINA!A14 -> 9 | B14: =NOMINA!B14 -> CHAVEZ AMURRIO SEBASTIAN FABIAN | C14: 45 | F14: =IF(ROUND((C14+D14+E14)/3,0)>0,ROUND((C14+D14+E14)/3,0)," ") -> 15
A15: =NOMINA!A15 -> 10 | B15: =NOMINA!B15 -> CHOQUE ARISPE YURIANA LUCIA | C15: 67 | F15: =IF(ROUND((C15+D15+E15)/3,0)>0,ROUND((C15+D15+E15)/3,0)," ") -> 22
A16: =NOMINA!A16 -> 11 | B16: =NOMINA!B16 -> CHOQUE PERALTA JHOEL ELIAZAR | C16: 83 | F16: =IF(ROUND((C16+D16+E16)/3,0)>0,ROUND((C16+D16+E16)/3,0)," ") -> 28
A17: =NOMINA!A17 -> 12 | B17: =NOMINA!B17 -> COPA RIVERO MARCIA MARCELA | C17: 51 | F17: =IF(ROUND((C17+D17+E17)/3,0)>0,ROUND((C17+D17+E17)/3,0)," ") -> 17
... A40: =NOMINA!A40 -> 35 | B40: =NOMINA!B40 -> ZAMBRANA MENDEZ MIRCO ALEXANDER | C40: 69 | F40: =IF(ROUND((C40+D40+E40)/3,0)>0,ROUND((C40+D40+E40)/3,0)," ") -> 23
A41: =NOMINA!A41 -> 36 | B41: =NOMINA!B41 -> 0 | F41: =IF(ROUND((C41+D41+E41)/3,0)>0,ROUND((C41+D41+E41)/3,0)," ")
A42: =NOMINA!A42 -> 37 | B42: =NOMINA!B42 -> 0 | F42: =IF(ROUND((C42+D42+E42)/3,0)>0,ROUND((C42+D42+E42)/3,0)," ")
A43: =NOMINA!A43 -> 38 | B43: =NOMINA!B43 -> 0 | F43: =IF(ROUND((C43+D43+E43)/3,0)>0,ROUND((C43+D43+E43)/3,0)," ")
A44: =NOMINA!A44 -> 39 | B44: =NOMINA!B44 -> 0 | F44: =IF(ROUND((C44+D44+E44)/3,0)>0,ROUND((C44+D44+E44)/3,0)," ")
A45: =NOMINA!A45 -> 40 | B45: =NOMINA!B45 -> 0 | F45: =IF(ROUND((C45+D45+E45)/3,0)>0,ROUND((C45+D45+E45)/3,0)," ")
A46: =NOMINA!A46 -> 41 | B46: =NOMINA!B46 -> 0 | F46: =IF(ROUND((C46+D46+E46)/3,0)>0,ROUND((C46+D46+E46)/3,0)," ")
A47: =NOMINA!A47 -> 42 | B47: =NOMINA!B47 -> 0 | F47: =IF(ROUND((C47+D47+E47)/3,0)>0,ROUND((C47+D47+E47)/3,0)," ")
A48: =NOMINA!A48 -> 43 | B48: =NOMINA!B48 -> 0 | F48: =IF(ROUND((C48+D48+E48)/3,0)>0,ROUND((C48+D48+E48)/3,0)," ")
A49: =NOMINA!A49 -> 44 | B49: =NOMINA!B49 -> 0 | F49: =IF(ROUND((C49+D49+E49)/3,0)>0,ROUND((C49+D49+E49)/3,0)," ")
A50: =NOMINA!A50 -> 45 | B50: =NOMINA!B50 -> 0 | F50: =IF(ROUND((C50+D50+E50)/3,0)>0,ROUND((C50+D50+E50)/3,0)," ")

Sheet REL.
B2: =NOMINA!$B$2 -> CURSO 2A | D2: RELIGION
A4: Nº | B4: APELLIDOS Y NOMBRES | C4: 1er. TRIM. | D4: 2do. TRIM. | E4: 3er. TRIM. | F4: PRO. ANUAL
C5: CUANT. | D5: CUANT. | E5: CUANT. | F5: P.TOTAL | G5: OBSERV.
A6: =NOMINA!A6 -> 1 | B6: =NOMINA!B6 -> ABREU MARRERO LIZ DANIELA | C6: =[1]CENTRALIZADOR!C7 -> 64.666667 | F6: =IF(ROUND((C6+D6+E6)/3,0)>0,ROUND((C6+D6+E6)/3,0)," ") -> 22
A7: =NOMINA!A7 -> 2 | B7: =NOMINA!B7 -> ALIAGA SAAVEDRA MARCU MAURICIO | C7: =[1]CENTRALIZADOR!C8 -> 62.416667 | F7: =IF(ROUND((C7+D7+E7)/3,0)>0,ROUND((C7+D7+E7)/3,0)," ") -> 21
A8: =NOMINA!A8 -> 3 | B8: =NOMINA!B8 -> ANTEZANA CACHI JOSE MAXWEL | C8: =[1]CENTRALIZADOR!C9 -> 70.333333 | F8: =IF(ROUND((C8+D8+E8)/3,0)>0,ROUND((C8+D8+E8)/3,0)," ") -> 23
A9: =NOMINA!A9 -> 4 | B9: =NOMINA!B9 -> ARIZACA SALGUERO SANTIAGO | C9: =[1]CENTRALIZADOR!C10 -> 51.75 | F9: =IF(ROUND((C9+D9+E9)/3,0)>0,ROUND((C9+D9+E9)/3,0)," ") -> 17
A10: =NOMINA!A10 -> 5 | B10: =NOMINA!B10 -> BAUTISTA GARCIA ALISON LUCIANA | C10: =[1]CENTRALIZADOR!C11 -> 78.833333 | F10: =IF(ROUND((C10+D10+E10)/3,0)>0,ROUND((C10+D10+E10)/3,0)," ") -> 26
A11: =NOMINA!A11 -> 6 | B11: =NOMINA!B11 -> BOLIVAR REVOLLO NIVARDO ADOLFO | C11: =[1]CENTRALIZADOR!C12 -> 77.166667 | F11: =IF(ROUND((C11+D11+E11)/3,0)>0,ROUND((C11+D11+E11)/3,0)," ") -> 26
A12: =NOMINA!A12 -> 7 | B12: =NOMINA!B12 -> CADIMA SOLIZ NICOLAS | C12: =[1]CENTRALIZADOR!C13 -> 66.166667 | F12: =IF(ROUND((C12+D12+E12)/3,0)>0,ROUND((C12+D12+E12)/3,0)," ") -> 22
A13: =NOMINA!A13 -> 8 | B13: =NOMINA!B13 -> CALLE PEREZ ANDREA BELEN | C13: =[1]CENTRALIZADOR!C14 -> 75.666667 | F13: =IF(ROUND((C13+D13+E13)/3,0)>0,ROUND((C13+D13+E13)/3,0)," ") -> 25
A14: =NOMINA!A14 -> 9 | B14: =NOMINA!B14 -> CHAVEZ AMURRIO SEBASTIAN FABIAN | C14: =[1]CENTRALIZADOR!C15 -> 52.25 | F14: =IF(ROUND((C14+D14+E14)/3,0)>0,ROUND((C14+D14+E14)/3,0)," ") -> 17
A15: =NOMINA!A15 -> 10 | B15: =NOMINA!B15 -> CHOQUE ARISPE YURIANA LUCIA | C15: =[1]CENTRALIZADOR!C16 -> 63.75 | F15: =IF(ROUND((C15+D15+E15)/3,0)>0,ROUND((C15+D15+E15)/3,0)," ") -> 21
A16: =NOMINA!A16 -> 11 | B16: =NOMINA!B16 -> CHOQUE PERALTA JHOEL ELIAZAR | C16: =[1]CENTRALIZADOR!C17 -> 68.833333 | F16: =IF(ROUND((C16+D16+E16)/3,0)>0,ROUND((C16+D16+E16)/3,0)," ") -> 23
A17: =NOMINA!A17 -> 12 | B17: =NOMINA!B17 -> COPA RIVERO MARCIA MARCELA | C17: =[1]CENTRALIZADOR!C18 -> 70.666667 | F17: =IF(ROUND((C17+D17+E17)/3,0)>0,ROUND((C17+D17+E17)/3,0)," ") -> 24
... A40: =NOMINA!A40 -> 35 | B40: =NOMINA!B40 -> ZAMBRANA MENDEZ MIRCO ALEXANDER | C40: =[1]CENTRALIZADOR!C41 -> 51.583333 | F40: =IF(ROUND((C40+D40+E40)/3,0)>0,ROUND((C40+D40+E40)/3,0)," ") -> 17
A41: =NOMINA!A41 -> 36 | B41: =NOMINA!B41 -> 0 | F41: =IF(ROUND((C41+D41+E41)/3,0)>0,ROUND((C41+D41+E41)/3,0)," ")
A42: =NOMINA!A42 -> 37 | B42: =NOMINA!B42 -> 0 | F42: =IF(ROUND((C42+D42+E42)/3,0)>0,ROUND((C42+D42+E42)/3,0)," ")
A43: =NOMINA!A43 -> 38 | B43: =NOMINA!B43 -> 0 | F43: =IF(ROUND((C43+D43+E43)/3,0)>0,ROUND((C43+D43+E43)/3,0)," ")
A44: =NOMINA!A44 -> 39 | B44: =NOMINA!B44 -> 0 | F44: =IF(ROUND((C44+D44+E44)/3,0)>0,ROUND((C44+D44+E44)/3,0)," ")
A45: =NOMINA!A45 -> 40 | B45: =NOMINA!B45 -> 0 | F45: =IF(ROUND((C45+D45+E45)/3,0)>0,ROUND((C45+D45+E45)/3,0)," ")
A46: =NOMINA!A46 -> 41 | B46: =NOMINA!B46 -> 0 | F46: =IF(ROUND((C46+D46+E46)/3,0)>0,ROUND((C46+D46+E46)/3,0)," ")
A47: =NOMINA!A47 -> 42 | B47: =NOMINA!B47 -> 0 | F47: =IF(ROUND((C47+D47+E47)/3,0)>0,ROUND((C47+D47+E47)/3,0)," ")
A48: =NOMINA!A48 -> 43 | B48: =NOMINA!B48 -> 0 | F48: =IF(ROUND((C48+D48+E48)/3,0)>0,ROUND((C48+D48+E48)/3,0)," ")
A49: =NOMINA!A49 -> 44 | B49: =NOMINA!B49 -> 0 | F49: =IF(ROUND((C49+D49+E49)/3,0)>0,ROUND((C49+D49+E49)/3,0)," ")
A50: =NOMINA!A50 -> 45 | B50: =NOMINA!B50 -> 0 | F50: =IF(ROUND((C50+D50+E50)/3,0)>0,ROUND((C50+D50+E50)/3,0)," ")

Sheet BOLET.
C2: BOLETIN DE NOTAS
A3: U. E. ABAROA B
A4: =NOMINA!$B$2 -> CURSO 2A | C4: =NOMINA!B6 -> ABREU MARRERO LIZ DANIELA
A5: =NOMINA!A6 -> 1 | C5: GENERO | D5: FECHA DE NACIMIENTO | F5: C. I.
C6: =NOMINA!C6 -> 0 | D6: =NOMINA!D6 -> 0 | F6: =NOMINA!F6 -> 0
A7: Campos de saberes | B7: Areas curriculares | C7: 1er.TRIM | D7: 2do. TRIM. | E7: 3er. TRIM. | F7: PROM. ANUAL
C8: CUANT. | D8: CUANT. | E8: CUANT. | F8: CUANT.
A9: COMUNIDAD Y SOCIEDAD | B9: LENGUAJE | C9: =IF(LEN!C6=0," ",LEN!C6) -> 54 | D9: =IF(LEN!D6=0," ",LEN!D6) | E9: =IF(LEN!E6=0," ",LEN!E6) | F9: =IF(LEN!F6=0," ",LEN!F6) -> 18
B10: INGLES | C10: =IF(ING!C6=0," ",ING!C6) -> 60 | D10: =IF(ING!D6=0," ",ING!D6) | E10: =IF(ING!E6=0," ",ING!E6) | F10: =IF(ING!F6=0," ",ING!F6) -> 20
B11: C SOCIALES | C11: =IF('C.SOC'!C6=0," ",'C.SOC'!C6) -> 73 | D11: =IF('C.SOC'!D6=0," ",'C.SOC'!D6) | E11: =IF('C.SOC'!E6=0," ",'C.SOC'!E6) | F11: =IF('C.SOC'!F6=0," ",'C.SOC'!F6) -> 24
B12: ED. FÍSICA | C12: =IF('E. FIS.'!C6=0," ",'E. FIS.'!C6) -> 70 | D12: =IF('E. FIS.'!D6=0," ",'E. FIS.'!D6) | E12: =IF('E. FIS.'!E6=0," ",'E. FIS.'!E6) | F12: =IF('E. FIS.'!F6=0," ",'E. FIS.'!F6) -> 23
B13: MÚSICA | C13: =IF(MUS.!C6=0," ",MUS.!C6) -> 94 | D13: =IF(MUS.!D6=0," ",MUS.!D6) | E13: =IF(MUS.!E6=0," ",MUS.!E6) | F13: =IF(MUS.!F6=0," ",MUS.!F6) -> 31
B14: ARTES PLASTICAS | C14: =IF('A.PL. '!C6=0," ",'A.PL. '!C6) -> 71 | D14: =IF('A.PL. '!D6=0," ",'A.PL. '!D6) | E14: =IF('A.PL. '!E6=0," ",'A.PL. '!E6) | F14: =IF('A.PL. '!F6=0," ",'A.PL. '!F6) -> 24
A15: CIENCIA TEC Y PRODUCCIÓN | B15: MATEMÁTICAS | C15: =IF(MAT!C6=0," ",MAT!C6) -> 64 | D15: =IF(MAT!D6=0," ",MAT!D6) | E15: =IF(MAT!E6=0," ",MAT!E6) | F15: =IF(MAT!F6=0," ",MAT!F6) -> 21
B16: T. TEC. GENERAL | C16: =IF('T. TEC. GRAL'!C6=0," ",'T. TEC. GRAL'!C6) -> 66 | D16: =IF('T. TEC. GRAL'!D6=0," ",'T. TEC. GRAL'!D6) | E16: =IF('T. TEC. GRAL'!E6=0," ",'T. TEC. GRAL'!E6) | F16: =IF('T. TEC. GRAL'!F6=0," ",'T. TEC. GRAL'!F6) -> 22
A17: VIDA TIERRA Y TERRITORIO | B17: BIOL. -GEOGRAFÍA | C17: =IF('BIO-GEO'!C6=0," ",'BIO-GEO'!C6) -> 77 | D17: =IF('BIO-GEO'!D6=0," ",'BIO-GEO'!D6) | E17: =IF('BIO-GEO'!E6=0," ",'BIO-GEO'!E6) | F17: =IF('BIO-GEO'!F6=0," ",'BIO-GEO'!F6) -> 26
A18: COSMOS Y PENSAMIENTO | B18: PSICOLOGÍA | C18: =IF(PSI!C6=0," ",PSI!C6) -> 74 | D18: =IF(PSI!D6=0," ",PSI!D6) | E18: =IF(PSI!E6=0," ",PSI!E6) | F18: =IF(PSI!F6=0," ",PSI!F6) -> 25
B19: RELIGIONES | C19: =IF('REL.'!C6=0," ",'REL.'!C6) -> 64.666667 | D19: =IF('REL.'!D6=0," ",'REL.'!D6) | E19: =IF('REL.'!E6=0," ",'REL.'!E6) | F19: =IF('REL.'!F6=0," ",'REL.'!F6) -> 22
C23: BOLETIN DE NOTAS
A24: =$A$3 -> U. E. ABAROA B | F24: =NOMINA!$D$2 -> GESTION: 2026
A25: =NOMINA!$B$2 -> CURSO 2A | C25: =NOMINA!B7 -> ALIAGA SAAVEDRA MARCU MAURICIO
A26: =NOMINA!A7 -> 2 | C26: GENERO | D26: FECHA DE NACIMIENTO | F26: C. I.
C27: =NOMINA!C7 -> 0 | D27: =NOMINA!D7 -> 0 | F27: =NOMINA!F7 -> 0
A28: Campos de saberes | B28: Areas curriculares | C28: 1er.TRIM | D28: 2do. TRIM. | E28: 3er. TRIM. | F28: PROM. ANUAL
C29: CUANT. | D29: CUANT. | E29: CUANT. | F29: CUANT.
A30: COMUNIDAD Y SOCIEDAD | B30: LENGUAJE | C30: =IF(LEN!C7=0," ",LEN!C7) -> 53 | D30: =IF(LEN!D7=0," ",LEN!D7) | E30: =IF(LEN!E7=0," ",LEN!E7) | F30: =IF(LEN!F7=0," ",LEN!F7) -> 18
B31: INGLES | C31: =IF(ING!C7=0," ",ING!C7) -> 66 | D31: =IF(ING!D7=0," ",ING!D7) | E31: =IF(ING!E7=0," ",ING!E7) | F31: =IF(ING!F7=0," ",ING!F7) -> 22
B32: C SOCIALES | C32: =IF('C.SOC'!C7=0," ",'C.SOC'!C7) -> 58 | D32: =IF('C.SOC'!D7=0," ",'C.SOC'!D7) | E32: =IF('C.SOC'!E7=0," ",'C.SOC'!E7) | F32: =IF('C.SOC'!F7=0," ",'C.SOC'!F7) -> 19
B33: ED. FÍSICA | C33: =IF('E. FIS.'!C7=0," ",'E. FIS.'!C7) -> 54 | D33: =IF('E. FIS.'!D7=0," ",'E. FIS.'!D7) | E33: =IF('E. FIS.'!E7=0," ",'E. FIS.'!E7) | F33: =IF('E. FIS.'!F7=0," ",'E. FIS.'!F7) -> 18
B34: MÚSICA | C34: =IF(MUS.!C7=0," ",MUS.!C7) -> 87 | D34: =IF(MUS.!D7=0," ",MUS.!D7) | E34: =IF(MUS.!E7=0," ",MUS.!E7) | F34: =IF(MUS.!F7=0," ",MUS.!F7) -> 29
B35: ARTES PLASTICAS | C35: =IF('A.PL. '!C7=0," ",'A.PL. '!C7) -> 55 | D35: =IF('A.PL. '!D7=0," ",'A.PL. '!D7) | E35: =IF('A.PL. '!E7=0," ",'A.PL. '!E7) | F35: =IF('A.PL. '!F7=0," ",'A.PL. '!F7) -> 18
A36: CIENCIA TEC Y PRODUCCIÓN | B36: MATEMÁTICAS | C36: =IF(MAT!C7=0," ",MAT!C7) -> 59 | D36: =IF(MAT!D7=0," ",MAT!D7) | E36: =IF(MAT!E7=0," ",MAT!E7) | F36: =IF(MAT!F7=0," ",MAT!F7) -> 20
B37: T. TEC. GENERAL | C37: =IF('T. TEC. GRAL'!C7=0," ",'T. TEC. GRAL'!C7) -> 63 | D37: =IF('T. TEC. GRAL'!D7=0," ",'T. TEC. GRAL'!D7) | E37: =IF('T. TEC. GRAL'!E7=0," ",'T. TEC. GRAL'!E7) | F37: =IF('T. TEC. GRAL'!F7=0," ",'T. TEC. GRAL'!F7) -> 21
A38: VIDA TIERRA Y TERRITORIO | B38: BIOL. -GEOGRAFÍA | C38: =IF('BIO-GEO'!C7=0," ",'BIO-GEO'!C7) -> 74 | D38: =IF('BIO-GEO'!D7=0," ",'BIO-GEO'!D7) | E38: =IF('BIO-GEO'!E7=0," ",'BIO-GEO'!E7) | F38: =IF('BIO-GEO'!F7=0," ",'BIO-GEO'!F7) -> 25
A39: COSMOS Y PENSAMIENTO | B39: PSICOLOGÍA | C39: =IF(PSI!C7=0," ",PSI!C7) -> 80 | D39: =IF(PSI!D7=0," ",PSI!D7) | E39: =IF(PSI!E7=0," ",PSI!E7) | F39: =IF(PSI!F7=0," ",PSI!F7) -> 27
B40: RELIGIONES | C40: =IF('REL.'!C7=0," ",'REL.'!C7) -> 62.416667 | D40: =IF('REL.'!D7=0," ",'REL.'!D7) | E40: =IF('REL.'!E7=0," ",'REL.'!E7) | F40: =IF('REL.'!F7=0," ",'REL.'!F7) -> 21
C42: BOLETIN DE NOTAS
A43: =$A$3 -> U. E. ABAROA B | F43: =NOMINA!$D$2 -> GESTION: 2026
A44: =NOMINA!$B$2 -> CURSO 2A | C44: =NOMINA!B8 -> ANTEZANA CACHI JOSE MAXWEL
A45: =NOMINA!A8 -> 3 | C45: GENERO | D45: FECHA DE NACIMIENTO | F45: C. I.
...

Sheet PROM.
C1: =NOMINA!B2 -> CURSO 2A | D1: =NOMINA!D2 -> GESTION: 2026
E2: =NOMINA!D3 -> ,
B3: =NOMINA!A4 -> Nº | C3: =NOMINA!B4 -> APELLIDOS Y NOMBRES | D3: PROMEDIO | I3: PROM 1° Y 2° trim.
D4: 1erTrim. | E4: 2doTrim. | F4: 3er Trim. | G4: P.ANUAL
B5: =NOMINA!A6 -> 1 | C5: =NOMINA!B6 -> ABREU MARRERO LIZ DANIELA | D5: =GRAL.!AL5 -> 69.787879 | E5: =GRAL.!AM5 -> 0 | F5: =GRAL.!AN5 -> 0 | G5: =AVERAGE(D5:F5) -> 23.262626 | I5: =AVERAGE(D5:E5) -> 34.893939
B6: =NOMINA!A7 -> 2 | C6: =NOMINA!B7 -> ALIAGA SAAVEDRA MARCU MAURICIO | D6: =GRAL.!AL6 -> 64.674242 | E6: =GRAL.!AM6 -> 0 | F6: =GRAL.!AN6 -> 0 | G6: =AVERAGE(D6:F6) -> 21.558081 | I6: =AVERAGE(D6:E6) -> 32.337121
B7: =NOMINA!A8 -> 3 | C7: =NOMINA!B8 -> ANTEZANA CACHI JOSE MAXWEL | D7: =GRAL.!AL7 -> 74.939394 | E7: =GRAL.!AM7 -> 0 | F7: =GRAL.!AN7 -> 0 | G7: =AVERAGE(D7:F7) -> 24.979798 | I7: =AVERAGE(D7:E7) -> 37.469697
B8: =NOMINA!A9 -> 4 | C8: =NOMINA!B9 -> ARIZACA SALGUERO SANTIAGO | D8: =GRAL.!AL8 -> 61.340909 | E8: =GRAL.!AM8 -> 0 | F8: =GRAL.!AN8 -> 0 | G8: =AVERAGE(D8:F8) -> 20.44697 | I8: =AVERAGE(D8:E8) -> 30.670455
B9: =NOMINA!A10 -> 5 | C9: =NOMINA!B10 -> BAUTISTA GARCIA ALISON LUCIANA | D9: =GRAL.!AL9 -> 65.257576 | E9: =GRAL.!AM9 -> 0 | F9: =GRAL.!AN9 -> 0 | G9: =AVERAGE(D9:F9) -> 21.752525 | I9: =AVERAGE(D9:E9) -> 32.628788
B10: =NOMINA!A11 -> 6 | C10: =NOMINA!B11 -> BOLIVAR REVOLLO NIVARDO ADOLFO | D10: =GRAL.!AL10 -> 59.560606 | E10: =GRAL.!AM10 -> 0 | F10: =GRAL.!AN10 -> 0 | G10: =AVERAGE(D10:F10) -> 19.853535 | I10: =AVERAGE(D10:E10) -> 29.780303
B11: =NOMINA!A12 -> 7 | C11: =NOMINA!B12 -> CADIMA SOLIZ NICOLAS | D11: =GRAL.!AL11 -> 57.287879 | E11: =GRAL.!AM11 -> 0 | F11: =GRAL.!AN11 -> 0 | G11: =AVERAGE(D11:F11) -> 19.09596 | I11: =AVERAGE(D11:E11) -> 28.643939
B12: =NOMINA!A13 -> 8 | C12: =NOMINA!B13 -> CALLE PEREZ ANDREA BELEN | D12: =GRAL.!AL12 -> 79.787879 | E12: =GRAL.!AM12 -> 0 | F12: =GRAL.!AN12 -> 0 | G12: =AVERAGE(D12:F12) -> 26.59596 | I12: =AVERAGE(D12:E12) -> 39.893939
B13: =NOMINA!A14 -> 9 | C13: =NOMINA!B14 -> CHAVEZ AMURRIO SEBASTIAN FABIAN | D13: =GRAL.!AL13 -> 48.75 | E13: =GRAL.!AM13 -> 0 | F13: =GRAL.!AN13 -> 0 | G13: =AVERAGE(D13:F13) -> 16.25 | I13: =AVERAGE(D13:E13) -> 24.375
B14: =NOMINA!A15 -> 10 | C14: =NOMINA!B15 -> CHOQUE ARISPE YURIANA LUCIA | D14: =GRAL.!AL14 -> 58.977273 | E14: =GRAL.!AM14 -> 0 | F14: =GRAL.!AN14 -> 0 | G14: =AVERAGE(D14:F14) -> 19.659091 | I14: =AVERAGE(D14:E14) -> 29.488636
B15: =NOMINA!A16 -> 11 | C15: =NOMINA!B16 -> CHOQUE PERALTA JHOEL ELIAZAR | D15: =GRAL.!AL15 -> 79.984848 | E15: =GRAL.!AM15 -> 0 | F15: =GRAL.!AN15 -> 0 | G15: =AVERAGE(D15:F15) -> 26.661616 | I15: =AVERAGE(D15:E15) -> 39.992424
B16: =NOMINA!A17 -> 12 | C16: =NOMINA!B17 -> COPA RIVERO MARCIA MARCELA | D16: =GRAL.!AL16 -> 60.060606 | E16: =GRAL.!AM16 -> 0 | F16: =GRAL.!AN16 -> 0 | G16: =AVERAGE(D16:F16) -> 20.020202 | I16: =AVERAGE(D16:E16) -> 30.030303
... B49: =NOMINA!A50 -> 45 | C49: =NOMINA!B50 -> 0 | D49: =GRAL.!AL49 -> 0 | E49: =GRAL.!AM49 -> 0 | F49: =GRAL.!AN49 -> 0 | G49: =AVERAGE(D49:F49) -> 0 | I49: =AVERAGE(D49:E49) -> 0

Sheet GRAL.
F1: CENTRALIZADOR TRIMESTRAL
B2: =NOMINA!$B$2 -> CURSO 2A | C2: LEN | F2: ING | I2: C. SOC. | L2: E. FIS. | O2: MUS | R2: A. PL. | U2: MAT | X2: T.TEC.GRAL. | AA2: BIO -GEO | AD2: PSI | AG2: REL | AL2: Promedio
C3: 1er Trim. | D3: 2do Trim. | E3: 3er Trim. | F3: 1er Trim. | G3: 2do Trim. | H3: 3er Trim. | I3: 1er Trim. | J3: 2do Trim. | K3: 3er Trim. | L3: 1er Trim. | M3: 2do Trim. | N3: 3er Trim. | O3: 1er Trim. | P3: 2do Trim. | Q3: 3er Trim. | R3: 1er Trim. | S3: 2do Trim. | T3: 3er Trim. | U3: 1er Trim. | V3: 2do Trim. | W3: 3er Trim. | X3: 1er Trim. | Y3: 2do Trim. | Z3: 3er Trim. | AA3: 1er Trim. | AB3: 2do Trim. | AC3: 3er Trim. | AD3: 1er Trim. | AE3: 2do Trim. | AF3: 3er Trim. | AG3: 1er Trim. | AH3: 2do Trim. | AI3: 3er Trim. | AL3: 1er Trim. | AM3: 2do Trim. | AN3: 3er Trim.
B4: NOMINA
A5: =NOMINA!A6 -> 1 | B5: =NOMINA!B6 -> ABREU MARRERO LIZ DANIELA | C5: =IF(LEN!C6=0," ",LEN!C6) -> 54 | D5: =IF(LEN!D6=0," ",LEN!D6) | E5: =IF(LEN!E6=0," ",LEN!E6) | F5: =IF(ING!C6=0," ",ING!C6) -> 60 | G5: =IF(ING!D6=0," ",ING!D6) | H5: =IF(ING!E6=0," ",ING!E6) | I5: =IF('C.SOC'!C6=0," ",'C.SOC'!C6) -> 73 | J5: =IF('C.SOC'!D6=0," ",'C.SOC'!D6) | K5: =IF('C.SOC'!E6=0," ",'C.SOC'!E6) | L5: =IF('E. FIS.'!C6=0," ",'E. FIS.'!C6) -> 70 | M5: =IF('E. FIS.'!D6=0," ",'E. FIS.'!D6) | N5: =IF('E. FIS.'!E6=0," ",'E. FIS.'!E6) | O5: =IF(MUS.!C6=0," ",MUS.!C6) -> 94 | P5: =IF(MUS.!D6=0," ",MUS.!D6) | Q5: =IF(MUS.!E6=0," ",MUS.!E6) | R5: =IF('A.PL. '!C6=0," ",'A.PL. '!C6) -> 71 | S5: =IF('A.PL. '!D6=0," ",'A.PL. '!D6) | T5: =IF('A.PL. '!E6=0," ",'A.PL. '!E6) | U5: =IF(MAT!C6=0," ",MAT!C6) -> 64 | V5: =IF(MAT!D6=0," ",MAT!D6) | W5: =IF(MAT!E6=0," ",MAT!E6) | X5: =IF('T. TEC. GRAL'!C6=0," ",'T. TEC. GRAL'!C6) -> 66 | Y5: =IF('T. TEC. GRAL'!D6=0," ",'T. TEC. GRAL'!D6) | Z5: =IF('T. TEC. GRAL'!E6=0," ",'T. TEC. GRAL'!E6) | AA5: =IF('BIO-GEO'!C6=0," ",'BIO-GEO'!C6) -> 77 | AB5: =IF('BIO-GEO'!D6=0," ",'BIO-GEO'!D6) | AC5: =IF('BIO-GEO'!E6=0," ",'BIO-GEO'!E6) | AD5: =IF(PSI!C6=0," ",PSI!C6) -> 74 | AE5: =IF(PSI!D6=0," ",PSI!D6) | AF5: =IF(PSI!E6=0," ",PSI!E6) | AG5: =IF('REL.'!C6=0," ",'REL.'!C6) -> 64.666667 | AH5: =IF('REL.'!D6=0," ",'REL.'!D6) | AI5: =IF('REL.'!E6=0," ",'REL.'!E6) | AL5: =IFERROR(AVERAGE(C5,F5,I5,L5,O5,R5,U5,X5,AA5,AD5,AG5),0) -> 69.787879 | AM5: =IFERROR(AVERAGE(D5,G5,J5,M5,P5,S5,V5,Y5,AB5,AE5,AH5),0) -> 0 | AN5: =IFERROR(AVERAGE(E5,H5,K5,N5,Q5,T5,W5,Z5,AC5,AF5,AI5),0) -> 0
A6: =NOMINA!A7 -> 2 | B6: =NOMINA!B7 -> ALIAGA SAAVEDRA MARCU MAURICIO | C6: =IF(LEN!C7=0," ",LEN!C7) -> 53 | D6: =IF(LEN!D7=0," ",LEN!D7) | E6: =IF(LEN!E7=0," ",LEN!E7) | F6: =IF(ING!C7=0," ",ING!C7) -> 66 | G6: =IF(ING!D7=0," ",ING!D7) | H6: =IF(ING!E7=0," ",ING!E7) | I6: =IF('C.SOC'!C7=0," ",'C.SOC'!C7) -> 58 | J6: =IF('C.SOC'!D7=0," ",'C.SOC'!D7) | K6: =IF('C.SOC'!E7=0," ",'C.SOC'!E7) | L6: =IF('E. FIS.'!C7=0," ",'E. FIS.'!C7) -> 54 | M6: =IF('E. FIS.'!D7=0," ",'E. FIS.'!D7) | N6: =IF('E. FIS.'!E7=0," ",'E. FIS.'!E7) | O6: =IF(MUS.!C7=0," ",MUS.!C7) -> 87 | P6: =IF(MUS.!D7=0," ",MUS.!D7) | Q6: =IF(MUS.!E7=0," ",MUS.!E7) | R6: =IF('A.PL. '!C7=0," ",'A.PL. '!C7) -> 55 | S6: =IF('A.PL. '!D7=0," ",'A.PL. '!D7) | T6: =IF('A.PL. '!E7=0," ",'A.PL. '!E7) | U6: =IF(MAT!C7=0," ",MAT!C7) -> 59 | V6: =IF(MAT!D7=0," ",MAT!D7) | W6: =IF(MAT!E7=0," ",MAT!E7) | X6: =IF('T. TEC. GRAL'!C7=0," ",'T. TEC. GRAL'!C7) -> 63 | Y6: =IF('T. TEC. GRAL'!D7=0," ",'T. TEC. GRAL'!D7) | Z6: =IF('T. TEC. GRAL'!E7=0," ",'T. TEC. GRAL'!E7) | AA6: =IF('BIO-GEO'!C7=0," ",'BIO-GEO'!C7) -> 74 | AB6: =IF('BIO-GEO'!D7=0," ",'BIO-GEO'!D7) | AC6: =IF('BIO-GEO'!E7=0," ",'BIO-GEO'!E7) | AD6: =IF(PSI!C7=0," ",PSI!C7) -> 80 | AE6: =IF(PSI!D7=0," ",PSI!D7) | AF6: =IF(PSI!E7=0," ",PSI!E7) | AG6: =IF('REL.'!C7=0," ",'REL.'!C7) -> 62.416667 | AH6: =IF('REL.'!D7=0," ",'REL.'!D7) | AI6: =IF('REL.'!E7=0," ",'REL.'!E7) | AL6: =IFERROR(AVERAGE(C6,F6,I6,L6,O6,R6,U6,X6,AA6,AD6,AG6),0) -> 64.674242 | AM6: =IFERROR(AVERAGE(D6,G6,J6,M6,P6,S6,V6,Y6,AB6,AE6,AH6),0) -> 0 | AN6: =IFERROR(AVERAGE(E6,H6,K6,N6,Q6,T6,W6,Z6,AC6,AF6,AI6),0) -> 0
A7: =NOMINA!A8 -> 3 | B7: =NOMINA!B8 -> ANTEZANA CACHI JOSE MAXWEL | C7: =IF(LEN!C8=0," ",LEN!C8) -> 65 | D7: =IF(LEN!D8=0," ",LEN!D8) | E7: =IF(LEN!E8=0," ",LEN!E8) | F7: =IF(ING!C8=0," ",ING!C8) -> 81 | G7: =IF(ING!D8=0," ",ING!D8) | H7: =IF(ING!E8=0," ",ING!E8) | I7: =IF('C.SOC'!C8=0," ",'C.SOC'!C8) -> 74 | J7: =IF('C.SOC'!D8=0," ",'C.SOC'!D8) | K7: =IF('C.SOC'!E8=0," ",'C.SOC'!E8) | L7: =IF('E. FIS.'!C8=0," ",'E. FIS.'!C8) -> 63 | M7: =IF('E. FIS.'!D8=0," ",'E. FIS.'!D8) | N7: =IF('E. FIS.'!E8=0," ",'E. FIS.'!E8) | O7: =IF(MUS.!C8=0," ",MUS.!C8) -> 96 | P7: =IF(MUS.!D8=0," ",MUS.!D8) | Q7: =IF(MUS.!E8=0," ",MUS.!E8) | R7: =IF('A.PL. '!C8=0," ",'A.PL. '!C8) -> 59 | S7: =IF('A.PL. '!D8=0," ",'A.PL. '!D8) | T7: =IF('A.PL. '!E8=0," ",'A.PL. '!E8) | U7: =IF(MAT!C8=0," ",MAT!C8) -> 91 | V7: =IF(MAT!D8=0," ",MAT!D8) | W7: =IF(MAT!E8=0," ",MAT!E8) | X7: =IF('T. TEC. GRAL'!C8=0," ",'T. TEC. GRAL'!C8) -> 65 | Y7: =IF('T. TEC. GRAL'!D8=0," ",'T. TEC. GRAL'!D8) | Z7: =IF('T. TEC. GRAL'!E8=0," ",'T. TEC. GRAL'!E8) | AA7: =IF('BIO-GEO'!C8=0," ",'BIO-GEO'!C8) -> 75 | AB7: =IF('BIO-GEO'!D8=0," ",'BIO-GEO'!D8) | AC7: =IF('BIO-GEO'!E8=0," ",'BIO-GEO'!E8) | AD7: =IF(PSI!C8=0," ",PSI!C8) -> 85 | AE7: =IF(PSI!D8=0," ",PSI!D8) | AF7: =IF(PSI!E8=0," ",PSI!E8) | AG7: =IF('REL.'!C8=0," ",'REL.'!C8) -> 70.333333 | AH7: =IF('REL.'!D8=0," ",'REL.'!D8) | AI7: =IF('REL.'!E8=0," ",'REL.'!E8) | AL7: =IFERROR(AVERAGE(C7,F7,I7,L7,O7,R7,U7,X7,AA7,AD7,AG7),0) -> 74.939394 | AM7: =IFERROR(AVERAGE(D7,G7,J7,M7,P7,S7,V7,Y7,AB7,AE7,AH7),0) -> 0 | AN7: =IFERROR(AVERAGE(E7,H7,K7,N7,Q7,T7,W7,Z7,AC7,AF7,AI7),0) -> 0
A8: =NOMINA!A9 -> 4 | B8: =NOMINA!B9 -> ARIZACA SALGUERO SANTIAGO | C8: =IF(LEN!C9=0," ",LEN!C9) -> 46 | D8: =IF(LEN!D9=0," ",LEN!D9) | E8: =IF(LEN!E9=0," ",LEN!E9) | F8: =IF(ING!C9=0," ",ING!C9) -> 48 | G8: =IF(ING!D9=0," ",ING!D9) | H8: =IF(ING!E9=0," ",ING!E9) | I8: =IF('C.SOC'!C9=0," ",'C.SOC'!C9) -> 63 | J8: =IF('C.SOC'!D9=0," ",'C.SOC'!D9) | K8: =IF('C.SOC'!E9=0," ",'C.SOC'!E9) | L8: =IF('E. FIS.'!C9=0," ",'E. FIS.'!C9) -> 76 | M8: =IF('E. FIS.'!D9=0," ",'E. FIS.'!D9) | N8: =IF('E. FIS.'!E9=0," ",'E. FIS.'!E9) | O8: =IF(MUS.!C9=0," ",MUS.!C9) -> 70 | P8: =IF(MUS.!D9=0," ",MUS.!D9) | Q8: =IF(MUS.!E9=0," ",MUS.!E9) | R8: =IF('A.PL. '!C9=0," ",'A.PL. '!C9) -> 63 | S8: =IF('A.PL. '!D9=0," ",'A.PL. '!D9) | T8: =IF('A.PL. '!E9=0," ",'A.PL. '!E9) | U8: =IF(MAT!C9=0," ",MAT!C9) -> 61 | V8: =IF(MAT!D9=0," ",MAT!D9) | W8: =IF(MAT!E9=0," ",MAT!E9) | X8: =IF('T. TEC. GRAL'!C9=0," ",'T. TEC. GRAL'!C9) -> 68 | Y8: =IF('T. TEC. GRAL'!D9=0," ",'T. TEC. GRAL'!D9) | Z8: =IF('T. TEC. GRAL'!E9=0," ",'T. TEC. GRAL'!E9) | AA8: =IF('BIO-GEO'!C9=0," ",'BIO-GEO'!C9) -> 77 | AB8: =IF('BIO-GEO'!D9=0," ",'BIO-GEO'!D9) | AC8: =IF('BIO-GEO'!E9=0," ",'BIO-GEO'!E9) | AD8: =IF(PSI!C9=0," ",PSI!C9) -> 51 | AE8: =IF(PSI!D9=0," ",PSI!D9) | AF8: =IF(PSI!E9=0," ",PSI!E9) | AG8: =IF('REL.'!C9=0," ",'REL.'!C9) -> 51.75 | AH8: =IF('REL.'!D9=0," ",'REL.'!D9) | AI8: =IF('REL.'!E9=0," ",'REL.'!E9) | AL8: =IFERROR(AVERAGE(C8,F8,I8,L8,O8,R8,U8,X8,AA8,AD8,AG8),0) -> 61.340909 | AM8: =IFERROR(AVERAGE(D8,G8,J8,M8,P8,S8,V8,Y8,AB8,AE8,AH8),0) -> 0 | AN8: =IFERROR(AVERAGE(E8,H8,K8,N8,Q8,T8,W8,Z8,AC8,AF8,AI8),0) -> 0
A9: =NOMINA!A10 -> 5 | B9: =NOMINA!B10 -> BAUTISTA GARCIA ALISON LUCIANA | C9: =IF(LEN!C10=0," ",LEN!C10) -> 52 | D9: =IF(LEN!D10=0," ",LEN!D10) | E9: =IF(LEN!E10=0," ",LEN!E10) | F9: =IF(ING!C10=0," ",ING!C10) -> 57 | G9: =IF(ING!D10=0," ",ING!D10) | H9: =IF(ING!E10=0," ",ING!E10) | I9: =IF('C.SOC'!C10=0," ",'C.SOC'!C10) -> 51 | J9: =IF('C.SOC'!D10=0," ",'C.SOC'!D10) | K9: =IF('C.SOC'!E10=0," ",'C.SOC'!E10) | L9: =IF('E. FIS.'!C10=0," ",'E. FIS.'!C10) -> 67 | M9: =IF('E. FIS.'!D10=0," ",'E. FIS.'!D10) | N9: =IF('E. FIS.'!E10=0," ",'E. FIS.'!E10) | O9: =IF(MUS.!C10=0," ",MUS.!C10) -> 76 | P9: =IF(MUS.!D10=0," ",MUS.!D10) | Q9: =IF(MUS.!E10=0," ",MUS.!E10) | R9: =IF('A.PL. '!C10=0," ",'A.PL. '!C10) -> 71 | S9: =IF('A.PL. '!D10=0," ",'A.PL. '!D10) | T9: =IF('A.PL. '!E10=0," ",'A.PL. '!E10) | U9: =IF(MAT!C10=0," ",MAT!C10) -> 58 | V9: =IF(MAT!D10=0," ",MAT!D10) | W9: =IF(MAT!E10=0," ",MAT!E10) | X9: =IF('T. TEC. GRAL'!C10=0," ",'T. TEC. GRAL'!C10) -> 71 | Y9: =IF('T. TEC. GRAL'!D10=0," ",'T. TEC. GRAL'!D10) | Z9: =IF('T. TEC. GRAL'!E10=0," ",'T. TEC. GRAL'!E10) | AA9: =IF('BIO-GEO'!C10=0," ",'BIO-GEO'!C10) -> 70 | AB9: =IF('BIO-GEO'!D10=0," ",'BIO-GEO'!D10) | AC9: =IF('BIO-GEO'!E10=0," ",'BIO-GEO'!E10) | AD9: =IF(PSI!C10=0," ",PSI!C10) -> 66 | AE9: =IF(PSI!D10=0," ",PSI!D10) | AF9: =IF(PSI!E10=0," ",PSI!E10) | AG9: =IF('REL.'!C10=0," ",'REL.'!C10) -> 78.833333 | AH9: =IF('REL.'!D10=0," ",'REL.'!D10) | AI9: =IF('REL.'!E10=0," ",'REL.'!E10) | AL9: =IFERROR(AVERAGE(C9,F9,I9,L9,O9,R9,U9,X9,AA9,AD9,AG9),0) -> 65.257576 | AM9: =IFERROR(AVERAGE(D9,G9,J9,M9,P9,S9,V9,Y9,AB9,AE9,AH9),0) -> 0 | AN9: =IFERROR(AVERAGE(E9,H9,K9,N9,Q9,T9,W9,Z9,AC9,AF9,AI9),0) -> 0
A10: =NOMINA!A11 -> 6 | B10: =NOMINA!B11 -> BOLIVAR REVOLLO NIVARDO ADOLFO | C10: =IF(LEN!C11=0," ",LEN!C11) -> 51 | D10: =IF(LEN!D11=0," ",LEN!D11) | E10: =IF(LEN!E11=0," ",LEN!E11) | F10: =IF(ING!C11=0," ",ING!C11) -> 63 | G10: =IF(ING!D11=0," ",ING!D11) | H10: =IF(ING!E11=0," ",ING!E11) | I10: =IF('C.SOC'!C11=0," ",'C.SOC'!C11) -> 43 | J10: =IF('C.SOC'!D11=0," ",'C.SOC'!D11) | K10: =IF('C.SOC'!E11=0," ",'C.SOC'!E11) | L10: =IF('E. FIS.'!C11=0," ",'E. FIS.'!C11) -> 59 | M10: =IF('E. FIS.'!D11=0," ",'E. FIS.'!D11) | N10: =IF('E. FIS.'!E11=0," ",'E. FIS.'!E11) | O10: =IF(MUS.!C11=0," ",MUS.!C11) -> 72 | P10: =IF(MUS.!D11=0," ",MUS.!D11) | Q10: =IF(MUS.!E11=0," ",MUS.!E11) | R10: =IF('A.PL. '!C11=0," ",'A.PL. '!C11) -> 53 | S10: =IF('A.PL. '!D11=0," ",'A.PL. '!D11) | T10: =IF('A.PL. '!E11=0," ",'A.PL. '!E11) | U10: =IF(MAT!C11=0," ",MAT!C11) -> 46 | V10: =IF(MAT!D11=0," ",MAT!D11) | W10: =IF(MAT!E11=0," ",MAT!E11) | X10: =IF('T. TEC. GRAL'!C11=0," ",'T. TEC. GRAL'!C11) -> 66 | Y10: =IF('T. TEC. GRAL'!D11=0," ",'T. TEC. GRAL'!D11) | Z10: =IF('T. TEC. GRAL'!E11=0," ",'T. TEC. GRAL'!E11) | AA10: =IF('BIO-GEO'!C11=0," ",'BIO-GEO'!C11) -> 61 | AB10: =IF('BIO-GEO'!D11=0," ",'BIO-GEO'!D11) | AC10: =IF('BIO-GEO'!E11=0," ",'BIO-GEO'!E11) | AD10: =IF(PSI!C11=0," ",PSI!C11) -> 64 | AE10: =IF(PSI!D11=0," ",PSI!D11) | AF10: =IF(PSI!E11=0," ",PSI!E11) | AG10: =IF('REL.'!C11=0," ",'REL.'!C11) -> 77.166667 | AH10: =IF('REL.'!D11=0," ",'REL.'!D11) | AI10: =IF('REL.'!E11=0," ",'REL.'!E11) | AL10: =IFERROR(AVERAGE(C10,F10,I10,L10,O10,R10,U10,X10,AA10,AD10,AG10),0) -> 59.560606 | AM10: =IFERROR(AVERAGE(D10,G10,J10,M10,P10,S10,V10,Y10,AB10,AE10,AH10),0) -> 0 | AN10: =IFERROR(AVERAGE(E10,H10,K10,N10,Q10,T10,W10,Z10,AC10,AF10,AI10),0) -> 0
A11: =NOMINA!A12 -> 7 | B11: =NOMINA!B12 -> CADIMA SOLIZ NICOLAS | C11: =IF(LEN!C12=0," ",LEN!C12) -> 46 | D11: =IF(LEN!D12=0," ",LEN!D12) | E11: =IF(LEN!E12=0," ",LEN!E12) | F11: =IF(ING!C12=0," ",ING!C12) -> 47 | G11: =IF(ING!D12=0," ",ING!D12) | H11: =IF(ING!E12=0," ",ING!E12) | I11: =IF('C.SOC'!C12=0," ",'C.SOC'!C12) -> 40 | J11: =IF('C.SOC'!D12=0," ",'C.SOC'!D12) | K11: =IF('C.SOC'!E12=0," ",'C.SOC'!E12) | L11: =IF('E. FIS.'!C12=0," ",'E. FIS.'!C12) -> 69 | M11: =IF('E. FIS.'!D12=0," ",'E. FIS.'!D12) | N11: =IF('E. FIS.'!E12=0," ",'E. FIS.'!E12) | O11: =IF(MUS.!C12=0," ",MUS.!C12) -> 66 | P11: =IF(MUS.!D12=0," ",MUS.!D12) | Q11: =IF(MUS.!E12=0," ",MUS.!E12) | R11: =IF('A.PL. '!C12=0," ",'A.PL. '!C12) -> 59 | S11: =IF('A.PL. '!D12=0," ",'A.PL. '!D12) | T11: =IF('A.PL. '!E12=0," ",'A.PL. '!E12) | U11: =IF(MAT!C12=0," ",MAT!C12) -> 46 | V11: =IF(MAT!D12=0," ",MAT!D12) | W11: =IF(MAT!E12=0," ",MAT!E12) | X11: =IF('T. TEC. GRAL'!C12=0," ",'T. TEC. GRAL'!C12) -> 57 | Y11: =IF('T. TEC. GRAL'!D12=0," ",'T. TEC. GRAL'!D12) | Z11: =IF('T. TEC. GRAL'!E12=0," ",'T. TEC. GRAL'!E12) | AA11: =IF('BIO-GEO'!C12=0," ",'BIO-GEO'!C12) -> 67 | AB11: =IF('BIO-GEO'!D12=0," ",'BIO-GEO'!D12) | AC11: =IF('BIO-GEO'!E12=0," ",'BIO-GEO'!E12) | AD11: =IF(PSI!C12=0," ",PSI!C12) -> 67 | AE11: =IF(PSI!D12=0," ",PSI!D12) | AF11: =IF(PSI!E12=0," ",PSI!E12) | AG11: =IF('REL.'!C12=0," ",'REL.'!C12) -> 66.166667 | AH11: =IF('REL.'!D12=0," ",'REL.'!D12) | AI11: =IF('REL.'!E12=0," ",'REL.'!E12) | AL11: =IFERROR(AVERAGE(C11,F11,I11,L11,O11,R11,U11,X11,AA11,AD11,AG11),0) -> 57.287879 | AM11: =IFERROR(AVERAGE(D11,G11,J11,M11,P11,S11,V11,Y11,AB11,AE11,AH11),0) -> 0 | AN11: =IFERROR(AVERAGE(E11,H11,K11,N11,Q11,T11,W11,Z11,AC11,AF11,AI11),0) -> 0
