Workbook

Sheet INDICE

Sheet Carátula
W1: PASOS A SEGUIR
W2: 1. LLENE SOLO LOS DATOS DE LA CARATULA Y FILIACION
W3: 2. ESTOS DATOS SALTARAN DE FORMA AUTOMATICA EN TODAS LAS HOJAS
W4: 3. ESTE REGISTRO NO ESTA BLOQUEADO PUEDE MODIFICARLO A SUS NECESIDADES
D7: CUADERNO PEDAGÓGICO
F8: 2026
D10: DISTRITO:
D11: COCHABAMBA 2
D13: UNIDAD EDUCATIVA
D14: SIMON BOLIVAR
F16: LOGO U.E. | M16: CODIGO SIE: | P16: 809811111
M18: NIVEL: | P18: SECUNDARIA
M20: CURSO: | P20: SEXTO | S20: "A"
D22: PROFESOR:
D23: JOSE CUELLAR SANCHEZ
D25: ÁREA:
D26: MATEMÁTICAS
I28: COCHABAMBA - BOLIVIA
R29: www.educa-tics.com

Sheet FIL
A1: FILIACIÓN DE ESTUDIANTES - GESTIÓN 2026 | L1: www.educatic.xyz
A2: =CONCATENATE("PROFESOR(A):"," ",Carátula!D23) -> PROFESOR(A): JOSE CUELLAR SANCHEZ | F2: =CONCATENATE("NIVEL:"," ",Carátula!P18) -> NIVEL: SECUNDARIA
A3: =CONCATENATE("CODIGO SIE:"," ",Carátula!P16) -> CODIGO SIE: 809811111 | F3: =CONCATENATE("GRADO:"," ",Carátula!P20) -> GRADO: SEXTO
A4: =CONCATENATE("UNIDAD EDUCATIVA:"," ",Carátula!D14) -> UNIDAD EDUCATIVA: SIMON BOLIVAR | F4: =CONCATENATE("PARALELO:"," ",Carátula!S20) -> PARALELO: "A" | G4: DATOS DE LA MADRE | J4: DATOS DEL PADRE
A5: N° | B5: RUDE | C5: PATERNO | D5: MATERNO | E5: NOMBRES | F5: TELEFONO/CELULAR | G5: NOMBRE | H5: OCUPACION | I5: CELULAR | J5: NOMBRE | K5: OCUPACION | L5: CELULAR
A6: 1 | C6: CUELLAR | D6: SANCHEZ | E6: JOSE
A7: 2 | C7: VALENCIA | D7: ROJAS | E7: NICOLAS
A8: 3
A9: 4
A10: 5
A11: 6
A12: 7
A13: 8
A14: 9
A15: 10
A16: 11
A17: 12
A18: 13
A19: 14
... A55: 50

Sheet REGISTRO PPFF
D1: REGISTRO DE PADRES DE FAMILIA O TUTORES
A2: UNIDAD EDUCATIVA: | C2: =Carátula!$D$14 -> SIMON BOLIVAR | E2: CODIGÓ SIE: | F2: =Carátula!$P$16 -> 809811111 | R2: =[1]CARATULA!P16 -> 80890037
A3: NIVEL : | C3: =Carátula!$P$18 -> SECUNDARIA | E3: CURSO: | F3: =Carátula!$P$20&" "&Carátula!$S$20 -> SEXTO "A" | R3: =CONCATENATE([1]CARATULA!P20," ",[1]CARATULA!S20) -> TERCERO "A"
A5: Nº | B5: APELLIDOS Y NOMBRES ESTUDIANTE | D5: DATOS DEL PADRE / O TUTOR | F5: DATOS DE LA MADRE | H5: DIRECCION
D6: NOMBRE | E6: TELEFONO | F6: NOMBRE | G6: TELEFONO
A7: 1 | B7: =IF(ISBLANK(FIL!E6),"",CONCATENATE(FIL!C6," ",FIL!D6," ",FIL!E6)) -> CUELLAR SANCHEZ JOSE | D7: =IF(ISBLANK(FIL!G6),"",(FIL!G6)) | F7: =IF(ISBLANK(FIL!J6),"",(FIL!J6))
A8: 2 | B8: =IF(ISBLANK(FIL!E7),"",CONCATENATE(FIL!C7," ",FIL!D7," ",FIL!E7)) -> VALENCIA ROJAS NICOLAS | D8: =IF(ISBLANK(FIL!G7),"",(FIL!G7)) | F8: =IF(ISBLANK(FIL!J7),"",(FIL!J7))
A9: 3 | B9: =IF(ISBLANK(FIL!E8),"",CONCATENATE(FIL!C8," ",FIL!D8," ",FIL!E8)) | D9: =IF(ISBLANK(FIL!G8),"",(FIL!G8)) | F9: =IF(ISBLANK(FIL!J8),"",(FIL!J8))
A10: 4 | B10: =IF(ISBLANK(FIL!E9),"",CONCATENATE(FIL!C9," ",FIL!D9," ",FIL!E9)) | D10: =IF(ISBLANK(FIL!G9),"",(FIL!G9)) | F10: =IF(ISBLANK(FIL!J9),"",(FIL!J9))
A11: 5 | B11: =IF(ISBLANK(FIL!E10),"",CONCATENATE(FIL!C10," ",FIL!D10," ",FIL!E10)) | D11: =IF(ISBLANK(FIL!G10),"",(FIL!G10)) | F11: =IF(ISBLANK(FIL!J10),"",(FIL!J10))
A12: 6 | B12: =IF(ISBLANK(FIL!E11),"",CONCATENATE(FIL!C11," ",FIL!D11," ",FIL!E11)) | D12: =IF(ISBLANK(FIL!G11),"",(FIL!G11)) | F12: =IF(ISBLANK(FIL!J11),"",(FIL!J11))
A13: 7 | B13: =IF(ISBLANK(FIL!E12),"",CONCATENATE(FIL!C12," ",FIL!D12," ",FIL!E12)) | D13: =IF(ISBLANK(FIL!G12),"",(FIL!G12)) | F13: =IF(ISBLANK(FIL!J12),"",(FIL!J12))
A14: 8 | B14: =IF(ISBLANK(FIL!E13),"",CONCATENATE(FIL!C13," ",FIL!D13," ",FIL!E13)) | D14: =IF(ISBLANK(FIL!G13),"",(FIL!G13)) | F14: =IF(ISBLANK(FIL!J13),"",(FIL!J13))
A15: 9 | B15: =IF(ISBLANK(FIL!E14),"",CONCATENATE(FIL!C14," ",FIL!D14," ",FIL!E14)) | D15: =IF(ISBLANK(FIL!G14),"",(FIL!G14)) | F15: =IF(ISBLANK(FIL!J14),"",(FIL!J14))
A16: 10 | B16: =IF(ISBLANK(FIL!E15),"",CONCATENATE(FIL!C15," ",FIL!D15," ",FIL!E15)) | D16: =IF(ISBLANK(FIL!G15),"",(FIL!G15)) | F16: =IF(ISBLANK(FIL!J15),"",(FIL!J15))
A17: 11 | B17: =IF(ISBLANK(FIL!E16),"",CONCATENATE(FIL!C16," ",FIL!D16," ",FIL!E16)) | D17: =IF(ISBLANK(FIL!G16),"",(FIL!G16)) | F17: =IF(ISBLANK(FIL!J16),"",(FIL!J16))
A18: 12 | B18: =IF(ISBLANK(FIL!E17),"",CONCATENATE(FIL!C17," ",FIL!D17," ",FIL!E17)) | D18: =IF(ISBLANK(FIL!G17),"",(FIL!G17)) | F18: =IF(ISBLANK(FIL!J17),"",(FIL!J17))
... A56: 50 | B56: =IF(ISBLANK(FIL!E55),"",CONCATENATE(FIL!C55," ",FIL!D55," ",FIL!E55)) | D56: =IF(ISBLANK(FIL!G55),"",(FIL!G55)) | F56: =IF(ISBLANK(FIL!J55),"",(FIL!J55))

Sheet Asist. 1 Trim. Sec.
A1: ASISTENCIA PRIMER TRIMESTRE - GESTIÓN 2026
A2: PROFESOR(A): | C2: =Carátula!$D$23 -> JOSE CUELLAR SANCHEZ | S2: NIVEL: | X2: =Carátula!$P$18 -> SECUNDARIA
A3: CODIGO SIE: | C3: =Carátula!$P$16 -> 809811111 | S3: GRADO: | X3: =Carátula!$P$20 -> SEXTO
A4: UNIDAD EDUCATIVA: | C4: =Carátula!$D$14 -> SIMON BOLIVAR | S4: PARALELO: | X4: =Carátula!$S$20 -> "A" | AB4: P=Presente | AC4: F=Faltas | AD4: A=Atrasos | AE4: L=Licencias
A5: N° | B5: APELLIDOS Y NOMBRES | C5: MESES:
A8: 1 | B8: =IF(ISBLANK(FIL!E6),"",CONCATENATE(FIL!C6," ",FIL!D6," ",FIL!E6)) -> CUELLAR SANCHEZ JOSE | AB8: =IF(COUNTIF(C8:AA8,"=P")=0,"",COUNTIF(C8:AA8,"=P")) | AC8: =IF(COUNTIF(C8:AA8,"=F")=0,"",COUNTIF(C8:AA8,"=F")) | AD8: =IF(COUNTIF(C8:AA8,"=A")=0,"",COUNTIF(C8:AA8,"=A")) | AE8: =IF(COUNTIF(C8:AA8,"=L")=0,"",COUNTIF(C8:AA8,"=L"))
A9: 2 | B9: =IF(ISBLANK(FIL!E7),"",CONCATENATE(FIL!C7," ",FIL!D7," ",FIL!E7)) -> VALENCIA ROJAS NICOLAS | AB9: =IF(COUNTIF(C9:AA9,"=P")=0,"",COUNTIF(C9:AA9,"=P")) | AC9: =IF(COUNTIF(C9:AA9,"=F")=0,"",COUNTIF(C9:AA9,"=F")) | AD9: =IF(COUNTIF(C9:AA9,"=A")=0,"",COUNTIF(C9:AA9,"=A")) | AE9: =IF(COUNTIF(C9:AA9,"=L")=0,"",COUNTIF(C9:AA9,"=L"))
A10: 3 | B10: =IF(ISBLANK(FIL!E8),"",CONCATENATE(FIL!C8," ",FIL!D8," ",FIL!E8)) | AB10: =IF(COUNTIF(C10:AA10,"=P")=0,"",COUNTIF(C10:AA10,"=P")) | AC10: =IF(COUNTIF(C10:AA10,"=F")=0,"",COUNTIF(C10:AA10,"=F")) | AD10: =IF(COUNTIF(C10:AA10,"=A")=0,"",COUNTIF(C10:AA10,"=A")) | AE10: =IF(COUNTIF(C10:AA10,"=L")=0,"",COUNTIF(C10:AA10,"=L"))
A11: 4 | B11: =IF(ISBLANK(FIL!E9),"",CONCATENATE(FIL!C9," ",FIL!D9," ",FIL!E9)) | AB11: =IF(COUNTIF(C11:AA11,"=P")=0,"",COUNTIF(C11:AA11,"=P")) | AC11: =IF(COUNTIF(C11:AA11,"=F")=0,"",COUNTIF(C11:AA11,"=F")) | AD11: =IF(COUNTIF(C11:AA11,"=A")=0,"",COUNTIF(C11:AA11,"=A")) | AE11: =IF(COUNTIF(C11:AA11,"=L")=0,"",COUNTIF(C11:AA11,"=L"))
A12: 5 | B12: =IF(ISBLANK(FIL!E10),"",CONCATENATE(FIL!C10," ",FIL!D10," ",FIL!E10)) | AB12: =IF(COUNTIF(C12:AA12,"=P")=0,"",COUNTIF(C12:AA12,"=P")) | AC12: =IF(COUNTIF(C12:AA12,"=F")=0,"",COUNTIF(C12:AA12,"=F")) | AD12: =IF(COUNTIF(C12:AA12,"=A")=0,"",COUNTIF(C12:AA12,"=A")) | AE12: =IF(COUNTIF(C12:AA12,"=L")=0,"",COUNTIF(C12:AA12,"=L"))
A13: 6 | B13: =IF(ISBLANK(FIL!E11),"",CONCATENATE(FIL!C11," ",FIL!D11," ",FIL!E11)) | AB13: =IF(COUNTIF(C13:AA13,"=P")=0,"",COUNTIF(C13:AA13,"=P")) | AC13: =IF(COUNTIF(C13:AA13,"=F")=0,"",COUNTIF(C13:AA13,"=F")) | AD13: =IF(COUNTIF(C13:AA13,"=A")=0,"",COUNTIF(C13:AA13,"=A")) | AE13: =IF(COUNTIF(C13:AA13,"=L")=0,"",COUNTIF(C13:AA13,"=L"))
A14: 7 | B14: =IF(ISBLANK(FIL!E12),"",CONCATENATE(FIL!C12," ",FIL!D12," ",FIL!E12)) | AB14: =IF(COUNTIF(C14:AA14,"=P")=0,"",COUNTIF(C14:AA14,"=P")) | AC14: =IF(COUNTIF(C14:AA14,"=F")=0,"",COUNTIF(C14:AA14,"=F")) | AD14: =IF(COUNTIF(C14:AA14,"=A")=0,"",COUNTIF(C14:AA14,"=A")) | AE14: =IF(COUNTIF(C14:AA14,"=L")=0,"",COUNTIF(C14:AA14,"=L"))
A15: 8 | B15: =IF(ISBLANK(FIL!E13),"",CONCATENATE(FIL!C13," ",FIL!D13," ",FIL!E13)) | AB15: =IF(COUNTIF(C15:AA15,"=P")=0,"",COUNTIF(C15:AA15,"=P")) | AC15: =IF(COUNTIF(C15:AA15,"=F")=0,"",COUNTIF(C15:AA15,"=F")) | AD15: =IF(COUNTIF(C15:AA15,"=A")=0,"",COUNTIF(C15:AA15,"=A")) | AE15: =IF(COUNTIF(C15:AA15,"=L")=0,"",COUNTIF(C15:AA15,"=L"))
A16: 9 | B16: =IF(ISBLANK(FIL!E14),"",CONCATENATE(FIL!C14," ",FIL!D14," ",FIL!E14)) | AB16: =IF(COUNTIF(C16:AA16,"=P")=0,"",COUNTIF(C16:AA16,"=P")) | AC16: =IF(COUNTIF(C16:AA16,"=F")=0,"",COUNTIF(C16:AA16,"=F")) | AD16: =IF(COUNTIF(C16:AA16,"=A")=0,"",COUNTIF(C16:AA16,"=A")) | AE16: =IF(COUNTIF(C16:AA16,"=L")=0,"",COUNTIF(C16:AA16,"=L"))
A17: 10 | B17: =IF(ISBLANK(FIL!E15),"",CONCATENATE(FIL!C15," ",FIL!D15," ",FIL!E15)) | AB17: =IF(COUNTIF(C17:AA17,"=P")=0,"",COUNTIF(C17:AA17,"=P")) | AC17: =IF(COUNTIF(C17:AA17,"=F")=0,"",COUNTIF(C17:AA17,"=F")) | AD17: =IF(COUNTIF(C17:AA17,"=A")=0,"",COUNTIF(C17:AA17,"=A")) | AE17: =IF(COUNTIF(C17:AA17,"=L")=0,"",COUNTIF(C17:AA17,"=L"))
A18: 11 | B18: =IF(ISBLANK(FIL!E16),"",CONCATENATE(FIL!C16," ",FIL!D16," ",FIL!E16)) | AB18: =IF(COUNTIF(C18:AA18,"=P")=0,"",COUNTIF(C18:AA18,"=P")) | AC18: =IF(COUNTIF(C18:AA18,"=F")=0,"",COUNTIF(C18:AA18,"=F")) | AD18: =IF(COUNTIF(C18:AA18,"=A")=0,"",COUNTIF(C18:AA18,"=A")) | AE18: =IF(COUNTIF(C18:AA18,"=L")=0,"",COUNTIF(C18:AA18,"=L"))
A19: 12 | B19: =IF(ISBLANK(FIL!E17),"",CONCATENATE(FIL!C17," ",FIL!D17," ",FIL!E17)) | AB19: =IF(COUNTIF(C19:AA19,"=P")=0,"",COUNTIF(C19:AA19,"=P")) | AC19: =IF(COUNTIF(C19:AA19,"=F")=0,"",COUNTIF(C19:AA19,"=F")) | AD19: =IF(COUNTIF(C19:AA19,"=A")=0,"",COUNTIF(C19:AA19,"=A")) | AE19: =IF(COUNTIF(C19:AA19,"=L")=0,"",COUNTIF(C19:AA19,"=L"))
... A57: 50 | B57: =IF(ISBLANK(FIL!E55),"",CONCATENATE(FIL!C55," ",FIL!D55," ",FIL!E55)) | AB57: =IF(COUNTIF(C57:AA57,"=P")=0,"",COUNTIF(C57:AA57,"=P")) | AC57: =IF(COUNTIF(C57:AA57,"=F")=0,"",COUNTIF(C57:AA57,"=F")) | AD57: =IF(COUNTIF(C57:AA57,"=A")=0,"",COUNTIF(C57:AA57,"=A")) | AE57: =IF(COUNTIF(C57:AA57,"=L")=0,"",COUNTIF(C57:AA57,"=L"))
B58: Total Estudiantes: | C58: =COUNTA(FIL!E6:E55) -> 2 | AB58: =IF(SUM(AB8:AB57)=0,"",SUM(AB8:AB57)) | AC58: =IF(SUM(AC8:AC57)=0,"",SUM(AC8:AC57)) | AD58: =IF(SUM(AD8:AD57)=0,"",SUM(AD8:AD57)) | AE58: =IF(SUM(AE8:AE57)=0,"",SUM(AE8:AE57))
B59: Días trabajados: | C59: =COUNTA(C7:AA7) -> 0 | AB59: =IF(ISNUMBER(AB58),AB58/SUM(AB58:AE58),"") | AC59: =IF(ISNUMBER(AC58),AC58/SUM(AB58:AE58),"") | AD59: =IF(ISNUMBER(AD58),AD58/SUM(AB58:AE58),"") | AE59: =IF(ISNUMBER(AE58),AE58/SUM(AB58:AE58),"")

Sheet Asist. Bimestral Prim.
A1: ASISTENCIA TRIMESTRAL - GESTIÓN
A2: PROFESOR(A): | C2: =Carátula!$D$23 -> JOSE CUELLAR SANCHEZ | AH2: NIVEL: | AM2: =Carátula!$P$18 -> SECUNDARIA
A3: CODIGO SIE: | C3: =Carátula!$P$16 -> 809811111 | AH3: GRADO: | AM3: =Carátula!$P$20 -> SEXTO
A4: UNIDAD EDUCATIVA: | C4: =Carátula!$D$14 -> SIMON BOLIVAR | AH4: PARALELO: | AM4: =Carátula!$S$20 -> "A" | AQ4: P=Presente | AR4: F=Faltas | AS4: A=Atrasos | AT4: L=Licencias
A5: N° | B5: APELLIDOS Y NOMBRES
A8: 1 | B8: =IF(ISBLANK(FIL!E6),"",CONCATENATE(FIL!C6," ",FIL!D6," ",FIL!E6)) -> CUELLAR SANCHEZ JOSE | AQ8: =IF(COUNTIF(C8:AP8,"=P")=0,"",COUNTIF(C8:AP8,"=P")) | AR8: =IF(COUNTIF(C8:AP8,"=F")=0,"",COUNTIF(C8:AP8,"=F")) | AS8: =IF(COUNTIF(C8:AP8,"=A")=0,"",COUNTIF(C8:AP8,"=A")) | AT8: =IF(COUNTIF(C8:AP8,"=L")=0,"",COUNTIF(C8:AP8,"=L"))
A9: 2 | B9: =IF(ISBLANK(FIL!E7),"",CONCATENATE(FIL!C7," ",FIL!D7," ",FIL!E7)) -> VALENCIA ROJAS NICOLAS | AQ9: =IF(COUNTIF(C9:AP9,"=P")=0,"",COUNTIF(C9:AP9,"=P")) | AR9: =IF(COUNTIF(C9:AP9,"=F")=0,"",COUNTIF(C9:AP9,"=F")) | AS9: =IF(COUNTIF(C9:AP9,"=A")=0,"",COUNTIF(C9:AP9,"=A")) | AT9: =IF(COUNTIF(C9:AP9,"=L")=0,"",COUNTIF(C9:AP9,"=L"))
A10: 3 | B10: =IF(ISBLANK(FIL!E8),"",CONCATENATE(FIL!C8," ",FIL!D8," ",FIL!E8)) | AQ10: =IF(COUNTIF(C10:AP10,"=P")=0,"",COUNTIF(C10:AP10,"=P")) | AR10: =IF(COUNTIF(C10:AP10,"=F")=0,"",COUNTIF(C10:AP10,"=F")) | AS10: =IF(COUNTIF(C10:AP10,"=A")=0,"",COUNTIF(C10:AP10,"=A")) | AT10: =IF(COUNTIF(C10:AP10,"=L")=0,"",COUNTIF(C10:AP10,"=L"))
A11: 4 | B11: =IF(ISBLANK(FIL!E9),"",CONCATENATE(FIL!C9," ",FIL!D9," ",FIL!E9)) | AQ11: =IF(COUNTIF(C11:AP11,"=P")=0,"",COUNTIF(C11:AP11,"=P")) | AR11: =IF(COUNTIF(C11:AP11,"=F")=0,"",COUNTIF(C11:AP11,"=F")) | AS11: =IF(COUNTIF(C11:AP11,"=A")=0,"",COUNTIF(C11:AP11,"=A")) | AT11: =IF(COUNTIF(C11:AP11,"=L")=0,"",COUNTIF(C11:AP11,"=L"))
A12: 5 | B12: =IF(ISBLANK(FIL!E10),"",CONCATENATE(FIL!C10," ",FIL!D10," ",FIL!E10)) | AQ12: =IF(COUNTIF(C12:AP12,"=P")=0,"",COUNTIF(C12:AP12,"=P")) | AR12: =IF(COUNTIF(C12:AP12,"=F")=0,"",COUNTIF(C12:AP12,"=F")) | AS12: =IF(COUNTIF(C12:AP12,"=A")=0,"",COUNTIF(C12:AP12,"=A")) | AT12: =IF(COUNTIF(C12:AP12,"=L")=0,"",COUNTIF(C12:AP12,"=L"))
A13: 6 | B13: =IF(ISBLANK(FIL!E11),"",CONCATENATE(FIL!C11," ",FIL!D11," ",FIL!E11)) | AQ13: =IF(COUNTIF(C13:AP13,"=P")=0,"",COUNTIF(C13:AP13,"=P")) | AR13: =IF(COUNTIF(C13:AP13,"=F")=0,"",COUNTIF(C13:AP13,"=F")) | AS13: =IF(COUNTIF(C13:AP13,"=A")=0,"",COUNTIF(C13:AP13,"=A")) | AT13: =IF(COUNTIF(C13:AP13,"=L")=0,"",COUNTIF(C13:AP13,"=L"))
A14: 7 | B14: =IF(ISBLANK(FIL!E12),"",CONCATENATE(FIL!C12," ",FIL!D12," ",FIL!E12)) | AQ14: =IF(COUNTIF(C14:AP14,"=P")=0,"",COUNTIF(C14:AP14,"=P")) | AR14: =IF(COUNTIF(C14:AP14,"=F")=0,"",COUNTIF(C14:AP14,"=F")) | AS14: =IF(COUNTIF(C14:AP14,"=A")=0,"",COUNTIF(C14:AP14,"=A")) | AT14: =IF(COUNTIF(C14:AP14,"=L")=0,"",COUNTIF(C14:AP14,"=L"))
A15: 8 | B15: =IF(ISBLANK(FIL!E13),"",CONCATENATE(FIL!C13," ",FIL!D13," ",FIL!E13)) | AQ15: =IF(COUNTIF(C15:AP15,"=P")=0,"",COUNTIF(C15:AP15,"=P")) | AR15: =IF(COUNTIF(C15:AP15,"=F")=0,"",COUNTIF(C15:AP15,"=F")) | AS15: =IF(COUNTIF(C15:AP15,"=A")=0,"",COUNTIF(C15:AP15,"=A")) | AT15: =IF(COUNTIF(C15:AP15,"=L")=0,"",COUNTIF(C15:AP15,"=L"))
A16: 9 | B16: =IF(ISBLANK(FIL!E14),"",CONCATENATE(FIL!C14," ",FIL!D14," ",FIL!E14)) | AQ16: =IF(COUNTIF(C16:AP16,"=P")=0,"",COUNTIF(C16:AP16,"=P")) | AR16: =IF(COUNTIF(C16:AP16,"=F")=0,"",COUNTIF(C16:AP16,"=F")) | AS16: =IF(COUNTIF(C16:AP16,"=A")=0,"",COUNTIF(C16:AP16,"=A")) | AT16: =IF(COUNTIF(C16:AP16,"=L")=0,"",COUNTIF(C16:AP16,"=L"))
A17: 10 | B17: =IF(ISBLANK(FIL!E15),"",CONCATENATE(FIL!C15," ",FIL!D15," ",FIL!E15)) | AQ17: =IF(COUNTIF(C17:AP17,"=P")=0,"",COUNTIF(C17:AP17,"=P")) | AR17: =IF(COUNTIF(C17:AP17,"=F")=0,"",COUNTIF(C17:AP17,"=F")) | AS17: =IF(COUNTIF(C17:AP17,"=A")=0,"",COUNTIF(C17:AP17,"=A")) | AT17: =IF(COUNTIF(C17:AP17,"=L")=0,"",COUNTIF(C17:AP17,"=L"))
A18: 11 | B18: =IF(ISBLANK(FIL!E16),"",CONCATENATE(FIL!C16," ",FIL!D16," ",FIL!E16)) | AQ18: =IF(COUNTIF(C18:AP18,"=P")=0,"",COUNTIF(C18:AP18,"=P")) | AR18: =IF(COUNTIF(C18:AP18,"=F")=0,"",COUNTIF(C18:AP18,"=F")) | AS18: =IF(COUNTIF(C18:AP18,"=A")=0,"",COUNTIF(C18:AP18,"=A")) | AT18: =IF(COUNTIF(C18:AP18,"=L")=0,"",COUNTIF(C18:AP18,"=L"))
A19: 12 | B19: =IF(ISBLANK(FIL!E17),"",CONCATENATE(FIL!C17," ",FIL!D17," ",FIL!E17)) | AQ19: =IF(COUNTIF(C19:AP19,"=P")=0,"",COUNTIF(C19:AP19,"=P")) | AR19: =IF(COUNTIF(C19:AP19,"=F")=0,"",COUNTIF(C19:AP19,"=F")) | AS19: =IF(COUNTIF(C19:AP19,"=A")=0,"",COUNTIF(C19:AP19,"=A")) | AT19: =IF(COUNTIF(C19:AP19,"=L")=0,"",COUNTIF(C19:AP19,"=L"))
... A57: 50 | B57: =IF(ISBLANK(FIL!E55),"",CONCATENATE(FIL!C55," ",FIL!D55," ",FIL!E55)) | AQ57: =IF(COUNTIF(C57:AP57,"=P")=0,"",COUNTIF(C57:AP57,"=P")) | AR57: =IF(COUNTIF(C57:AP57,"=F")=0,"",COUNTIF(C57:AP57,"=F")) | AS57: =IF(COUNTIF(C57:AP57,"=A")=0,"",COUNTIF(C57:AP57,"=A")) | AT57: =IF(COUNTIF(C57:AP57,"=L")=0,"",COUNTIF(C57:AP57,"=L"))
B58: Total Estudiantes: | C58: =COUNTA(FIL!E6:E55) -> 2 | V58: Totales: | AQ58: =IF(SUM(AQ8:AQ57)=0,"",SUM(AQ8:AQ57)) | AR58: =IF(SUM(AR8:AR57)=0,"",SUM(AR8:AR57)) | AS58: =IF(SUM(AS8:AS57)=0,"",SUM(AS8:AS57)) | AT58: =IF(SUM(AT8:AT57)=0,"",SUM(AT8:AT57))
B59: Días trabajados: | C59: =COUNTA(C7:AP7) -> 0 | V59: Porcentajes: | AQ59: =IF(ISNUMBER(AQ58),AQ58/SUM(AQ58:AT58),"") | AR59: =IF(ISNUMBER(AR58),AR58/SUM(AQ58:AT58),"") | AS59: =IF(ISNUMBER(AS58),AS58/SUM(AQ58:AT58),"") | AT59: =IF(ISNUMBER(AT58),AT58/SUM(AQ58:AT58),"")

Sheet Asist. 2 Trim. Sec.
A1: ASISTENCIA SEGUNDO TRIMESTRE - GESTIÓN 2026
A2: PROFESOR(A): | C2: =Carátula!$D$23 -> JOSE CUELLAR SANCHEZ | S2: NIVEL: | X2: =Carátula!$P$18 -> SECUNDARIA
A3: CODIGO SIE: | C3: =Carátula!$P$16 -> 809811111 | S3: GRADO: | X3: =Carátula!$P$20 -> SEXTO
A4: UNIDAD EDUCATIVA: | C4: =Carátula!$D$14 -> SIMON BOLIVAR | S4: PARALELO: | X4: =Carátula!$S$20 -> "A" | AB4: P=Presente | AC4: F=Faltas | AD4: A=Atrasos | AE4: L=Licencias
A5: N° | B5: APELLIDOS Y NOMBRES | C5: MESES:
A8: 1 | B8: =IF(ISBLANK(FIL!E6),"",CONCATENATE(FIL!C6," ",FIL!D6," ",FIL!E6)) -> CUELLAR SANCHEZ JOSE | AB8: =IF(COUNTIF(C8:AA8,"=P")=0,"",COUNTIF(C8:AA8,"=P")) | AC8: =IF(COUNTIF(C8:AA8,"=F")=0,"",COUNTIF(C8:AA8,"=F")) | AD8: =IF(COUNTIF(C8:AA8,"=A")=0,"",COUNTIF(C8:AA8,"=A")) | AE8: =IF(COUNTIF(C8:AA8,"=L")=0,"",COUNTIF(C8:AA8,"=L"))
A9: 2 | B9: =IF(ISBLANK(FIL!E7),"",CONCATENATE(FIL!C7," ",FIL!D7," ",FIL!E7)) -> VALENCIA ROJAS NICOLAS | AB9: =IF(COUNTIF(C9:AA9,"=P")=0,"",COUNTIF(C9:AA9,"=P")) | AC9: =IF(COUNTIF(C9:AA9,"=F")=0,"",COUNTIF(C9:AA9,"=F")) | AD9: =IF(COUNTIF(C9:AA9,"=A")=0,"",COUNTIF(C9:AA9,"=A")) | AE9: =IF(COUNTIF(C9:AA9,"=L")=0,"",COUNTIF(C9:AA9,"=L"))
A10: 3 | B10: =IF(ISBLANK(FIL!E8),"",CONCATENATE(FIL!C8," ",FIL!D8," ",FIL!E8)) | AB10: =IF(COUNTIF(C10:AA10,"=P")=0,"",COUNTIF(C10:AA10,"=P")) | AC10: =IF(COUNTIF(C10:AA10,"=F")=0,"",COUNTIF(C10:AA10,"=F")) | AD10: =IF(COUNTIF(C10:AA10,"=A")=0,"",COUNTIF(C10:AA10,"=A")) | AE10: =IF(COUNTIF(C10:AA10,"=L")=0,"",COUNTIF(C10:AA10,"=L"))
A11: 4 | B11: =IF(ISBLANK(FIL!E9),"",CONCATENATE(FIL!C9," ",FIL!D9," ",FIL!E9)) | AB11: =IF(COUNTIF(C11:AA11,"=P")=0,"",COUNTIF(C11:AA11,"=P")) | AC11: =IF(COUNTIF(C11:AA11,"=F")=0,"",COUNTIF(C11:AA11,"=F")) | AD11: =IF(COUNTIF(C11:AA11,"=A")=0,"",COUNTIF(C11:AA11,"=A")) | AE11: =IF(COUNTIF(C11:AA11,"=L")=0,"",COUNTIF(C11:AA11,"=L"))
A12: 5 | B12: =IF(ISBLANK(FIL!E10),"",CONCATENATE(FIL!C10," ",FIL!D10," ",FIL!E10)) | AB12: =IF(COUNTIF(C12:AA12,"=P")=0,"",COUNTIF(C12:AA12,"=P")) | AC12: =IF(COUNTIF(C12:AA12,"=F")=0,"",COUNTIF(C12:AA12,"=F")) | AD12: =IF(COUNTIF(C12:AA12,"=A")=0,"",COUNTIF(C12:AA12,"=A")) | AE12: =IF(COUNTIF(C12:AA12,"=L")=0,"",COUNTIF(C12:AA12,"=L"))
A13: 6 | B13: =IF(ISBLANK(FIL!E11),"",CONCATENATE(FIL!C11," ",FIL!D11," ",FIL!E11)) | AB13: =IF(COUNTIF(C13:AA13,"=P")=0,"",COUNTIF(C13:AA13,"=P")) | AC13: =IF(COUNTIF(C13:AA13,"=F")=0,"",COUNTIF(C13:AA13,"=F")) | AD13: =IF(COUNTIF(C13:AA13,"=A")=0,"",COUNTIF(C13:AA13,"=A")) | AE13: =IF(COUNTIF(C13:AA13,"=L")=0,"",COUNTIF(C13:AA13,"=L"))
A14: 7 | B14: =IF(ISBLANK(FIL!E12),"",CONCATENATE(FIL!C12," ",FIL!D12," ",FIL!E12)) | AB14: =IF(COUNTIF(C14:AA14,"=P")=0,"",COUNTIF(C14:AA14,"=P")) | AC14: =IF(COUNTIF(C14:AA14,"=F")=0,"",COUNTIF(C14:AA14,"=F")) | AD14: =IF(COUNTIF(C14:AA14,"=A")=0,"",COUNTIF(C14:AA14,"=A")) | AE14: =IF(COUNTIF(C14:AA14,"=L")=0,"",COUNTIF(C14:AA14,"=L"))
A15: 8 | B15: =IF(ISBLANK(FIL!E13),"",CONCATENATE(FIL!C13," ",FIL!D13," ",FIL!E13)) | AB15: =IF(COUNTIF(C15:AA15,"=P")=0,"",COUNTIF(C15:AA15,"=P")) | AC15: =IF(COUNTIF(C15:AA15,"=F")=0,"",COUNTIF(C15:AA15,"=F")) | AD15: =IF(COUNTIF(C15:AA15,"=A")=0,"",COUNTIF(C15:AA15,"=A")) | AE15: =IF(COUNTIF(C15:AA15,"=L")=0,"",COUNTIF(C15:AA15,"=L"))
A16: 9 | B16: =IF(ISBLANK(FIL!E14),"",CONCATENATE(FIL!C14," ",FIL!D14," ",FIL!E14)) | AB16: =IF(COUNTIF(C16:AA16,"=P")=0,"",COUNTIF(C16:AA16,"=P")) | AC16: =IF(COUNTIF(C16:AA16,"=F")=0,"",COUNTIF(C16:AA16,"=F")) | AD16: =IF(COUNTIF(C16:AA16,"=A")=0,"",COUNTIF(C16:AA16,"=A")) | AE16: =IF(COUNTIF(C16:AA16,"=L")=0,"",COUNTIF(C16:AA16,"=L"))
A17: 10 | B17: =IF(ISBLANK(FIL!E15),"",CONCATENATE(FIL!C15," ",FIL!D15," ",FIL!E15)) | AB17: =IF(COUNTIF(C17:AA17,"=P")=0,"",COUNTIF(C17:AA17,"=P")) | AC17: =IF(COUNTIF(C17:AA17,"=F")=0,"",COUNTIF(C17:AA17,"=F")) | AD17: =IF(COUNTIF(C17:AA17,"=A")=0,"",COUNTIF(C17:AA17,"=A")) | AE17: =IF(COUNTIF(C17:AA17,"=L")=0,"",COUNTIF(C17:AA17,"=L"))
A18: 11 | B18: =IF(ISBLANK(FIL!E16),"",CONCATENATE(FIL!C16," ",FIL!D16," ",FIL!E16)) | AB18: =IF(COUNTIF(C18:AA18,"=P")=0,"",COUNTIF(C18:AA18,"=P")) | AC18: =IF(COUNTIF(C18:AA18,"=F")=0,"",COUNTIF(C18:AA18,"=F")) | AD18: =IF(COUNTIF(C18:AA18,"=A")=0,"",COUNTIF(C18:AA18,"=A")) | AE18: =IF(COUNTIF(C18:AA18,"=L")=0,"",COUNTIF(C18:AA18,"=L"))
A19: 12 | B19: =IF(ISBLANK(FIL!E17),"",CONCATENATE(FIL!C17," ",FIL!D17," ",FIL!E17)) | AB19: =IF(COUNTIF(C19:AA19,"=P")=0,"",COUNTIF(C19:AA19,"=P")) | AC19: =IF(COUNTIF(C19:AA19,"=F")=0,"",COUNTIF(C19:AA19,"=F")) | AD19: =IF(COUNTIF(C19:AA19,"=A")=0,"",COUNTIF(C19:AA19,"=A")) | AE19: =IF(COUNTIF(C19:AA19,"=L")=0,"",COUNTIF(C19:AA19,"=L"))
... A57: 50 | B57: =IF(ISBLANK(FIL!E55),"",CONCATENATE(FIL!C55," ",FIL!D55," ",FIL!E55)) | AB57: =IF(COUNTIF(C57:AA57,"=P")=0,"",COUNTIF(C57:AA57,"=P")) | AC57: =IF(COUNTIF(C57:AA57,"=F")=0,"",COUNTIF(C57:AA57,"=F")) | AD57: =IF(COUNTIF(C57:AA57,"=A")=0,"",COUNTIF(C57:AA57,"=A")) | AE57: =IF(COUNTIF(C57:AA57,"=L")=0,"",COUNTIF(C57:AA57,"=L"))
B58: Total Estudiantes: | C58: =COUNTA(FIL!E6:E55) -> 2 | AB58: =IF(SUM(AB8:AB57)=0,"",SUM(AB8:AB57)) | AC58: =IF(SUM(AC8:AC57)=0,"",SUM(AC8:AC57)) | AD58: =IF(SUM(AD8:AD57)=0,"",SUM(AD8:AD57)) | AE58: =IF(SUM(AE8:AE57)=0,"",SUM(AE8:AE57))
B59: Días trabajados: | C59: =COUNTA(C7:AA7) -> 0 | AB59: =IF(ISNUMBER(AB58),AB58/SUM(AB58:AE58),"") | AC59: =IF(ISNUMBER(AC58),AC58/SUM(AB58:AE58),"") | AD59: =IF(ISNUMBER(AD58),AD58/SUM(AB58:AE58),"") | AE59: =IF(ISNUMBER(AE58),AE58/SUM(AB58:AE58),"")

Sheet Asist. 3 Trim. Sec.
A1: ASISTENCIA TERCER TRIMESTRE - GESTIÓN 2026
A2: PROFESOR(A): | C2: =Carátula!$D$23 -> JOSE CUELLAR SANCHEZ | S2: NIVEL: | X2: =Carátula!$P$18 -> SECUNDARIA
A3: CODIGO SIE: | C3: =Carátula!$P$16 -> 809811111 | S3: GRADO: | X3: =Carátula!$P$20 -> SEXTO
A4: UNIDAD EDUCATIVA: | C4: =Carátula!$D$14 -> SIMON BOLIVAR | S4: PARALELO: | X4: =Carátula!$S$20 -> "A" | AB4: P=Presente | AC4: F=Faltas | AD4: A=Atrasos | AE4: L=Licencias
A5: N° | B5: APELLIDOS Y NOMBRES | C5: MESES:
A8: 1 | B8: =IF(ISBLANK(FIL!E6),"",CONCATENATE(FIL!C6," ",FIL!D6," ",FIL!E6)) -> CUELLAR SANCHEZ JOSE | AB8: =IF(COUNTIF(C8:AA8,"=P")=0,"",COUNTIF(C8:AA8,"=P")) | AC8: =IF(COUNTIF(C8:AA8,"=F")=0,"",COUNTIF(C8:AA8,"=F")) | AD8: =IF(COUNTIF(C8:AA8,"=A")=0,"",COUNTIF(C8:AA8,"=A")) | AE8: =IF(COUNTIF(C8:AA8,"=L")=0,"",COUNTIF(C8:AA8,"=L"))
A9: 2 | B9: =IF(ISBLANK(FIL!E7),"",CONCATENATE(FIL!C7," ",FIL!D7," ",FIL!E7)) -> VALENCIA ROJAS NICOLAS | AB9: =IF(COUNTIF(C9:AA9,"=P")=0,"",COUNTIF(C9:AA9,"=P")) | AC9: =IF(COUNTIF(C9:AA9,"=F")=0,"",COUNTIF(C9:AA9,"=F")) | AD9: =IF(COUNTIF(C9:AA9,"=A")=0,"",COUNTIF(C9:AA9,"=A")) | AE9: =IF(COUNTIF(C9:AA9,"=L")=0,"",COUNTIF(C9:AA9,"=L"))
A10: 3 | B10: =IF(ISBLANK(FIL!E8),"",CONCATENATE(FIL!C8," ",FIL!D8," ",FIL!E8)) | AB10: =IF(COUNTIF(C10:AA10,"=P")=0,"",COUNTIF(C10:AA10,"=P")) | AC10: =IF(COUNTIF(C10:AA10,"=F")=0,"",COUNTIF(C10:AA10,"=F")) | AD10: =IF(COUNTIF(C10:AA10,"=A")=0,"",COUNTIF(C10:AA10,"=A")) | AE10: =IF(COUNTIF(C10:AA10,"=L")=0,"",COUNTIF(C10:AA10,"=L"))
A11: 4 | B11: =IF(ISBLANK(FIL!E9),"",CONCATENATE(FIL!C9," ",FIL!D9," ",FIL!E9)) | AB11: =IF(COUNTIF(C11:AA11,"=P")=0,"",COUNTIF(C11:AA11,"=P")) | AC11: =IF(COUNTIF(C11:AA11,"=F")=0,"",COUNTIF(C11:AA11,"=F")) | AD11: =IF(COUNTIF(C11:AA11,"=A")=0,"",COUNTIF(C11:AA11,"=A")) | AE11: =IF(COUNTIF(C11:AA11,"=L")=0,"",COUNTIF(C11:AA11,"=L"))
A12: 5 | B12: =IF(ISBLANK(FIL!E10),"",CONCATENATE(FIL!C10," ",FIL!D10," ",FIL!E10)) | AB12: =IF(COUNTIF(C12:AA12,"=P")=0,"",COUNTIF(C12:AA12,"=P")) | AC12: =IF(COUNTIF(C12:AA12,"=F")=0,"",COUNTIF(C12:AA12,"=F")) | AD12: =IF(COUNTIF(C12:AA12,"=A")=0,"",COUNTIF(C12:AA12,"=A")) | AE12: =IF(COUNTIF(C12:AA12,"=L")=0,"",COUNTIF(C12:AA12,"=L"))
A13: 6 | B13: =IF(ISBLANK(FIL!E11),"",CONCATENATE(FIL!C11," ",FIL!D11," ",FIL!E11)) | AB13: =IF(COUNTIF(C13:AA13,"=P")=0,"",COUNTIF(C13:AA13,"=P")) | AC13: =IF(COUNTIF(C13:AA13,"=F")=0,"",COUNTIF(C13:AA13,"=F")) | AD13: =IF(COUNTIF(C13:AA13,"=A")=0,"",COUNTIF(C13:AA13,"=A")) | AE13: =IF(COUNTIF(C13:AA13,"=L")=0,"",COUNTIF(C13:AA13,"=L"))
A14: 7 | B14: =IF(ISBLANK(FIL!E12),"",CONCATENATE(FIL!C12," ",FIL!D12," ",FIL!E12)) | AB14: =IF(COUNTIF(C14:AA14,"=P")=0,"",COUNTIF(C14:AA14,"=P")) | AC14: =IF(COUNTIF(C14:AA14,"=F")=0,"",COUNTIF(C14:AA14,"=F")) | AD14: =IF(COUNTIF(C14:AA14,"=A")=0,"",COUNTIF(C14:AA14,"=A")) | AE14: =IF(COUNTIF(C14:AA14,"=L")=0,"",COUNTIF(C14:AA14,"=L"))
A15: 8 | B15: =IF(ISBLANK(FIL!E13),"",CONCATENATE(FIL!C13," ",FIL!D13," ",FIL!E13)) | AB15: =IF(COUNTIF(C15:AA15,"=P")=0,"",COUNTIF(C15:AA15,"=P")) | AC15: =IF(COUNTIF(C15:AA15,"=F")=0,"",COUNTIF(C15:AA15,"=F")) | AD15: =IF(COUNTIF(C15:AA15,"=A")=0,"",COUNTIF(C15:AA15,"=A")) | AE15: =IF(COUNTIF(C15:AA15,"=L")=0,"",COUNTIF(C15:AA15,"=L"))
A16: 9 | B16: =IF(ISBLANK(FIL!E14),"",CONCATENATE(FIL!C14," ",FIL!D14," ",FIL!E14)) | AB16: =IF(COUNTIF(C16:AA16,"=P")=0,"",COUNTIF(C16:AA16,"=P")) | AC16: =IF(COUNTIF(C16:AA16,"=F")=0,"",COUNTIF(C16:AA16,"=F")) | AD16: =IF(COUNTIF(C16:AA16,"=A")=0,"",COUNTIF(C16:AA16,"=A")) | AE16: =IF(COUNTIF(C16:AA16,"=L")=0,"",COUNTIF(C16:AA16,"=L"))
A17: 10 | B17: =IF(ISBLANK(FIL!E15),"",CONCATENATE(FIL!C15," ",FIL!D15," ",FIL!E15)) | AB17: =IF(COUNTIF(C17:AA17,"=P")=0,"",COUNTIF(C17:AA17,"=P")) | AC17: =IF(COUNTIF(C17:AA17,"=F")=0,"",COUNTIF(C17:AA17,"=F")) | AD17: =IF(COUNTIF(C17:AA17,"=A")=0,"",COUNTIF(C17:AA17,"=A")) | AE17: =IF(COUNTIF(C17:AA17,"=L")=0,"",COUNTIF(C17:AA17,"=L"))
A18: 11 | B18: =IF(ISBLANK(FIL!E16),"",CONCATENATE(FIL!C16," ",FIL!D16," ",FIL!E16)) | AB18: =IF(COUNTIF(C18:AA18,"=P")=0,"",COUNTIF(C18:AA18,"=P")) | AC18: =IF(COUNTIF(C18:AA18,"=F")=0,"",COUNTIF(C18:AA18,"=F")) | AD18: =IF(COUNTIF(C18:AA18,"=A")=0,"",COUNTIF(C18:AA18,"=A")) | AE18: =IF(COUNTIF(C18:AA18,"=L")=0,"",COUNTIF(C18:AA18,"=L"))
A19: 12 | B19: =IF(ISBLANK(FIL!E17),"",CONCATENATE(FIL!C17," ",FIL!D17," ",FIL!E17)) | AB19: =IF(COUNTIF(C19:AA19,"=P")=0,"",COUNTIF(C19:AA19,"=P")) | AC19: =IF(COUNTIF(C19:AA19,"=F")=0,"",COUNTIF(C19:AA19,"=F")) | AD19: =IF(COUNTIF(C19:AA19,"=A")=0,"",COUNTIF(C19:AA19,"=A")) | AE19: =IF(COUNTIF(C19:AA19,"=L")=0,"",COUNTIF(C19:AA19,"=L"))
... A57: 50 | B57: =IF(ISBLANK(FIL!E55),"",CONCATENATE(FIL!C55," ",FIL!D55," ",FIL!E55)) | AB57: =IF(COUNTIF(C57:AA57,"=P")=0,"",COUNTIF(C57:AA57,"=P")) | AC57: =IF(COUNTIF(C57:AA57,"=F")=0,"",COUNTIF(C57:AA57,"=F")) | AD57: =IF(COUNTIF(C57:AA57,"=A")=0,"",COUNTIF(C57:AA57,"=A")) | AE57: =IF(COUNTIF(C57:AA57,"=L")=0,"",COUNTIF(C57:AA57,"=L"))
B58: Total Estudiantes: | C58: =COUNTA(FIL!E6:E55) -> 2 | AB58: =IF(SUM(AB8:AB57)=0,"",SUM(AB8:AB57)) | AC58: =IF(SUM(AC8:AC57)=0,"",SUM(AC8:AC57)) | AD58: =IF(SUM(AD8:AD57)=0,"",SUM(AD8:AD57)) | AE58: =IF(SUM(AE8:AE57)=0,"",SUM(AE8:AE57))
B59: Días trabajados: | C59: =COUNTA(C7:AA7) -> 0 | AB59: =IF(ISNUMBER(AB58),AB58/SUM(AB58:AE58),"") | AC59: =IF(ISNUMBER(AC58),AC58/SUM(AB58:AE58),"") | AD59: =IF(ISNUMBER(AD58),AD58/SUM(AB58:AE58),"") | AE59: =IF(ISNUMBER(AE58),AE58/SUM(AB58:AE58),"")

Sheet Primer Trimestre
G1: REGISTRO DE CALIFICACIONES | T1: UNIDAD EDUCATIVA | AA1: =Carátula!D14 -> SIMON BOLIVAR | AJ1: www.educa-tics.com
A2: Curso: | C2: =CONCATENATE(Carátula!P20," ",Carátula!S20) -> SEXTO "A" | G2: EVALUACION DEL MAESTRA (O) - DIMENSIONES | AL2: Auto-Eval | AM2: Prom. 1er Trim.
A3: Gestión: | C3: =Carátula!F8 -> 2026 | G3: SER - 10 | K3: SABER - 45 | W3: HACER - 40 | AK3: PROMEDIO PARCIAL | AL3: 5
A4: Materia: | C4: =Carátula!D26 -> MATEMÁTICAS | J4: VALORACIÓN 5 Pts | V4: VALORACION 45 Pts | AJ4: VALORACION 40 Pts | AL4: AUTOEVALAUCIÓN 5 Pts
A5: Prof.: | C5: =Carátula!D23 -> JOSE CUELLAR SANCHEZ
A6: Trimestre: | C6: PRIMER TRIMESTRE
A7: 1
A8: Nº | B8: APELLIDOS Y NOMBRES
A9: 1 | B9: =IF(ISBLANK(FIL!E6),"",CONCATENATE(FIL!C6," ",FIL!D6," ",FIL!E6)) -> CUELLAR SANCHEZ JOSE | G9: 10 | J9: =IF(ISERROR(ROUND(AVERAGE(G9:I9),1)),"",ROUND(AVERAGE(G9:I9),1)) -> 10 | K9: 10 | V9: =IF(ISERROR(ROUND(AVERAGE(K9:U9),1)),"",ROUND(AVERAGE(K9:U9),1)) -> 10 | W9: 40 | AJ9: =IF(ISERROR(ROUND(AVERAGE(W9:AI9),1)),"",ROUND(AVERAGE(W9:AI9),1)) -> 40 | AK9: =IF(AO9<>0,IF(ISERROR(ROUND( (J9+V9+AJ9),0)),"",ROUND(((J9+V9+AJ9)+AO9)/2,0)),IF(ISERROR(ROUND( J9+V9+AJ9,0)),"",ROUND(J9+V9+AJ9,0))) -> 60 | AL9: 5 | AM9: =IF(AO9<>0,IF(ISERROR(ROUND( (AK9+AL9),0)),"",ROUND(((AK9+AL9)+AO9)/2,0)),IF(ISERROR(ROUND( AK9+AL9,0)),"",ROUND(AK9+AL9,0))) -> 65
A10: 2 | B10: =IF(ISBLANK(FIL!E7),"",CONCATENATE(FIL!C7," ",FIL!D7," ",FIL!E7)) -> VALENCIA ROJAS NICOLAS | G10: 6 | J10: =IF(ISERROR(ROUND(AVERAGE(G10:I10),1)),"",ROUND(AVERAGE(G10:I10),1)) -> 6 | K10: 45 | V10: =IF(ISERROR(ROUND(AVERAGE(K10:U10),1)),"",ROUND(AVERAGE(K10:U10),1)) -> 45 | W10: 40 | AJ10: =IF(ISERROR(ROUND(AVERAGE(W10:AI10),1)),"",ROUND(AVERAGE(W10:AI10),1)) -> 40 | AK10: =IF(AO10<>0,IF(ISERROR(ROUND( (J10+V10+AJ10),0)),"",ROUND(((J10+V10+AJ10)+AO10)/2,0)),IF(ISERROR(ROUND( J10+V10+AJ10,0)),"",ROUND(J10+V10+AJ10,0))) -> 91 | AL10: 2 | AM10: =IF(AO10<>0,IF(ISERROR(ROUND( (AK10+AL10),0)),"",ROUND(((AK10+AL10)+AO10)/2,0)),IF(ISERROR(ROUND( AK10+AL10,0)),"",ROUND(AK10+AL10,0))) -> 93
A11: 3 | B11: =IF(ISBLANK(FIL!E8),"",CONCATENATE(FIL!C8," ",FIL!D8," ",FIL!E8)) | J11: =IF(ISERROR(ROUND(AVERAGE(G11:I11),1)),"",ROUND(AVERAGE(G11:I11),1)) | V11: =IF(ISERROR(ROUND(AVERAGE(K11:U11),1)),"",ROUND(AVERAGE(K11:U11),1)) | AJ11: =IF(ISERROR(ROUND(AVERAGE(W11:AI11),1)),"",ROUND(AVERAGE(W11:AI11),1)) | AK11: =IF(AO11<>0,IF(ISERROR(ROUND( (J11+V11+AJ11),0)),"",ROUND(((J11+V11+AJ11)+AO11)/2,0)),IF(ISERROR(ROUND( J11+V11+AJ11,0)),"",ROUND(J11+V11+AJ11,0))) | AM11: =IF(AO11<>0,IF(ISERROR(ROUND( (AK11+AL11),0)),"",ROUND(((AK11+AL11)+AO11)/2,0)),IF(ISERROR(ROUND( AK11+AL11,0)),"",ROUND(AK11+AL11,0)))
A12: 4 | B12: =IF(ISBLANK(FIL!E9),"",CONCATENATE(FIL!C9," ",FIL!D9," ",FIL!E9)) | J12: =IF(ISERROR(ROUND(AVERAGE(G12:I12),1)),"",ROUND(AVERAGE(G12:I12),1)) | V12: =IF(ISERROR(ROUND(AVERAGE(K12:U12),1)),"",ROUND(AVERAGE(K12:U12),1)) | AJ12: =IF(ISERROR(ROUND(AVERAGE(W12:AI12),1)),"",ROUND(AVERAGE(W12:AI12),1)) | AK12: =IF(AO12<>0,IF(ISERROR(ROUND( (J12+V12+AJ12),0)),"",ROUND(((J12+V12+AJ12)+AO12)/2,0)),IF(ISERROR(ROUND( J12+V12+AJ12,0)),"",ROUND(J12+V12+AJ12,0))) | AM12: =IF(AO12<>0,IF(ISERROR(ROUND( (AK12+AL12),0)),"",ROUND(((AK12+AL12)+AO12)/2,0)),IF(ISERROR(ROUND( AK12+AL12,0)),"",ROUND(AK12+AL12,0)))
A13: 5 | B13: =IF(ISBLANK(FIL!E10),"",CONCATENATE(FIL!C10," ",FIL!D10," ",FIL!E10)) | J13: =IF(ISERROR(ROUND(AVERAGE(G13:I13),1)),"",ROUND(AVERAGE(G13:I13),1)) | V13: =IF(ISERROR(ROUND(AVERAGE(K13:U13),1)),"",ROUND(AVERAGE(K13:U13),1)) | AJ13: =IF(ISERROR(ROUND(AVERAGE(W13:AI13),1)),"",ROUND(AVERAGE(W13:AI13),1)) | AK13: =IF(AO13<>0,IF(ISERROR(ROUND( (J13+V13+AJ13),0)),"",ROUND(((J13+V13+AJ13)+AO13)/2,0)),IF(ISERROR(ROUND( J13+V13+AJ13,0)),"",ROUND(J13+V13+AJ13,0))) | AM13: =IF(AO13<>0,IF(ISERROR(ROUND( (AK13+AL13),0)),"",ROUND(((AK13+AL13)+AO13)/2,0)),IF(ISERROR(ROUND( AK13+AL13,0)),"",ROUND(AK13+AL13,0)))
A14: 6 | B14: =IF(ISBLANK(FIL!E11),"",CONCATENATE(FIL!C11," ",FIL!D11," ",FIL!E11)) | J14: =IF(ISERROR(ROUND(AVERAGE(G14:I14),1)),"",ROUND(AVERAGE(G14:I14),1)) | V14: =IF(ISERROR(ROUND(AVERAGE(K14:U14),1)),"",ROUND(AVERAGE(K14:U14),1)) | AJ14: =IF(ISERROR(ROUND(AVERAGE(W14:AI14),1)),"",ROUND(AVERAGE(W14:AI14),1)) | AK14: =IF(AO14<>0,IF(ISERROR(ROUND( (J14+V14+AJ14),0)),"",ROUND(((J14+V14+AJ14)+AO14)/2,0)),IF(ISERROR(ROUND( J14+V14+AJ14,0)),"",ROUND(J14+V14+AJ14,0))) | AM14: =IF(AO14<>0,IF(ISERROR(ROUND( (AK14+AL14),0)),"",ROUND(((AK14+AL14)+AO14)/2,0)),IF(ISERROR(ROUND( AK14+AL14,0)),"",ROUND(AK14+AL14,0)))
A15: 7 | B15: =IF(ISBLANK(FIL!E12),"",CONCATENATE(FIL!C12," ",FIL!D12," ",FIL!E12)) | J15: =IF(ISERROR(ROUND(AVERAGE(G15:I15),1)),"",ROUND(AVERAGE(G15:I15),1)) | V15: =IF(ISERROR(ROUND(AVERAGE(K15:U15),1)),"",ROUND(AVERAGE(K15:U15),1)) | AJ15: =IF(ISERROR(ROUND(AVERAGE(W15:AI15),1)),"",ROUND(AVERAGE(W15:AI15),1)) | AK15: =IF(AO15<>0,IF(ISERROR(ROUND( (J15+V15+AJ15),0)),"",ROUND(((J15+V15+AJ15)+AO15)/2,0)),IF(ISERROR(ROUND( J15+V15+AJ15,0)),"",ROUND(J15+V15+AJ15,0))) | AM15: =IF(AO15<>0,IF(ISERROR(ROUND( (AK15+AL15),0)),"",ROUND(((AK15+AL15)+AO15)/2,0)),IF(ISERROR(ROUND( AK15+AL15,0)),"",ROUND(AK15+AL15,0)))
A16: 8 | B16: =IF(ISBLANK(FIL!E13),"",CONCATENATE(FIL!C13," ",FIL!D13," ",FIL!E13)) | J16: =IF(ISERROR(ROUND(AVERAGE(G16:I16),1)),"",ROUND(AVERAGE(G16:I16),1)) | V16: =IF(ISERROR(ROUND(AVERAGE(K16:U16),1)),"",ROUND(AVERAGE(K16:U16),1)) | AJ16: =IF(ISERROR(ROUND(AVERAGE(W16:AI16),1)),"",ROUND(AVERAGE(W16:AI16),1)) | AK16: =IF(AO16<>0,IF(ISERROR(ROUND( (J16+V16+AJ16),0)),"",ROUND(((J16+V16+AJ16)+AO16)/2,0)),IF(ISERROR(ROUND( J16+V16+AJ16,0)),"",ROUND(J16+V16+AJ16,0))) | AM16: =IF(AO16<>0,IF(ISERROR(ROUND( (AK16+AL16),0)),"",ROUND(((AK16+AL16)+AO16)/2,0)),IF(ISERROR(ROUND( AK16+AL16,0)),"",ROUND(AK16+AL16,0)))
A17: 9 | B17: =IF(ISBLANK(FIL!E14),"",CONCATENATE(FIL!C14," ",FIL!D14," ",FIL!E14)) | J17: =IF(ISERROR(ROUND(AVERAGE(G17:I17),1)),"",ROUND(AVERAGE(G17:I17),1)) | V17: =IF(ISERROR(ROUND(AVERAGE(K17:U17),1)),"",ROUND(AVERAGE(K17:U17),1)) | AJ17: =IF(ISERROR(ROUND(AVERAGE(W17:AI17),1)),"",ROUND(AVERAGE(W17:AI17),1)) | AK17: =IF(AO17<>0,IF(ISERROR(ROUND( (J17+V17+AJ17),0)),"",ROUND(((J17+V17+AJ17)+AO17)/2,0)),IF(ISERROR(ROUND( J17+V17+AJ17,0)),"",ROUND(J17+V17+AJ17,0))) | AM17: =IF(AO17<>0,IF(ISERROR(ROUND( (AK17+AL17),0)),"",ROUND(((AK17+AL17)+AO17)/2,0)),IF(ISERROR(ROUND( AK17+AL17,0)),"",ROUND(AK17+AL17,0)))
A18: 10 | B18: =IF(ISBLANK(FIL!E15),"",CONCATENATE(FIL!C15," ",FIL!D15," ",FIL!E15)) | J18: =IF(ISERROR(ROUND(AVERAGE(G18:I18),1)),"",ROUND(AVERAGE(G18:I18),1)) | V18: =IF(ISERROR(ROUND(AVERAGE(K18:U18),1)),"",ROUND(AVERAGE(K18:U18),1)) | AJ18: =IF(ISERROR(ROUND(AVERAGE(W18:AI18),1)),"",ROUND(AVERAGE(W18:AI18),1)) | AK18: =IF(AO18<>0,IF(ISERROR(ROUND( (J18+V18+AJ18),0)),"",ROUND(((J18+V18+AJ18)+AO18)/2,0)),IF(ISERROR(ROUND( J18+V18+AJ18,0)),"",ROUND(J18+V18+AJ18,0))) | AM18: =IF(AO18<>0,IF(ISERROR(ROUND( (AK18+AL18),0)),"",ROUND(((AK18+AL18)+AO18)/2,0)),IF(ISERROR(ROUND( AK18+AL18,0)),"",ROUND(AK18+AL18,0)))
A19: 11 | B19: =IF(ISBLANK(FIL!E16),"",CONCATENATE(FIL!C16," ",FIL!D16," ",FIL!E16)) | J19: =IF(ISERROR(ROUND(AVERAGE(G19:I19),1)),"",ROUND(AVERAGE(G19:I19),1)) | V19: =IF(ISERROR(ROUND(AVERAGE(K19:U19),1)),"",ROUND(AVERAGE(K19:U19),1)) | AJ19: =IF(ISERROR(ROUND(AVERAGE(W19:AI19),1)),"",ROUND(AVERAGE(W19:AI19),1)) | AK19: =IF(AO19<>0,IF(ISERROR(ROUND( (J19+V19+AJ19),0)),"",ROUND(((J19+V19+AJ19)+AO19)/2,0)),IF(ISERROR(ROUND( J19+V19+AJ19,0)),"",ROUND(J19+V19+AJ19,0))) | AM19: =IF(AO19<>0,IF(ISERROR(ROUND( (AK19+AL19),0)),"",ROUND(((AK19+AL19)+AO19)/2,0)),IF(ISERROR(ROUND( AK19+AL19,0)),"",ROUND(AK19+AL19,0)))
A20: 12 | B20: =IF(ISBLANK(FIL!E17),"",CONCATENATE(FIL!C17," ",FIL!D17," ",FIL!E17)) | J20: =IF(ISERROR(ROUND(AVERAGE(G20:I20),1)),"",ROUND(AVERAGE(G20:I20),1)) | V20: =IF(ISERROR(ROUND(AVERAGE(K20:U20),1)),"",ROUND(AVERAGE(K20:U20),1)) | AJ20: =IF(ISERROR(ROUND(AVERAGE(W20:AI20),1)),"",ROUND(AVERAGE(W20:AI20),1)) | AK20: =IF(AO20<>0,IF(ISERROR(ROUND( (J20+V20+AJ20),0)),"",ROUND(((J20+V20+AJ20)+AO20)/2,0)),IF(ISERROR(ROUND( J20+V20+AJ20,0)),"",ROUND(J20+V20+AJ20,0))) | AM20: =IF(AO20<>0,IF(ISERROR(ROUND( (AK20+AL20),0)),"",ROUND(((AK20+AL20)+AO20)/2,0)),IF(ISERROR(ROUND( AK20+AL20,0)),"",ROUND(AK20+AL20,0)))
A21: 13 | B21: =IF(ISBLANK(FIL!E18),"",CONCATENATE(FIL!C18," ",FIL!D18," ",FIL!E18)) | J21: =IF(ISERROR(ROUND(AVERAGE(G21:I21),1)),"",ROUND(AVERAGE(G21:I21),1)) | V21: =IF(ISERROR(ROUND(AVERAGE(K21:U21),1)),"",ROUND(AVERAGE(K21:U21),1)) | AJ21: =IF(ISERROR(ROUND(AVERAGE(W21:AI21),1)),"",ROUND(AVERAGE(W21:AI21),1)) | AK21: =IF(AO21<>0,IF(ISERROR(ROUND( (J21+V21+AJ21),0)),"",ROUND(((J21+V21+AJ21)+AO21)/2,0)),IF(ISERROR(ROUND( J21+V21+AJ21,0)),"",ROUND(J21+V21+AJ21,0))) | AM21: =IF(AO21<>0,IF(ISERROR(ROUND( (AK21+AL21),0)),"",ROUND(((AK21+AL21)+AO21)/2,0)),IF(ISERROR(ROUND( AK21+AL21,0)),"",ROUND(AK21+AL21,0)))
A22: 14 | B22: =IF(ISBLANK(FIL!E19),"",CONCATENATE(FIL!C19," ",FIL!D19," ",FIL!E19)) | J22: =IF(ISERROR(ROUND(AVERAGE(G22:I22),1)),"",ROUND(AVERAGE(G22:I22),1)) | V22: =IF(ISERROR(ROUND(AVERAGE(K22:U22),1)),"",ROUND(AVERAGE(K22:U22),1)) | AJ22: =IF(ISERROR(ROUND(AVERAGE(W22:AI22),1)),"",ROUND(AVERAGE(W22:AI22),1)) | AK22: =IF(AO22<>0,IF(ISERROR(ROUND( (J22+V22+AJ22),0)),"",ROUND(((J22+V22+AJ22)+AO22)/2,0)),IF(ISERROR(ROUND( J22+V22+AJ22,0)),"",ROUND(J22+V22+AJ22,0))) | AM22: =IF(AO22<>0,IF(ISERROR(ROUND( (AK22+AL22),0)),"",ROUND(((AK22+AL22)+AO22)/2,0)),IF(ISERROR(ROUND( AK22+AL22,0)),"",ROUND(AK22+AL22,0)))
... A55: 47 | B55: =IF(ISBLANK(FIL!E52),"",CONCATENATE(FIL!C52," ",FIL!D52," ",FIL!E52)) | J55: =IF(ISERROR(ROUND(AVERAGE(G55:I55),1)),"",ROUND(AVERAGE(G55:I55),1)) | V55: =IF(ISERROR(ROUND(AVERAGE(K55:U55),1)),"",ROUND(AVERAGE(K55:U55),1)) | AJ55: =IF(ISERROR(ROUND(AVERAGE(W55:AI55),1)),"",ROUND(AVERAGE(W55:AI55),1)) | AK55: =IF(AO55<>0,IF(ISERROR(ROUND( (J55+V55+AJ55),0)),"",ROUND(((J55+V55+AJ55)+AO55)/2,0)),IF(ISERROR(ROUND( J55+V55+AJ55,0)),"",ROUND(J55+V55+AJ55,0))) | AM55: =IF(AO55<>0,IF(ISERROR(ROUND( (AK55+AL55),0)),"",ROUND(((AK55+AL55)+AO55)/2,0)),IF(ISERROR(ROUND( AK55+AL55,0)),"",ROUND(AK55+AL55,0)))
A56: 48 | U56: =IF(ISERROR(ROUND(AVERAGE(H56:T56),1)),"",ROUND(AVERAGE(H56:T56),1)) | AJ56: =IF(ISERROR(ROUND(AVERAGE(V56:AI56),1)),"",ROUND(AVERAGE(V56:AI56),1)) | AL56: =IF(ISERROR(ROUND(U56+AJ56+#REF!,0)),"",ROUND(U56+AJ56+#REF!,0))
A57: 49 | U57: =IF(ISERROR(ROUND(AVERAGE(H57:T57),1)),"",ROUND(AVERAGE(H57:T57),1)) | AJ57: =IF(ISERROR(ROUND(AVERAGE(V57:AI57),1)),"",ROUND(AVERAGE(V57:AI57),1)) | AL57: =IF(ISERROR(ROUND(U57+AJ57+#REF!,0)),"",ROUND(U57+AJ57+#REF!,0))
A58: 50 | U58: =IF(ISERROR(ROUND(AVERAGE(H58:T58),1)),"",ROUND(AVERAGE(H58:T58),1)) | AJ58: =IF(ISERROR(ROUND(AVERAGE(V58:AI58),1)),"",ROUND(AVERAGE(V58:AI58),1)) | AL58: =IF(ISERROR(ROUND(U58+AJ58+#REF!,0)),"",ROUND(U58+AJ58+#REF!,0))
G60: TOTAL DE ESTUDIANTES | AM60: =COUNTIF($AM$9:$AM$58,">0") -> 2
G61: TOTAL APROBADOS | AM61: =IF($AM$60>0,COUNTIF($AM$9:$AM$58,">50"),"") -> 2
G62: TOTAL REPROBADOS | AM62: =IF($AM$60>0,COUNTIF($AM$9:$AM$58,"<51"),"") -> 0
G63: PROMEDIO TRIMESTRAL | AM63: =IF($AM$60>0,ROUND(AVERAGE($AM9:$AM58),0),"") -> 79
A64: _ _ _ _ _ _ _ _ _ _ _ _ _ _ _ _ _ _ _ _ _ _ _ | G64: PORCENTAJE DE APROBADOS | AM64: =IF(AM60>0,AM61*100/AM60,"") -> 100
A65: FIRMA / SELLO | G65: PORCENTAJE DE REPROBADOS | AM65: =IF(AM60>0,AM62*100/AM60,"") -> 0

Sheet Segundo Trimestre
G1: REGISTRO DE CALIFICACIONES | T1: UNIDAD EDUCATIVA | AA1: =Carátula!D14 -> SIMON BOLIVAR | AJ1: www.educa-tics.com
A2: Curso: | C2: =CONCATENATE(Carátula!P20," ",Carátula!S20) -> SEXTO "A" | G2: EVALUACION DEL MAESTRA (O) - DIMENSIONES | AL2: Auto-Eval | AM2: Prom. 1er Trim.
A3: Gestión: | C3: =Carátula!F8 -> 2026 | G3: SER - 10 | K3: SABER - 45 | W3: HACER - 40 | AK3: PROMEDIO PARCIAL | AL3: 5
A4: Materia: | C4: =Carátula!D26 -> MATEMÁTICAS | J4: VALORACIÓN 5 Pts | V4: VALORACION 45 Pts | AJ4: VALORACION 40 Pts | AL4: AUTOEVALAUCIÓN 5 Pts
A5: Prof.: | C5: =Carátula!D23 -> JOSE CUELLAR SANCHEZ
A6: Trimestre: | C6: SEGUNDO TRIMESTRE
A7: 1
A8: Nº | B8: APELLIDOS Y NOMBRES
A9: 1 | B9: =IF(ISBLANK(FIL!E6),"",CONCATENATE(FIL!C6," ",FIL!D6," ",FIL!E6)) -> CUELLAR SANCHEZ JOSE | G9: 10 | J9: =IF(ISERROR(ROUND(AVERAGE(G9:I9),1)),"",ROUND(AVERAGE(G9:I9),1)) -> 10 | K9: 45 | V9: =IF(ISERROR(ROUND(AVERAGE(K9:U9),1)),"",ROUND(AVERAGE(K9:U9),1)) -> 45 | W9: 40 | AJ9: =IF(ISERROR(ROUND(AVERAGE(W9:AI9),1)),"",ROUND(AVERAGE(W9:AI9),1)) -> 40 | AK9: =IF(AO9<>0,IF(ISERROR(ROUND( (J9+V9+AJ9),0)),"",ROUND(((J9+V9+AJ9)+AO9)/2,0)),IF(ISERROR(ROUND( J9+V9+AJ9,0)),"",ROUND(J9+V9+AJ9,0))) -> 95 | AL9: 5 | AM9: =IF(AO9<>0,IF(ISERROR(ROUND( (AK9+AL9),0)),"",ROUND(((AK9+AL9)+AO9)/2,0)),IF(ISERROR(ROUND( AK9+AL9,0)),"",ROUND(AK9+AL9,0))) -> 100
A10: 2 | B10: =IF(ISBLANK(FIL!E7),"",CONCATENATE(FIL!C7," ",FIL!D7," ",FIL!E7)) -> VALENCIA ROJAS NICOLAS | G10: 8 | J10: =IF(ISERROR(ROUND(AVERAGE(G10:I10),1)),"",ROUND(AVERAGE(G10:I10),1)) -> 8 | K10: 10 | V10: =IF(ISERROR(ROUND(AVERAGE(K10:U10),1)),"",ROUND(AVERAGE(K10:U10),1)) -> 10 | W10: 35 | AJ10: =IF(ISERROR(ROUND(AVERAGE(W10:AI10),1)),"",ROUND(AVERAGE(W10:AI10),1)) -> 35 | AK10: =IF(AO10<>0,IF(ISERROR(ROUND( (J10+V10+AJ10),0)),"",ROUND(((J10+V10+AJ10)+AO10)/2,0)),IF(ISERROR(ROUND( J10+V10+AJ10,0)),"",ROUND(J10+V10+AJ10,0))) -> 53 | AL10: 3 | AM10: =IF(AO10<>0,IF(ISERROR(ROUND( (AK10+AL10),0)),"",ROUND(((AK10+AL10)+AO10)/2,0)),IF(ISERROR(ROUND( AK10+AL10,0)),"",ROUND(AK10+AL10,0))) -> 56
A11: 3 | B11: =IF(ISBLANK(FIL!E8),"",CONCATENATE(FIL!C8," ",FIL!D8," ",FIL!E8)) | J11: =IF(ISERROR(ROUND(AVERAGE(G11:I11),1)),"",ROUND(AVERAGE(G11:I11),1)) | V11: =IF(ISERROR(ROUND(AVERAGE(K11:U11),1)),"",ROUND(AVERAGE(K11:U11),1)) | AJ11: =IF(ISERROR(ROUND(AVERAGE(W11:AI11),1)),"",ROUND(AVERAGE(W11:AI11),1)) | AK11: =IF(AO11<>0,IF(ISERROR(ROUND( (J11+V11+AJ11),0)),"",ROUND(((J11+V11+AJ11)+AO11)/2,0)),IF(ISERROR(ROUND( J11+V11+AJ11,0)),"",ROUND(J11+V11+AJ11,0))) | AM11: =IF(AO11<>0,IF(ISERROR(ROUND( (AK11+AL11),0)),"",ROUND(((AK11+AL11)+AO11)/2,0)),IF(ISERROR(ROUND( AK11+AL11,0)),"",ROUND(AK11+AL11,0)))
A12: 4 | B12: =IF(ISBLANK(FIL!E9),"",CONCATENATE(FIL!C9," ",FIL!D9," ",FIL!E9)) | J12: =IF(ISERROR(ROUND(AVERAGE(G12:I12),1)),"",ROUND(AVERAGE(G12:I12),1)) | V12: =IF(ISERROR(ROUND(AVERAGE(K12:U12),1)),"",ROUND(AVERAGE(K12:U12),1)) | AJ12: =IF(ISERROR(ROUND(AVERAGE(W12:AI12),1)),"",ROUND(AVERAGE(W12:AI12),1)) | AK12: =IF(AO12<>0,IF(ISERROR(ROUND( (J12+V12+AJ12),0)),"",ROUND(((J12+V12+AJ12)+AO12)/2,0)),IF(ISERROR(ROUND( J12+V12+AJ12,0)),"",ROUND(J12+V12+AJ12,0))) | AM12: =IF(AO12<>0,IF(ISERROR(ROUND( (AK12+AL12),0)),"",ROUND(((AK12+AL12)+AO12)/2,0)),IF(ISERROR(ROUND( AK12+AL12,0)),"",ROUND(AK12+AL12,0)))
A13: 5 | B13: =IF(ISBLANK(FIL!E10),"",CONCATENATE(FIL!C10," ",FIL!D10," ",FIL!E10)) | J13: =IF(ISERROR(ROUND(AVERAGE(G13:I13),1)),"",ROUND(AVERAGE(G13:I13),1)) | V13: =IF(ISERROR(ROUND(AVERAGE(K13:U13),1)),"",ROUND(AVERAGE(K13:U13),1)) | AJ13: =IF(ISERROR(ROUND(AVERAGE(W13:AI13),1)),"",ROUND(AVERAGE(W13:AI13),1)) | AK13: =IF(AO13<>0,IF(ISERROR(ROUND( (J13+V13+AJ13),0)),"",ROUND(((J13+V13+AJ13)+AO13)/2,0)),IF(ISERROR(ROUND( J13+V13+AJ13,0)),"",ROUND(J13+V13+AJ13,0))) | AM13: =IF(AO13<>0,IF(ISERROR(ROUND( (AK13+AL13),0)),"",ROUND(((AK13+AL13)+AO13)/2,0)),IF(ISERROR(ROUND( AK13+AL13,0)),"",ROUND(AK13+AL13,0)))
A14: 6 | B14: =IF(ISBLANK(FIL!E11),"",CONCATENATE(FIL!C11," ",FIL!D11," ",FIL!E11)) | J14: =IF(ISERROR(ROUND(AVERAGE(G14:I14),1)),"",ROUND(AVERAGE(G14:I14),1)) | V14: =IF(ISERROR(ROUND(AVERAGE(K14:U14),1)),"",ROUND(AVERAGE(K14:U14),1)) | AJ14: =IF(ISERROR(ROUND(AVERAGE(W14:AI14),1)),"",ROUND(AVERAGE(W14:AI14),1)) | AK14: =IF(AO14<>0,IF(ISERROR(ROUND( (J14+V14+AJ14),0)),"",ROUND(((J14+V14+AJ14)+AO14)/2,0)),IF(ISERROR(ROUND( J14+V14+AJ14,0)),"",ROUND(J14+V14+AJ14,0))) | AM14: =IF(AO14<>0,IF(ISERROR(ROUND( (AK14+AL14),0)),"",ROUND(((AK14+AL14)+AO14)/2,0)),IF(ISERROR(ROUND( AK14+AL14,0)),"",ROUND(AK14+AL14,0)))
A15: 7 | B15: =IF(ISBLANK(FIL!E12),"",CONCATENATE(FIL!C12," ",FIL!D12," ",FIL!E12)) | J15: =IF(ISERROR(ROUND(AVERAGE(G15:I15),1)),"",ROUND(AVERAGE(G15:I15),1)) | V15: =IF(ISERROR(ROUND(AVERAGE(K15:U15),1)),"",ROUND(AVERAGE(K15:U15),1)) | AJ15: =IF(ISERROR(ROUND(AVERAGE(W15:AI15),1)),"",ROUND(AVERAGE(W15:AI15),1)) | AK15: =IF(AO15<>0,IF(ISERROR(ROUND( (J15+V15+AJ15),0)),"",ROUND(((J15+V15+AJ15)+AO15)/2,0)),IF(ISERROR(ROUND( J15+V15+AJ15,0)),"",ROUND(J15+V15+AJ15,0))) | AM15: =IF(AO15<>0,IF(ISERROR(ROUND( (AK15+AL15),0)),"",ROUND(((AK15+AL15)+AO15)/2,0)),IF(ISERROR(ROUND( AK15+AL15,0)),"",ROUND(AK15+AL15,0)))
A16: 8 | B16: =IF(ISBLANK(FIL!E13),"",CONCATENATE(FIL!C13," ",FIL!D13," ",FIL!E13)) | J16: =IF(ISERROR(ROUND(AVERAGE(G16:I16),1)),"",ROUND(AVERAGE(G16:I16),1)) | V16: =IF(ISERROR(ROUND(AVERAGE(K16:U16),1)),"",ROUND(AVERAGE(K16:U16),1)) | AJ16: =IF(ISERROR(ROUND(AVERAGE(W16:AI16),1)),"",ROUND(AVERAGE(W16:AI16),1)) | AK16: =IF(AO16<>0,IF(ISERROR(ROUND( (J16+V16+AJ16),0)),"",ROUND(((J16+V16+AJ16)+AO16)/2,0)),IF(ISERROR(ROUND( J16+V16+AJ16,0)),"",ROUND(J16+V16+AJ16,0))) | AM16: =IF(AO16<>0,IF(ISERROR(ROUND( (AK16+AL16),0)),"",ROUND(((AK16+AL16)+AO16)/2,0)),IF(ISERROR(ROUND( AK16+AL16,0)),"",ROUND(AK16+AL16,0)))
A17: 9 | B17: =IF(ISBLANK(FIL!E14),"",CONCATENATE(FIL!C14," ",FIL!D14," ",FIL!E14)) | J17: =IF(ISERROR(ROUND(AVERAGE(G17:I17),1)),"",ROUND(AVERAGE(G17:I17),1)) | V17: =IF(ISERROR(ROUND(AVERAGE(K17:U17),1)),"",ROUND(AVERAGE(K17:U17),1)) | AJ17: =IF(ISERROR(ROUND(AVERAGE(W17:AI17),1)),"",ROUND(AVERAGE(W17:AI17),1)) | AK17: =IF(AO17<>0,IF(ISERROR(ROUND( (J17+V17+AJ17),0)),"",ROUND(((J17+V17+AJ17)+AO17)/2,0)),IF(ISERROR(ROUND( J17+V17+AJ17,0)),"",ROUND(J17+V17+AJ17,0))) | AM17: =IF(AO17<>0,IF(ISERROR(ROUND( (AK17+AL17),0)),"",ROUND(((AK17+AL17)+AO17)/2,0)),IF(ISERROR(ROUND( AK17+AL17,0)),"",ROUND(AK17+AL17,0)))
A18: 10 | B18: =IF(ISBLANK(FIL!E15),"",CONCATENATE(FIL!C15," ",FIL!D15," ",FIL!E15)) | J18: =IF(ISERROR(ROUND(AVERAGE(G18:I18),1)),"",ROUND(AVERAGE(G18:I18),1)) | V18: =IF(ISERROR(ROUND(AVERAGE(K18:U18),1)),"",ROUND(AVERAGE(K18:U18),1)) | AJ18: =IF(ISERROR(ROUND(AVERAGE(W18:AI18),1)),"",ROUND(AVERAGE(W18:AI18),1)) | AK18: =IF(AO18<>0,IF(ISERROR(ROUND( (J18+V18+AJ18),0)),"",ROUND(((J18+V18+AJ18)+AO18)/2,0)),IF(ISERROR(ROUND( J18+V18+AJ18,0)),"",ROUND(J18+V18+AJ18,0))) | AM18: =IF(AO18<>0,IF(ISERROR(ROUND( (AK18+AL18),0)),"",ROUND(((AK18+AL18)+AO18)/2,0)),IF(ISERROR(ROUND( AK18+AL18,0)),"",ROUND(AK18+AL18,0)))
A19: 11 | B19: =IF(ISBLANK(FIL!E16),"",CONCATENATE(FIL!C16," ",FIL!D16," ",FIL!E16)) | J19: =IF(ISERROR(ROUND(AVERAGE(G19:I19),1)),"",ROUND(AVERAGE(G19:I19),1)) | V19: =IF(ISERROR(ROUND(AVERAGE(K19:U19),1)),"",ROUND(AVERAGE(K19:U19),1)) | AJ19: =IF(ISERROR(ROUND(AVERAGE(W19:AI19),1)),"",ROUND(AVERAGE(W19:AI19),1)) | AK19: =IF(AO19<>0,IF(ISERROR(ROUND( (J19+V19+AJ19),0)),"",ROUND(((J19+V19+AJ19)+AO19)/2,0)),IF(ISERROR(ROUND( J19+V19+AJ19,0)),"",ROUND(J19+V19+AJ19,0))) | AM19: =IF(AO19<>0,IF(ISERROR(ROUND( (AK19+AL19),0)),"",ROUND(((AK19+AL19)+AO19)/2,0)),IF(ISERROR(ROUND( AK19+AL19,0)),"",ROUND(AK19+AL19,0)))
A20: 12 | B20: =IF(ISBLANK(FIL!E17),"",CONCATENATE(FIL!C17," ",FIL!D17," ",FIL!E17)) | J20: =IF(ISERROR(ROUND(AVERAGE(G20:I20),1)),"",ROUND(AVERAGE(G20:I20),1)) | V20: =IF(ISERROR(ROUND(AVERAGE(K20:U20),1)),"",ROUND(AVERAGE(K20:U20),1)) | AJ20: =IF(ISERROR(ROUND(AVERAGE(W20:AI20),1)),"",ROUND(AVERAGE(W20:AI20),1)) | AK20: =IF(AO20<>0,IF(ISERROR(ROUND( (J20+V20+AJ20),0)),"",ROUND(((J20+V20+AJ20)+AO20)/2,0)),IF(ISERROR(ROUND( J20+V20+AJ20,0)),"",ROUND(J20+V20+AJ20,0))) | AM20: =IF(AO20<>0,IF(ISERROR(ROUND( (AK20+AL20),0)),"",ROUND(((AK20+AL20)+AO20)/2,0)),IF(ISERROR(ROUND( AK20+AL20,0)),"",ROUND(AK20+AL20,0)))
A21: 13 | B21: =IF(ISBLANK(FIL!E18),"",CONCATENATE(FIL!C18," ",FIL!D18," ",FIL!E18)) | J21: =IF(ISERROR(ROUND(AVERAGE(G21:I21),1)),"",ROUND(AVERAGE(G21:I21),1)) | V21: =IF(ISERROR(ROUND(AVERAGE(K21:U21),1)),"",ROUND(AVERAGE(K21:U21),1)) | AJ21: =IF(ISERROR(ROUND(AVERAGE(W21:AI21),1)),"",ROUND(AVERAGE(W21:AI21),1)) | AK21: =IF(AO21<>0,IF(ISERROR(ROUND( (J21+V21+AJ21),0)),"",ROUND(((J21+V21+AJ21)+AO21)/2,0)),IF(ISERROR(ROUND( J21+V21+AJ21,0)),"",ROUND(J21+V21+AJ21,0))) | AM21: =IF(AO21<>0,IF(ISERROR(ROUND( (AK21+AL21),0)),"",ROUND(((AK21+AL21)+AO21)/2,0)),IF(ISERROR(ROUND( AK21+AL21,0)),"",ROUND(AK21+AL21,0)))
A22: 14 | B22: =IF(ISBLANK(FIL!E19),"",CONCATENATE(FIL!C19," ",FIL!D19," ",FIL!E19)) | J22: =IF(ISERROR(ROUND(AVERAGE(G22:I22),1)),"",ROUND(AVERAGE(G22:I22),1)) | V22: =IF(ISERROR(ROUND(AVERAGE(K22:U22),1)),"",ROUND(AVERAGE(K22:U22),1)) | AJ22: =IF(ISERROR(ROUND(AVERAGE(W22:AI22),1)),"",ROUND(AVERAGE(W22:AI22),1)) | AK22: =IF(AO22<>0,IF(ISERROR(ROUND( (J22+V22+AJ22),0)),"",ROUND(((J22+V22+AJ22)+AO22)/2,0)),IF(ISERROR(ROUND( J22+V22+AJ22,0)),"",ROUND(J22+V22+AJ22,0))) | AM22: =IF(AO22<>0,IF(ISERROR(ROUND( (AK22+AL22),0)),"",ROUND(((AK22+AL22)+AO22)/2,0)),IF(ISERROR(ROUND( AK22+AL22,0)),"",ROUND(AK22+AL22,0)))
... A55: 47 | B55: =IF(ISBLANK(FIL!E52),"",CONCATENATE(FIL!C52," ",FIL!D52," ",FIL!E52)) | J55: =IF(ISERROR(ROUND(AVERAGE(G55:I55),1)),"",ROUND(AVERAGE(G55:I55),1)) | V55: =IF(ISERROR(ROUND(AVERAGE(K55:U55),1)),"",ROUND(AVERAGE(K55:U55),1)) | AJ55: =IF(ISERROR(ROUND(AVERAGE(W55:AI55),1)),"",ROUND(AVERAGE(W55:AI55),1)) | AK55: =IF(AO55<>0,IF(ISERROR(ROUND( (J55+V55+AJ55),0)),"",ROUND(((J55+V55+AJ55)+AO55)/2,0)),IF(ISERROR(ROUND( J55+V55+AJ55,0)),"",ROUND(J55+V55+AJ55,0))) | AM55: =IF(AO55<>0,IF(ISERROR(ROUND( (AK55+AL55),0)),"",ROUND(((AK55+AL55)+AO55)/2,0)),IF(ISERROR(ROUND( AK55+AL55,0)),"",ROUND(AK55+AL55,0)))
A56: 48 | U56: =IF(ISERROR(ROUND(AVERAGE(H56:T56),1)),"",ROUND(AVERAGE(H56:T56),1)) | AJ56: =IF(ISERROR(ROUND(AVERAGE(V56:AI56),1)),"",ROUND(AVERAGE(V56:AI56),1)) | AL56: =IF(ISERROR(ROUND(U56+AJ56+#REF!,0)),"",ROUND(U56+AJ56+#REF!,0))
A57: 49 | U57: =IF(ISERROR(ROUND(AVERAGE(H57:T57),1)),"",ROUND(AVERAGE(H57:T57),1)) | AJ57: =IF(ISERROR(ROUND(AVERAGE(V57:AI57),1)),"",ROUND(AVERAGE(V57:AI57),1)) | AL57: =IF(ISERROR(ROUND(U57+AJ57+#REF!,0)),"",ROUND(U57+AJ57+#REF!,0))
A58: 50 | U58: =IF(ISERROR(ROUND(AVERAGE(H58:T58),1)),"",ROUND(AVERAGE(H58:T58),1)) | AJ58: =IF(ISERROR(ROUND(AVERAGE(V58:AI58),1)),"",ROUND(AVERAGE(V58:AI58),1)) | AL58: =IF(ISERROR(ROUND(U58+AJ58+#REF!,0)),"",ROUND(U58+AJ58+#REF!,0))
G60: TOTAL DE ESTUDIANTES | AM60: =COUNTIF($AM$9:$AM$58,">0") -> 2
G61: TOTAL APROBADOS | AM61: =IF($AM$60>0,COUNTIF($AM$9:$AM$58,">50"),"") -> 2
G62: TOTAL REPROBADOS | AM62: =IF($AM$60>0,COUNTIF($AM$9:$AM$58,"<51"),"") -> 0
G63: PROMEDIO TRIMESTRAL | AM63: =IF($AM$60>0,ROUND(AVERAGE($AM9:$AM58),0),"") -> 78
A64: _ _ _ _ _ _ _ _ _ _ _ _ _ _ _ _ _ _ _ _ _ _ _ | G64: PORCENTAJE DE APROBADOS | AM64: =IF(AM60>0,AM61*100/AM60,"") -> 100
A65: FIRMA / SELLO | G65: PORCENTAJE DE REPROBADOS | AM65: =IF(AM60>0,AM62*100/AM60,"") -> 0

Sheet Tercer Trimestre
G1: REGISTRO DE CALIFICACIONES | T1: UNIDAD EDUCATIVA | AA1: =Carátula!D14 -> SIMON BOLIVAR | AJ1: www.educa-tics.com
A2: Curso: | C2: =CONCATENATE(Carátula!P20," ",Carátula!S20) -> SEXTO "A" | G2: EVALUACION DEL MAESTRA (O) - DIMENSIONES | AL2: Auto-Eval | AM2: Prom. 1er Trim.
A3: Gestión: | C3: =Carátula!F8 -> 2026 | G3: SER - 10 | K3: SABER - 45 | W3: HACER - 40 | AK3: PROMEDIO PARCIAL | AL3: 5
A4: Materia: | C4: =Carátula!D26 -> MATEMÁTICAS | J4: VALORACIÓN 5 Pts | V4: VALORACION 45 Pts | AJ4: VALORACION 40 Pts | AL4: AUTOEVALAUCIÓN 5 Pts
A5: Prof.: | C5: =Carátula!D23 -> JOSE CUELLAR SANCHEZ
A6: Trimestre: | C6: TERCER TRIMESTRE
A7: 1
A8: Nº | B8: APELLIDOS Y NOMBRES
A9: 1 | B9: =IF(ISBLANK(FIL!E6),"",CONCATENATE(FIL!C6," ",FIL!D6," ",FIL!E6)) -> CUELLAR SANCHEZ JOSE | G9: 5 | J9: =IF(ISERROR(ROUND(AVERAGE(G9:I9),1)),"",ROUND(AVERAGE(G9:I9),1)) -> 5 | K9: 17 | V9: =IF(ISERROR(ROUND(AVERAGE(K9:U9),1)),"",ROUND(AVERAGE(K9:U9),1)) -> 17 | W9: 25 | AJ9: =IF(ISERROR(ROUND(AVERAGE(W9:AI9),1)),"",ROUND(AVERAGE(W9:AI9),1)) -> 25 | AK9: =IF(AO9<>0,IF(ISERROR(ROUND( (J9+V9+AJ9),0)),"",ROUND(((J9+V9+AJ9)+AO9)/2,0)),IF(ISERROR(ROUND( J9+V9+AJ9,0)),"",ROUND(J9+V9+AJ9,0))) -> 47 | AL9: 3 | AM9: =IF(AO9<>0,IF(ISERROR(ROUND( (AK9+AL9),0)),"",ROUND(((AK9+AL9)+AO9)/2,0)),IF(ISERROR(ROUND( AK9+AL9,0)),"",ROUND(AK9+AL9,0))) -> 50
A10: 2 | B10: =IF(ISBLANK(FIL!E7),"",CONCATENATE(FIL!C7," ",FIL!D7," ",FIL!E7)) -> VALENCIA ROJAS NICOLAS | G10: 6 | J10: =IF(ISERROR(ROUND(AVERAGE(G10:I10),1)),"",ROUND(AVERAGE(G10:I10),1)) -> 6 | K10: 25 | V10: =IF(ISERROR(ROUND(AVERAGE(K10:U10),1)),"",ROUND(AVERAGE(K10:U10),1)) -> 25 | W10: 25 | AJ10: =IF(ISERROR(ROUND(AVERAGE(W10:AI10),1)),"",ROUND(AVERAGE(W10:AI10),1)) -> 25 | AK10: =IF(AO10<>0,IF(ISERROR(ROUND( (J10+V10+AJ10),0)),"",ROUND(((J10+V10+AJ10)+AO10)/2,0)),IF(ISERROR(ROUND( J10+V10+AJ10,0)),"",ROUND(J10+V10+AJ10,0))) -> 56 | AL10: 2 | AM10: =IF(AO10<>0,IF(ISERROR(ROUND( (AK10+AL10),0)),"",ROUND(((AK10+AL10)+AO10)/2,0)),IF(ISERROR(ROUND( AK10+AL10,0)),"",ROUND(AK10+AL10,0))) -> 58
A11: 3 | B11: =IF(ISBLANK(FIL!E8),"",CONCATENATE(FIL!C8," ",FIL!D8," ",FIL!E8)) | J11: =IF(ISERROR(ROUND(AVERAGE(G11:I11),1)),"",ROUND(AVERAGE(G11:I11),1)) | V11: =IF(ISERROR(ROUND(AVERAGE(K11:U11),1)),"",ROUND(AVERAGE(K11:U11),1)) | AJ11: =IF(ISERROR(ROUND(AVERAGE(W11:AI11),1)),"",ROUND(AVERAGE(W11:AI11),1)) | AK11: =IF(AO11<>0,IF(ISERROR(ROUND( (J11+V11+AJ11),0)),"",ROUND(((J11+V11+AJ11)+AO11)/2,0)),IF(ISERROR(ROUND( J11+V11+AJ11,0)),"",ROUND(J11+V11+AJ11,0))) | AM11: =IF(AO11<>0,IF(ISERROR(ROUND( (AK11+AL11),0)),"",ROUND(((AK11+AL11)+AO11)/2,0)),IF(ISERROR(ROUND( AK11+AL11,0)),"",ROUND(AK11+AL11,0)))
A12: 4 | B12: =IF(ISBLANK(FIL!E9),"",CONCATENATE(FIL!C9," ",FIL!D9," ",FIL!E9)) | J12: =IF(ISERROR(ROUND(AVERAGE(G12:I12),1)),"",ROUND(AVERAGE(G12:I12),1)) | V12: =IF(ISERROR(ROUND(AVERAGE(K12:U12),1)),"",ROUND(AVERAGE(K12:U12),1)) | AJ12: =IF(ISERROR(ROUND(AVERAGE(W12:AI12),1)),"",ROUND(AVERAGE(W12:AI12),1)) | AK12: =IF(AO12<>0,IF(ISERROR(ROUND( (J12+V12+AJ12),0)),"",ROUND(((J12+V12+AJ12)+AO12)/2,0)),IF(ISERROR(ROUND( J12+V12+AJ12,0)),"",ROUND(J12+V12+AJ12,0))) | AM12: =IF(AO12<>0,IF(ISERROR(ROUND( (AK12+AL12),0)),"",ROUND(((AK12+AL12)+AO12)/2,0)),IF(ISERROR(ROUND( AK12+AL12,0)),"",ROUND(AK12+AL12,0)))
A13: 5 | B13: =IF(ISBLANK(FIL!E10),"",CONCATENATE(FIL!C10," ",FIL!D10," ",FIL!E10)) | J13: =IF(ISERROR(ROUND(AVERAGE(G13:I13),1)),"",ROUND(AVERAGE(G13:I13),1)) | V13: =IF(ISERROR(ROUND(AVERAGE(K13:U13),1)),"",ROUND(AVERAGE(K13:U13),1)) | AJ13: =IF(ISERROR(ROUND(AVERAGE(W13:AI13),1)),"",ROUND(AVERAGE(W13:AI13),1)) | AK13: =IF(AO13<>0,IF(ISERROR(ROUND( (J13+V13+AJ13),0)),"",ROUND(((J13+V13+AJ13)+AO13)/2,0)),IF(ISERROR(ROUND( J13+V13+AJ13,0)),"",ROUND(J13+V13+AJ13,0))) | AM13: =IF(AO13<>0,IF(ISERROR(ROUND( (AK13+AL13),0)),"",ROUND(((AK13+AL13)+AO13)/2,0)),IF(ISERROR(ROUND( AK13+AL13,0)),"",ROUND(AK13+AL13,0)))
A14: 6 | B14: =IF(ISBLANK(FIL!E11),"",CONCATENATE(FIL!C11," ",FIL!D11," ",FIL!E11)) | J14: =IF(ISERROR(ROUND(AVERAGE(G14:I14),1)),"",ROUND(AVERAGE(G14:I14),1)) | V14: =IF(ISERROR(ROUND(AVERAGE(K14:U14),1)),"",ROUND(AVERAGE(K14:U14),1)) | AJ14: =IF(ISERROR(ROUND(AVERAGE(W14:AI14),1)),"",ROUND(AVERAGE(W14:AI14),1)) | AK14: =IF(AO14<>0,IF(ISERROR(ROUND( (J14+V14+AJ14),0)),"",ROUND(((J14+V14+AJ14)+AO14)/2,0)),IF(ISERROR(ROUND( J14+V14+AJ14,0)),"",ROUND(J14+V14+AJ14,0))) | AM14: =IF(AO14<>0,IF(ISERROR(ROUND( (AK14+AL14),0)),"",ROUND(((AK14+AL14)+AO14)/2,0)),IF(ISERROR(ROUND( AK14+AL14,0)),"",ROUND(AK14+AL14,0)))
A15: 7 | B15: =IF(ISBLANK(FIL!E12),"",CONCATENATE(FIL!C12," ",FIL!D12," ",FIL!E12)) | J15: =IF(ISERROR(ROUND(AVERAGE(G15:I15),1)),"",ROUND(AVERAGE(G15:I15),1)) | V15: =IF(ISERROR(ROUND(AVERAGE(K15:U15),1)),"",ROUND(AVERAGE(K15:U15),1)) | AJ15: =IF(ISERROR(ROUND(AVERAGE(W15:AI15),1)),"",ROUND(AVERAGE(W15:AI15),1)) | AK15: =IF(AO15<>0,IF(ISERROR(ROUND( (J15+V15+AJ15),0)),"",ROUND(((J15+V15+AJ15)+AO15)/2,0)),IF(ISERROR(ROUND( J15+V15+AJ15,0)),"",ROUND(J15+V15+AJ15,0))) | AM15: =IF(AO15<>0,IF(ISERROR(ROUND( (AK15+AL15),0)),"",ROUND(((AK15+AL15)+AO15)/2,0)),IF(ISERROR(ROUND( AK15+AL15,0)),"",ROUND(AK15+AL15,0)))
A16: 8 | B16: =IF(ISBLANK(FIL!E13),"",CONCATENATE(FIL!C13," ",FIL!D13," ",FIL!E13)) | J16: =IF(ISERROR(ROUND(AVERAGE(G16:I16),1)),"",ROUND(AVERAGE(G16:I16),1)) | V16: =IF(ISERROR(ROUND(AVERAGE(K16:U16),1)),"",ROUND(AVERAGE(K16:U16),1)) | AJ16: =IF(ISERROR(ROUND(AVERAGE(W16:AI16),1)),"",ROUND(AVERAGE(W16:AI16),1)) | AK16: =IF(AO16<>0,IF(ISERROR(ROUND( (J16+V16+AJ16),0)),"",ROUND(((J16+V16+AJ16)+AO16)/2,0)),IF(ISERROR(ROUND( J16+V16+AJ16,0)),"",ROUND(J16+V16+AJ16,0))) | AM16: =IF(AO16<>0,IF(ISERROR(ROUND( (AK16+AL16),0)),"",ROUND(((AK16+AL16)+AO16)/2,0)),IF(ISERROR(ROUND( AK16+AL16,0)),"",ROUND(AK16+AL16,0)))
A17: 9 | B17: =IF(ISBLANK(FIL!E14),"",CONCATENATE(FIL!C14," ",FIL!D14," ",FIL!E14)) | J17: =IF(ISERROR(ROUND(AVERAGE(G17:I17),1)),"",ROUND(AVERAGE(G17:I17),1)) | V17: =IF(ISERROR(ROUND(AVERAGE(K17:U17),1)),"",ROUND(AVERAGE(K17:U17),1)) | AJ17: =IF(ISERROR(ROUND(AVERAGE(W17:AI17),1)),"",ROUND(AVERAGE(W17:AI17),1)) | AK17: =IF(AO17<>0,IF(ISERROR(ROUND( (J17+V17+AJ17),0)),"",ROUND(((J17+V17+AJ17)+AO17)/2,0)),IF(ISERROR(ROUND( J17+V17+AJ17,0)),"",ROUND(J17+V17+AJ17,0))) | AM17: =IF(AO17<>0,IF(ISERROR(ROUND( (AK17+AL17),0)),"",ROUND(((AK17+AL17)+AO17)/2,0)),IF(ISERROR(ROUND( AK17+AL17,0)),"",ROUND(AK17+AL17,0)))
A18: 10 | B18: =IF(ISBLANK(FIL!E15),"",CONCATENATE(FIL!C15," ",FIL!D15," ",FIL!E15)) | J18: =IF(ISERROR(ROUND(AVERAGE(G18:I18),1)),"",ROUND(AVERAGE(G18:I18),1)) | V18: =IF(ISERROR(ROUND(AVERAGE(K18:U18),1)),"",ROUND(AVERAGE(K18:U18),1)) | AJ18: =IF(ISERROR(ROUND(AVERAGE(W18:AI18),1)),"",ROUND(AVERAGE(W18:AI18),1)) | AK18: =IF(AO18<>0,IF(ISERROR(ROUND( (J18+V18+AJ18),0)),"",ROUND(((J18+V18+AJ18)+AO18)/2,0)),IF(ISERROR(ROUND( J18+V18+AJ18,0)),"",ROUND(J18+V18+AJ18,0))) | AM18: =IF(AO18<>0,IF(ISERROR(ROUND( (AK18+AL18),0)),"",ROUND(((AK18+AL18)+AO18)/2,0)),IF(ISERROR(ROUND( AK18+AL18,0)),"",ROUND(AK18+AL18,0)))
A19: 11 | B19: =IF(ISBLANK(FIL!E16),"",CONCATENATE(FIL!C16," ",FIL!D16," ",FIL!E16)) | J19: =IF(ISERROR(ROUND(AVERAGE(G19:I19),1)),"",ROUND(AVERAGE(G19:I19),1)) | V19: =IF(ISERROR(ROUND(AVERAGE(K19:U19),1)),"",ROUND(AVERAGE(K19:U19),1)) | AJ19: =IF(ISERROR(ROUND(AVERAGE(W19:AI19),1)),"",ROUND(AVERAGE(W19:AI19),1)) | AK19: =IF(AO19<>0,IF(ISERROR(ROUND( (J19+V19+AJ19),0)),"",ROUND(((J19+V19+AJ19)+AO19)/2,0)),IF(ISERROR(ROUND( J19+V19+AJ19,0)),"",ROUND(J19+V19+AJ19,0))) | AM19: =IF(AO19<>0,IF(ISERROR(ROUND( (AK19+AL19),0)),"",ROUND(((AK19+AL19)+AO19)/2,0)),IF(ISERROR(ROUND( AK19+AL19,0)),"",ROUND(AK19+AL19,0)))
A20: 12 | B20: =IF(ISBLANK(FIL!E17),"",CONCATENATE(FIL!C17," ",FIL!D17," ",FIL!E17)) | J20: =IF(ISERROR(ROUND(AVERAGE(G20:I20),1)),"",ROUND(AVERAGE(G20:I20),1)) | V20: =IF(ISERROR(ROUND(AVERAGE(K20:U20),1)),"",ROUND(AVERAGE(K20:U20),1)) | AJ20: =IF(ISERROR(ROUND(AVERAGE(W20:AI20),1)),"",ROUND(AVERAGE(W20:AI20),1)) | AK20: =IF(AO20<>0,IF(ISERROR(ROUND( (J20+V20+AJ20),0)),"",ROUND(((J20+V20+AJ20)+AO20)/2,0)),IF(ISERROR(ROUND( J20+V20+AJ20,0)),"",ROUND(J20+V20+AJ20,0))) | AM20: =IF(AO20<>0,IF(ISERROR(ROUND( (AK20+AL20),0)),"",ROUND(((AK20+AL20)+AO20)/2,0)),IF(ISERROR(ROUND( AK20+AL20,0)),"",ROUND(AK20+AL20,0)))
A21: 13 | B21: =IF(ISBLANK(FIL!E18),"",CONCATENATE(FIL!C18," ",FIL!D18," ",FIL!E18)) | J21: =IF(ISERROR(ROUND(AVERAGE(G21:I21),1)),"",ROUND(AVERAGE(G21:I21),1)) | V21: =IF(ISERROR(ROUND(AVERAGE(K21:U21),1)),"",ROUND(AVERAGE(K21:U21),1)) | AJ21: =IF(ISERROR(ROUND(AVERAGE(W21:AI21),1)),"",ROUND(AVERAGE(W21:AI21),1)) | AK21: =IF(AO21<>0,IF(ISERROR(ROUND( (J21+V21+AJ21),0)),"",ROUND(((J21+V21+AJ21)+AO21)/2,0)),IF(ISERROR(ROUND( J21+V21+AJ21,0)),"",ROUND(J21+V21+AJ21,0))) | AM21: =IF(AO21<>0,IF(ISERROR(ROUND( (AK21+AL21),0)),"",ROUND(((AK21+AL21)+AO21)/2,0)),IF(ISERROR(ROUND( AK21+AL21,0)),"",ROUND(AK21+AL21,0)))
A22: 14 | B22: =IF(ISBLANK(FIL!E19),"",CONCATENATE(FIL!C19," ",FIL!D19," ",FIL!E19)) | J22: =IF(ISERROR(ROUND(AVERAGE(G22:I22),1)),"",ROUND(AVERAGE(G22:I22),1)) | V22: =IF(ISERROR(ROUND(AVERAGE(K22:U22),1)),"",ROUND(AVERAGE(K22:U22),1)) | AJ22: =IF(ISERROR(ROUND(AVERAGE(W22:AI22),1)),"",ROUND(AVERAGE(W22:AI22),1)) | AK22: =IF(AO22<>0,IF(ISERROR(ROUND( (J22+V22+AJ22),0)),"",ROUND(((J22+V22+AJ22)+AO22)/2,0)),IF(ISERROR(ROUND( J22+V22+AJ22,0)),"",ROUND(J22+V22+AJ22,0))) | AM22: =IF(AO22<>0,IF(ISERROR(ROUND( (AK22+AL22),0)),"",ROUND(((AK22+AL22)+AO22)/2,0)),IF(ISERROR(ROUND( AK22+AL22,0)),"",ROUND(AK22+AL22,0)))
... A55: 47 | B55: =IF(ISBLANK(FIL!E52),"",CONCATENATE(FIL!C52," ",FIL!D52," ",FIL!E52)) | J55: =IF(ISERROR(ROUND(AVERAGE(G55:I55),1)),"",ROUND(AVERAGE(G55:I55),1)) | V55: =IF(ISERROR(ROUND(AVERAGE(K55:U55),1)),"",ROUND(AVERAGE(K55:U55),1)) | AJ55: =IF(ISERROR(ROUND(AVERAGE(W55:AI55),1)),"",ROUND(AVERAGE(W55:AI55),1)) | AK55: =IF(AO55<>0,IF(ISERROR(ROUND( (J55+V55+AJ55),0)),"",ROUND(((J55+V55+AJ55)+AO55)/2,0)),IF(ISERROR(ROUND( J55+V55+AJ55,0)),"",ROUND(J55+V55+AJ55,0))) | AM55: =IF(AO55<>0,IF(ISERROR(ROUND( (AK55+AL55),0)),"",ROUND(((AK55+AL55)+AO55)/2,0)),IF(ISERROR(ROUND( AK55+AL55,0)),"",ROUND(AK55+AL55,0)))
A56: 48 | U56: =IF(ISERROR(ROUND(AVERAGE(H56:T56),1)),"",ROUND(AVERAGE(H56:T56),1)) | AJ56: =IF(ISERROR(ROUND(AVERAGE(V56:AI56),1)),"",ROUND(AVERAGE(V56:AI56),1)) | AL56: =IF(ISERROR(ROUND(U56+AJ56+#REF!,0)),"",ROUND(U56+AJ56+#REF!,0))
A57: 49 | U57: =IF(ISERROR(ROUND(AVERAGE(H57:T57),1)),"",ROUND(AVERAGE(H57:T57),1)) | AJ57: =IF(ISERROR(ROUND(AVERAGE(V57:AI57),1)),"",ROUND(AVERAGE(V57:AI57),1)) | AL57: =IF(ISERROR(ROUND(U57+AJ57+#REF!,0)),"",ROUND(U57+AJ57+#REF!,0))
A58: 50 | U58: =IF(ISERROR(ROUND(AVERAGE(H58:T58),1)),"",ROUND(AVERAGE(H58:T58),1)) | AJ58: =IF(ISERROR(ROUND(AVERAGE(V58:AI58),1)),"",ROUND(AVERAGE(V58:AI58),1)) | AL58: =IF(ISERROR(ROUND(U58+AJ58+#REF!,0)),"",ROUND(U58+AJ58+#REF!,0))
G60: TOTAL DE ESTUDIANTES | AM60: =COUNTIF($AM$9:$AM$58,">0") -> 2
G61: TOTAL APROBADOS | AM61: =IF($AM$60>0,COUNTIF($AM$9:$AM$58,">50"),"") -> 1
G62: TOTAL REPROBADOS | AM62: =IF($AM$60>0,COUNTIF($AM$9:$AM$58,"<51"),"") -> 1
G63: PROMEDIO TRIMESTRAL | AM63: =IF($AM$60>0,ROUND(AVERAGE($AM9:$AM58),0),"") -> 54
A64: _ _ _ _ _ _ _ _ _ _ _ _ _ _ _ _ _ _ _ _ _ _ _ | G64: PORCENTAJE DE APROBADOS | AM64: =IF(AM60>0,AM61*100/AM60,"") -> 50
A65: FIRMA / SELLO | G65: PORCENTAJE DE REPROBADOS | AM65: =IF(AM60>0,AM62*100/AM60,"") -> 50

Sheet Centralizador
C1: BOLETIN CENTRALIZADOR | I1: www.educatic.xyz
